Workbook

Sheet Facilities List
A1: MICROPLAN_COUNTRY | B1: MICROPLAN_PROVINCE_HELPER | C1: MICROPLAN_PROVINCE | D1: MICROPLAN_DISTRICT_HELPER | E1: MICROPLAN_DISTRICT | F1: MICROPLAN_ADMINISTRATIVEPOST_HELPER | G1: MICROPLAN_ADMINISTRATIVEPOST | H1: MICROPLAN_LOCALITY_HELPER | I1: MICROPLAN_LOCALITY | J1: MICROPLAN_VILLAGE_HELPER | K1: MICROPLAN_VILLAGE | L1: HCM_ADMIN_CONSOLE_BOUNDARY_CODE | M1: HCM_ADMIN_CONSOLE_FACILITY_CODE | N1: HCM_ADMIN_CONSOLE_FACILITY_NAME | O1: HCM_ADMIN_CONSOLE_FACILITY_TYPE | P1: HCM_ADMIN_CONSOLE_FACILITY_STATUS | Q1: HCM_ADMIN_CONSOLE_FACILITY_CAPACITY | R1: HCM_ADMIN_CONSOLE_FACILITY_USAGE
A2: Country | B2: MICROPLAN_PROVINCE_HELPER | C2: Province | D2: MICROPLAN_DISTRICT_HELPER | E2: District | F2: MICROPLAN_ADMINISTRATIVEPOST_HELPER | G2: Administrative Post | H2: MICROPLAN_LOCALITY_HELPER | I2: Locality | J2: MICROPLAN_VILLAGE_HELPER | K2: Village | L2: Service Boundary Code | M2: Facility Code | N2: Facility Name | O2: Facility Type | P2: Facility Status | Q2: Capacity (Units: Bales for Bednets/ SPAQ Blister for SMC) | R2: Facility Usage
A3: Nigeria | B3: =IFERROR(INDEX(_h_SimpleLookup_h_!$I$16:$I$20,MATCH(CONCATENATE(INDIRECT("A"&ROW())),_h_SimpleLookup_h_!$H$16:$H$20,0)),"") -> H_04952a0f984dccfa1c401fbe5669c5342059049be3e2bba73dc5a481759b22a9 | C3: Gaza | D3: =IFERROR(INDEX(_h_SimpleLookup_h_!$I$16:$I$20,MATCH(CONCATENATE(INDIRECT("A"&ROW()), "#", INDIRECT("C"&ROW())),_h_SimpleLookup_h_!$H$16:$H$20,0)),"") -> H_3d746386df8e70fc233233a9e10a429bbb45de06e238ef21fcff52d27fd51781 | E3: Chibuto | F3: =IFERROR(INDEX(_h_SimpleLookup_h_!$I$16:$I$20,MATCH(CONCATENATE(INDIRECT("A"&ROW()), "#", INDIRECT("C"&ROW()), "#", INDIRECT("E"&ROW())),_h_SimpleLookup_h_!$H$16:$H$20,0)),"") -> H_f8225e850582739dca18bbc9f1b87eec4a399a506bac01963630d2d5869939c4 | G3: Chibutoo | H3: =IFERROR(INDEX(_h_SimpleLookup_h_!$I$16:$I$20,MATCH(CONCATENATE(INDIRECT("A"&ROW()), "#", INDIRECT("C"&ROW()), "#", INDIRECT("E"&ROW()), "#", INDIRECT("G"&ROW())),_h_SimpleLookup_h_!$H$16:$H$20,0)),"") -> H_9de166f1e87c37e01777111aa51a73d37bbe5559df989fc50fad851f9070f447 | I3: Chibuto Sede | J3: =IFERROR(INDEX(_h_SimpleLookup_h_!$I$16:$I$20,MATCH(CONCATENATE(INDIRECT("A"&ROW()), "#", INDIRECT("C"&ROW()), "#", INDIRECT("E"&ROW()), "#", INDIRECT("G"&ROW()), "#", INDIRECT("I"&ROW())),_h_SimpleLookup_h_!$H$16:$H$20,0)),"") -> H_e9c3596c6f157c143621a34465e5390d1264415e6840e00130c0b1805b8f179c | K3: Mapa | L3: =IF(K3<>"",IFERROR(VLOOKUP(K3,_h_SimpleLookup_h_!$D$8:$E$13,2,0),""),IF(I3<>"",IFERROR(VLOOKUP(I3,_h_SimpleLookup_h_!$D$8:$E$13,2,0),""),IF(G3<>"",IFERROR(VLOOKUP(G3,_h_SimpleLookup_h_!$D$8:$E$13,2,0),""),IF(E3<>"",IFERROR(VLOOKUP(E3,_h_SimpleLookup_h_!$D$8:$E$13,2,0),""),IF(C3<>"",IFERROR(VLOOKUP(C3,_h_SimpleLookup_h_!$D$8:$E$13,2,0),""),IF(A3<>"",IFERROR(VLOOKUP(A3,_h_SimpleLookup_h_!$D$8:$E$13,2,0),""),"")))))) -> MICROPLAN_MO_05_01_01_01_01_MAPA_TEST1 | M3: F-2026-03-11-000151 | N3: Facility Storage Gaza | O3: Storing Resource | P3: Permanent | Q3: 200 | R3: Active
A4: Nigeria | B4: =IFERROR(INDEX(_h_SimpleLookup_h_!$I$16:$I$20,MATCH(CONCATENATE(INDIRECT("A"&ROW())),_h_SimpleLookup_h_!$H$16:$H$20,0)),"") -> H_04952a0f984dccfa1c401fbe5669c5342059049be3e2bba73dc5a481759b22a9 | D4: =IFERROR(INDEX(_h_SimpleLookup_h_!$I$16:$I$20,MATCH(CONCATENATE(INDIRECT("A"&ROW()), "#", INDIRECT("C"&ROW())),_h_SimpleLookup_h_!$H$16:$H$20,0)),"") | F4: =IFERROR(INDEX(_h_SimpleLookup_h_!$I$16:$I$20,MATCH(CONCATENATE(INDIRECT("A"&ROW()), "#", INDIRECT("C"&ROW()), "#", INDIRECT("E"&ROW())),_h_SimpleLookup_h_!$H$16:$H$20,0)),"") | H4: =IFERROR(INDEX(_h_SimpleLookup_h_!$I$16:$I$20,MATCH(CONCATENATE(INDIRECT("A"&ROW()), "#", INDIRECT("C"&ROW()), "#", INDIRECT("E"&ROW()), "#", INDIRECT("G"&ROW())),_h_SimpleLookup_h_!$H$16:$H$20,0)),"") | J4: =IFERROR(INDEX(_h_SimpleLookup_h_!$I$16:$I$20,MATCH(CONCATENATE(INDIRECT("A"&ROW()), "#", INDIRECT("C"&ROW()), "#", INDIRECT("E"&ROW()), "#", INDIRECT("G"&ROW()), "#", INDIRECT("I"&ROW())),_h_SimpleLookup_h_!$H$16:$H$20,0)),"") | L4: =IF(K4<>"",IFERROR(VLOOKUP(K4,_h_SimpleLookup_h_!$D$8:$E$13,2,0),""),IF(I4<>"",IFERROR(VLOOKUP(I4,_h_SimpleLookup_h_!$D$8:$E$13,2,0),""),IF(G4<>"",IFERROR(VLOOKUP(G4,_h_SimpleLookup_h_!$D$8:$E$13,2,0),""),IF(E4<>"",IFERROR(VLOOKUP(E4,_h_SimpleLookup_h_!$D$8:$E$13,2,0),""),IF(C4<>"",IFERROR(VLOOKUP(C4,_h_SimpleLookup_h_!$D$8:$E$13,2,0),""),IF(A4<>"",IFERROR(VLOOKUP(A4,_h_SimpleLookup_h_!$D$8:$E$13,2,0),""),"")))))) -> MICROPLAN_MO | M4: F-2026-02-25-000126 | N4: LN 1 | O4: Warehouse | P4: Permanent | Q4: 100 | R4: Active
A5: Nigeria | B5: =IFERROR(INDEX(_h_SimpleLookup_h_!$I$16:$I$20,MATCH(CONCATENATE(INDIRECT("A"&ROW())),_h_SimpleLookup_h_!$H$16:$H$20,0)),"") -> H_04952a0f984dccfa1c401fbe5669c5342059049be3e2bba73dc5a481759b22a9 | D5: =IFERROR(INDEX(_h_SimpleLookup_h_!$I$16:$I$20,MATCH(CONCATENATE(INDIRECT("A"&ROW()), "#", INDIRECT("C"&ROW())),_h_SimpleLookup_h_!$H$16:$H$20,0)),"") | F5: =IFERROR(INDEX(_h_SimpleLookup_h_!$I$16:$I$20,MATCH(CONCATENATE(INDIRECT("A"&ROW()), "#", INDIRECT("C"&ROW()), "#", INDIRECT("E"&ROW())),_h_SimpleLookup_h_!$H$16:$H$20,0)),"") | H5: =IFERROR(INDEX(_h_SimpleLookup_h_!$I$16:$I$20,MATCH(CONCATENATE(INDIRECT("A"&ROW()), "#", INDIRECT("C"&ROW()), "#", INDIRECT("E"&ROW()), "#", INDIRECT("G"&ROW())),_h_SimpleLookup_h_!$H$16:$H$20,0)),"") | J5: =IFERROR(INDEX(_h_SimpleLookup_h_!$I$16:$I$20,MATCH(CONCATENATE(INDIRECT("A"&ROW()), "#", INDIRECT("C"&ROW()), "#", INDIRECT("E"&ROW()), "#", INDIRECT("G"&ROW()), "#", INDIRECT("I"&ROW())),_h_SimpleLookup_h_!$H$16:$H$20,0)),"") | L5: =IF(K5<>"",IFERROR(VLOOKUP(K5,_h_SimpleLookup_h_!$D$8:$E$13,2,0),""),IF(I5<>"",IFERROR(VLOOKUP(I5,_h_SimpleLookup_h_!$D$8:$E$13,2,0),""),IF(G5<>"",IFERROR(VLOOKUP(G5,_h_SimpleLookup_h_!$D$8:$E$13,2,0),""),IF(E5<>"",IFERROR(VLOOKUP(E5,_h_SimpleLookup_h_!$D$8:$E$13,2,0),""),IF(C5<>"",IFERROR(VLOOKUP(C5,_h_SimpleLookup_h_!$D$8:$E$13,2,0),""),IF(A5<>"",IFERROR(VLOOKUP(A5,_h_SimpleLookup_h_!$D$8:$E$13,2,0),""),"")))))) -> MICROPLAN_MO | M5: F-2026-02-25-000127 | N5: LN 2 | O5: Warehouse | P5: Permanent | Q5: 100 | R5: Active
A6: Nigeria | B6: =IFERROR(INDEX(_h_SimpleLookup_h_!$I$16:$I$20,MATCH(CONCATENATE(INDIRECT("A"&ROW())),_h_SimpleLookup_h_!$H$16:$H$20,0)),"") -> H_04952a0f984dccfa1c401fbe5669c5342059049be3e2bba73dc5a481759b22a9 | D6: =IFERROR(INDEX(_h_SimpleLookup_h_!$I$16:$I$20,MATCH(CONCATENATE(INDIRECT("A"&ROW()), "#", INDIRECT("C"&ROW())),_h_SimpleLookup_h_!$H$16:$H$20,0)),"") | F6: =IFERROR(INDEX(_h_SimpleLookup_h_!$I$16:$I$20,MATCH(CONCATENATE(INDIRECT("A"&ROW()), "#", INDIRECT("C"&ROW()), "#", INDIRECT("E"&ROW())),_h_SimpleLookup_h_!$H$16:$H$20,0)),"") | H6: =IFERROR(INDEX(_h_SimpleLookup_h_!$I$16:$I$20,MATCH(CONCATENATE(INDIRECT("A"&ROW()), "#", INDIRECT("C"&ROW()), "#", INDIRECT("E"&ROW()), "#", INDIRECT("G"&ROW())),_h_SimpleLookup_h_!$H$16:$H$20,0)),"") | J6: =IFERROR(INDEX(_h_SimpleLookup_h_!$I$16:$I$20,MATCH(CONCATENATE(INDIRECT("A"&ROW()), "#", INDIRECT("C"&ROW()), "#", INDIRECT("E"&ROW()), "#", INDIRECT("G"&ROW()), "#", INDIRECT("I"&ROW())),_h_SimpleLookup_h_!$H$16:$H$20,0)),"") | L6: =IF(K6<>"",IFERROR(VLOOKUP(K6,_h_SimpleLookup_h_!$D$8:$E$13,2,0),""),IF(I6<>"",IFERROR(VLOOKUP(I6,_h_SimpleLookup_h_!$D$8:$E$13,2,0),""),IF(G6<>"",IFERROR(VLOOKUP(G6,_h_SimpleLookup_h_!$D$8:$E$13,2,0),""),IF(E6<>"",IFERROR(VLOOKUP(E6,_h_SimpleLookup_h_!$D$8:$E$13,2,0),""),IF(C6<>"",IFERROR(VLOOKUP(C6,_h_SimpleLookup_h_!$D$8:$E$13,2,0),""),IF(A6<>"",IFERROR(VLOOKUP(A6,_h_SimpleLookup_h_!$D$8:$E$13,2,0),""),"")))))) -> MICROPLAN_MO | M6: F-2026-03-24-000340 | N6: Central facility | O6: Warehouse | P6: Permanent | Q6: 1000 | R6: Active
A7: Nigeria | B7: =IFERROR(INDEX(_h_SimpleLookup_h_!$I$16:$I$20,MATCH(CONCATENATE(INDIRECT("A"&ROW())),_h_SimpleLookup_h_!$H$16:$H$20,0)),"") -> H_04952a0f984dccfa1c401fbe5669c5342059049be3e2bba73dc5a481759b22a9 | C7: Gaza | D7: =IFERROR(INDEX(_h_SimpleLookup_h_!$I$16:$I$20,MATCH(CONCATENATE(INDIRECT("A"&ROW()), "#", INDIRECT("C"&ROW())),_h_SimpleLookup_h_!$H$16:$H$20,0)),"") -> H_3d746386df8e70fc233233a9e10a429bbb45de06e238ef21fcff52d27fd51781 | F7: =IFERROR(INDEX(_h_SimpleLookup_h_!$I$16:$I$20,MATCH(CONCATENATE(INDIRECT("A"&ROW()), "#", INDIRECT("C"&ROW()), "#", INDIRECT("E"&ROW())),_h_SimpleLookup_h_!$H$16:$H$20,0)),"") | H7: =IFERROR(INDEX(_h_SimpleLookup_h_!$I$16:$I$20,MATCH(CONCATENATE(INDIRECT("A"&ROW()), "#", INDIRECT("C"&ROW()), "#", INDIRECT("E"&ROW()), "#", INDIRECT("G"&ROW())),_h_SimpleLookup_h_!$H$16:$H$20,0)),"") | J7: =IFERROR(INDEX(_h_SimpleLookup_h_!$I$16:$I$20,MATCH(CONCATENATE(INDIRECT("A"&ROW()), "#", INDIRECT("C"&ROW()), "#", INDIRECT("E"&ROW()), "#", INDIRECT("G"&ROW()), "#", INDIRECT("I"&ROW())),_h_SimpleLookup_h_!$H$16:$H$20,0)),"") | L7: =IF(K7<>"",IFERROR(VLOOKUP(K7,_h_SimpleLookup_h_!$D$8:$E$13,2,0),""),IF(I7<>"",IFERROR(VLOOKUP(I7,_h_SimpleLookup_h_!$D$8:$E$13,2,0),""),IF(G7<>"",IFERROR(VLOOKUP(G7,_h_SimpleLookup_h_!$D$8:$E$13,2,0),""),IF(E7<>"",IFERROR(VLOOKUP(E7,_h_SimpleLookup_h_!$D$8:$E$13,2,0),""),IF(C7<>"",IFERROR(VLOOKUP(C7,_h_SimpleLookup_h_!$D$8:$E$13,2,0),""),IF(A7<>"",IFERROR(VLOOKUP(A7,_h_SimpleLookup_h_!$D$8:$E$13,2,0),""),"")))))) -> MICROPLAN_MO_05_GAZA_TEST1 | N7: Gaza Fac1 | O7: Health Facility | P7: Permanent | Q7: 1000 | R7: Active
A8: Nigeria | B8: =IFERROR(INDEX(_h_SimpleLookup_h_!$I$16:$I$20,MATCH(CONCATENATE(INDIRECT("A"&ROW())),_h_SimpleLookup_h_!$H$16:$H$20,0)),"") -> H_04952a0f984dccfa1c401fbe5669c5342059049be3e2bba73dc5a481759b22a9 | C8: Gaza | D8: =IFERROR(INDEX(_h_SimpleLookup_h_!$I$16:$I$20,MATCH(CONCATENATE(INDIRECT("A"&ROW()), "#", INDIRECT("C"&ROW())),_h_SimpleLookup_h_!$H$16:$H$20,0)),"") -> H_3d746386df8e70fc233233a9e10a429bbb45de06e238ef21fcff52d27fd51781 | E8: Chibuto | F8: =IFERROR(INDEX(_h_SimpleLookup_h_!$I$16:$I$20,MATCH(CONCATENATE(INDIRECT("A"&ROW()), "#", INDIRECT("C"&ROW()), "#", INDIRECT("E"&ROW())),_h_SimpleLookup_h_!$H$16:$H$20,0)),"") -> H_f8225e850582739dca18bbc9f1b87eec4a399a506bac01963630d2d5869939c4 | H8: =IFERROR(INDEX(_h_SimpleLookup_h_!$I$16:$I$20,MATCH(CONCATENATE(INDIRECT("A"&ROW()), "#", INDIRECT("C"&ROW()), "#", INDIRECT("E"&ROW()), "#", INDIRECT("G"&ROW())),_h_SimpleLookup_h_!$H$16:$H$20,0)),"") | J8: =IFERROR(INDEX(_h_SimpleLookup_h_!$I$16:$I$20,MATCH(CONCATENATE(INDIRECT("A"&ROW()), "#", INDIRECT("C"&ROW()), "#", INDIRECT("E"&ROW()), "#", INDIRECT("G"&ROW()), "#", INDIRECT("I"&ROW())),_h_SimpleLookup_h_!$H$16:$H$20,0)),"") | L8: =IF(K8<>"",IFERROR(VLOOKUP(K8,_h_SimpleLookup_h_!$D$8:$E$13,2,0),""),IF(I8<>"",IFERROR(VLOOKUP(I8,_h_SimpleLookup_h_!$D$8:$E$13,2,0),""),IF(G8<>"",IFERROR(VLOOKUP(G8,_h_SimpleLookup_h_!$D$8:$E$13,2,0),""),IF(E8<>"",IFERROR(VLOOKUP(E8,_h_SimpleLookup_h_!$D$8:$E$13,2,0),""),IF(C8<>"",IFERROR(VLOOKUP(C8,_h_SimpleLookup_h_!$D$8:$E$13,2,0),""),IF(A8<>"",IFERROR(VLOOKUP(A8,_h_SimpleLookup_h_!$D$8:$E$13,2,0),""),"")))))) -> MICROPLAN_MO_05_01_CHIBUTO_TEST1 | N8: Chibuto Fac1 | O8: Warehouse | P8: Permanent | Q8: 1000 | R8: Active
A9: Nigeria | B9: =IFERROR(INDEX(_h_SimpleLookup_h_!$I$16:$I$20,MATCH(CONCATENATE(INDIRECT("A"&ROW())),_h_SimpleLookup_h_!$H$16:$H$20,0)),"") -> H_04952a0f984dccfa1c401fbe5669c5342059049be3e2bba73dc5a481759b22a9 | C9: Gaza | D9: =IFERROR(INDEX(_h_SimpleLookup_h_!$I$16:$I$20,MATCH(CONCATENATE(INDIRECT("A"&ROW()), "#", INDIRECT("C"&ROW())),_h_SimpleLookup_h_!$H$16:$H$20,0)),"") -> H_3d746386df8e70fc233233a9e10a429bbb45de06e238ef21fcff52d27fd51781 | E9: Chibuto | F9: =IFERROR(INDEX(_h_SimpleLookup_h_!$I$16:$I$20,MATCH(CONCATENATE(INDIRECT("A"&ROW()), "#", INDIRECT("C"&ROW()), "#", INDIRECT("E"&ROW())),_h_SimpleLookup_h_!$H$16:$H$20,0)),"") -> H_f8225e850582739dca18bbc9f1b87eec4a399a506bac01963630d2d5869939c4 | G9: Chibutoo | H9: =IFERROR(INDEX(_h_SimpleLookup_h_!$I$16:$I$20,MATCH(CONCATENATE(INDIRECT("A"&ROW()), "#", INDIRECT("C"&ROW()), "#", INDIRECT("E"&ROW()), "#", INDIRECT("G"&ROW())),_h_SimpleLookup_h_!$H$16:$H$20,0)),"") -> H_9de166f1e87c37e01777111aa51a73d37bbe5559df989fc50fad851f9070f447 | J9: =IFERROR(INDEX(_h_SimpleLookup_h_!$I$16:$I$20,MATCH(CONCATENATE(INDIRECT("A"&ROW()), "#", INDIRECT("C"&ROW()), "#", INDIRECT("E"&ROW()), "#", INDIRECT("G"&ROW()), "#", INDIRECT("I"&ROW())),_h_SimpleLookup_h_!$H$16:$H$20,0)),"") | L9: =IF(K9<>"",IFERROR(VLOOKUP(K9,_h_SimpleLookup_h_!$D$8:$E$13,2,0),""),IF(I9<>"",IFERROR(VLOOKUP(I9,_h_SimpleLookup_h_!$D$8:$E$13,2,0),""),IF(G9<>"",IFERROR(VLOOKUP(G9,_h_SimpleLookup_h_!$D$8:$E$13,2,0),""),IF(E9<>"",IFERROR(VLOOKUP(E9,_h_SimpleLookup_h_!$D$8:$E$13,2,0),""),IF(C9<>"",IFERROR(VLOOKUP(C9,_h_SimpleLookup_h_!$D$8:$E$13,2,0),""),IF(A9<>"",IFERROR(VLOOKUP(A9,_h_SimpleLookup_h_!$D$8:$E$13,2,0),""),"")))))) -> MICROPLAN_MO_05_01_01_CHIBUTOO_TEST1 | N9: Chibutoo Fac1 | O9: Storing Resource | P9: Permanent | Q9: 1000 | R9: Active
A10: Nigeria | B10: =IFERROR(INDEX(_h_SimpleLookup_h_!$I$16:$I$20,MATCH(CONCATENATE(INDIRECT("A"&ROW())),_h_SimpleLookup_h_!$H$16:$H$20,0)),"") -> H_04952a0f984dccfa1c401fbe5669c5342059049be3e2bba73dc5a481759b22a9 | C10: Gaza | D10: =IFERROR(INDEX(_h_SimpleLookup_h_!$I$16:$I$20,MATCH(CONCATENATE(INDIRECT("A"&ROW()), "#", INDIRECT("C"&ROW())),_h_SimpleLookup_h_!$H$16:$H$20,0)),"") -> H_3d746386df8e70fc233233a9e10a429bbb45de06e238ef21fcff52d27fd51781 | E10: Chibuto | F10: =IFERROR(INDEX(_h_SimpleLookup_h_!$I$16:$I$20,MATCH(CONCATENATE(INDIRECT("A"&ROW()), "#", INDIRECT("C"&ROW()), "#", INDIRECT("E"&ROW())),_h_SimpleLookup_h_!$H$16:$H$20,0)),"") -> H_f8225e850582739dca18bbc9f1b87eec4a399a506bac01963630d2d5869939c4 | G10: Chibutoo | H10: =IFERROR(INDEX(_h_SimpleLookup_h_!$I$16:$I$20,MATCH(CONCATENATE(INDIRECT("A"&ROW()), "#", INDIRECT("C"&ROW()), "#", INDIRECT("E"&ROW()), "#", INDIRECT("G"&ROW())),_h_SimpleLookup_h_!$H$16:$H$20,0)),"") -> H_9de166f1e87c37e01777111aa51a73d37bbe5559df989fc50fad851f9070f447 | I10: Chibuto Sede | J10: =IFERROR(INDEX(_h_SimpleLookup_h_!$I$16:$I$20,MATCH(CONCATENATE(INDIRECT("A"&ROW()), "#", INDIRECT("C"&ROW()), "#", INDIRECT("E"&ROW()), "#", INDIRECT("G"&ROW()), "#", INDIRECT("I"&ROW())),_h_SimpleLookup_h_!$H$16:$H$20,0)),"") -> H_e9c3596c6f157c143621a34465e5390d1264415e6840e00130c0b1805b8f179c | L10: =IF(K10<>"",IFERROR(VLOOKUP(K10,_h_SimpleLookup_h_!$D$8:$E$13,2,0),""),IF(I10<>"",IFERROR(VLOOKUP(I10,_h_SimpleLookup_h_!$D$8:$E$13,2,0),""),IF(G10<>"",IFERROR(VLOOKUP(G10,_h_SimpleLookup_h_!$D$8:$E$13,2,0),""),IF(E10<>"",IFERROR(VLOOKUP(E10,_h_SimpleLookup_h_!$D$8:$E$13,2,0),""),IF(C10<>"",IFERROR(VLOOKUP(C10,_h_SimpleLookup_h_!$D$8:$E$13,2,0),""),IF(A10<>"",IFERROR(VLOOKUP(A10,_h_SimpleLookup_h_!$D$8:$E$13,2,0),""),"")))))) -> MICROPLAN_MO_05_01_01_01_CHIBUTO_SEDE_TEST1 | N10: Chibuto Sede Fac1 | O10: Health Facility | P10: Permanent | Q10: 1000 | R10: Active
A11: Nigeria | B11: =IFERROR(INDEX(_h_SimpleLookup_h_!$I$16:$I$20,MATCH(CONCATENATE(INDIRECT("A"&ROW())),_h_SimpleLookup_h_!$H$16:$H$20,0)),"") -> H_04952a0f984dccfa1c401fbe5669c5342059049be3e2bba73dc5a481759b22a9 | C11: Gaza | D11: =IFERROR(INDEX(_h_SimpleLookup_h_!$I$16:$I$20,MATCH(CONCATENATE(INDIRECT("A"&ROW()), "#", INDIRECT("C"&ROW())),_h_SimpleLookup_h_!$H$16:$H$20,0)),"") -> H_3d746386df8e70fc233233a9e10a429bbb45de06e238ef21fcff52d27fd51781 | E11: Chibuto | F11: =IFERROR(INDEX(_h_SimpleLookup_h_!$I$16:$I$20,MATCH(CONCATENATE(INDIRECT("A"&ROW()), "#", INDIRECT("C"&ROW()), "#", INDIRECT("E"&ROW())),_h_SimpleLookup_h_!$H$16:$H$20,0)),"") -> H_f8225e850582739dca18bbc9f1b87eec4a399a506bac01963630d2d5869939c4 | G11: Chibutoo | H11: =IFERROR(INDEX(_h_SimpleLookup_h_!$I$16:$I$20,MATCH(CONCATENATE(INDIRECT("A"&ROW()), "#", INDIRECT("C"&ROW()), "#", INDIRECT("E"&ROW()), "#", INDIRECT("G"&ROW())),_h_SimpleLookup_h_!$H$16:$H$20,0)),"") -> H_9de166f1e87c37e01777111aa51a73d37bbe5559df989fc50fad851f9070f447 | I11: Chibuto Sede | J11: =IFERROR(INDEX(_h_SimpleLookup_h_!$I$16:$I$20,MATCH(CONCATENATE(INDIRECT("A"&ROW()), "#", INDIRECT("C"&ROW()), "#", INDIRECT("E"&ROW()), "#", INDIRECT("G"&ROW()), "#", INDIRECT("I"&ROW())),_h_SimpleLookup_h_!$H$16:$H$20,0)),"") -> H_e9c3596c6f157c143621a34465e5390d1264415e6840e00130c0b1805b8f179c | K11: Mapa | L11: =IF(K11<>"",IFERROR(VLOOKUP(K11,_h_SimpleLookup_h_!$D$8:$E$13,2,0),""),IF(I11<>"",IFERROR(VLOOKUP(I11,_h_SimpleLookup_h_!$D$8:$E$13,2,0),""),IF(G11<>"",IFERROR(VLOOKUP(G11,_h_SimpleLookup_h_!$D$8:$E$13,2,0),""),IF(E11<>"",IFERROR(VLOOKUP(E11,_h_SimpleLookup_h_!$D$8:$E$13,2,0),""),IF(C11<>"",IFERROR(VLOOKUP(C11,_h_SimpleLookup_h_!$D$8:$E$13,2,0),""),IF(A11<>"",IFERROR(VLOOKUP(A11,_h_SimpleLookup_h_!$D$8:$E$13,2,0),""),"")))))) -> MICROPLAN_MO_05_01_01_01_01_MAPA_TEST1 | N11: Mapa Fac1 | O11: Warehouse | P11: Permanent | Q11: 1000 | R11: Active
B12: =IFERROR(INDEX(_h_SimpleLookup_h_!$I$16:$I$20,MATCH(CONCATENATE(INDIRECT("A"&ROW())),_h_SimpleLookup_h_!$H$16:$H$20,0)),"") | D12: =IFERROR(INDEX(_h_SimpleLookup_h_!$I$16:$I$20,MATCH(CONCATENATE(INDIRECT("A"&ROW()), "#", INDIRECT("C"&ROW())),_h_SimpleLookup_h_!$H$16:$H$20,0)),"") | F12: =IFERROR(INDEX(_h_SimpleLookup_h_!$I$16:$I$20,MATCH(CONCATENATE(INDIRECT("A"&ROW()), "#", INDIRECT("C"&ROW()), "#", INDIRECT("E"&ROW())),_h_SimpleLookup_h_!$H$16:$H$20,0)),"") | H12: =IFERROR(INDEX(_h_SimpleLookup_h_!$I$16:$I$20,MATCH(CONCATENATE(INDIRECT("A"&ROW()), "#", INDIRECT("C"&ROW()), "#", INDIRECT("E"&ROW()), "#", INDIRECT("G"&ROW())),_h_SimpleLookup_h_!$H$16:$H$20,0)),"") | J12: =IFERROR(INDEX(_h_SimpleLookup_h_!$I$16:$I$20,MATCH(CONCATENATE(INDIRECT("A"&ROW()), "#", INDIRECT("C"&ROW()), "#", INDIRECT("E"&ROW()), "#", INDIRECT("G"&ROW()), "#", INDIRECT("I"&ROW())),_h_SimpleLookup_h_!$H$16:$H$20,0)),"") | L12: =IF(K12<>"",IFERROR(VLOOKUP(K12,_h_SimpleLookup_h_!$D$8:$E$13,2,0),""),IF(I12<>"",IFERROR(VLOOKUP(I12,_h_SimpleLookup_h_!$D$8:$E$13,2,0),""),IF(G12<>"",IFERROR(VLOOKUP(G12,_h_SimpleLookup_h_!$D$8:$E$13,2,0),""),IF(E12<>"",IFERROR(VLOOKUP(E12,_h_SimpleLookup_h_!$D$8:$E$13,2,0),""),IF(C12<>"",IFERROR(VLOOKUP(C12,_h_SimpleLookup_h_!$D$8:$E$13,2,0),""),IF(A12<>"",IFERROR(VLOOKUP(A12,_h_SimpleLookup_h_!$D$8:$E$13,2,0),""),""))))))
B13: =IFERROR(INDEX(_h_SimpleLookup_h_!$I$16:$I$20,MATCH(CONCATENATE(INDIRECT("A"&ROW())),_h_SimpleLookup_h_!$H$16:$H$20,0)),"") | D13: =IFERROR(INDEX(_h_SimpleLookup_h_!$I$16:$I$20,MATCH(CONCATENATE(INDIRECT("A"&ROW()), "#", INDIRECT("C"&ROW())),_h_SimpleLookup_h_!$H$16:$H$20,0)),"") | F13: =IFERROR(INDEX(_h_SimpleLookup_h_!$I$16:$I$20,MATCH(CONCATENATE(INDIRECT("A"&ROW()), "#", INDIRECT("C"&ROW()), "#", INDIRECT("E"&ROW())),_h_SimpleLookup_h_!$H$16:$H$20,0)),"") | H13: =IFERROR(INDEX(_h_SimpleLookup_h_!$I$16:$I$20,MATCH(CONCATENATE(INDIRECT("A"&ROW()), "#", INDIRECT("C"&ROW()), "#", INDIRECT("E"&ROW()), "#", INDIRECT("G"&ROW())),_h_SimpleLookup_h_!$H$16:$H$20,0)),"") | J13: =IFERROR(INDEX(_h_SimpleLookup_h_!$I$16:$I$20,MATCH(CONCATENATE(INDIRECT("A"&ROW()), "#", INDIRECT("C"&ROW()), "#", INDIRECT("E"&ROW()), "#", INDIRECT("G"&ROW()), "#", INDIRECT("I"&ROW())),_h_SimpleLookup_h_!$H$16:$H$20,0)),"") | L13: =IF(K13<>"",IFERROR(VLOOKUP(K13,_h_SimpleLookup_h_!$D$8:$E$13,2,0),""),IF(I13<>"",IFERROR(VLOOKUP(I13,_h_SimpleLookup_h_!$D$8:$E$13,2,0),""),IF(G13<>"",IFERROR(VLOOKUP(G13,_h_SimpleLookup_h_!$D$8:$E$13,2,0),""),IF(E13<>"",IFERROR(VLOOKUP(E13,_h_SimpleLookup_h_!$D$8:$E$13,2,0),""),IF(C13<>"",IFERROR(VLOOKUP(C13,_h_SimpleLookup_h_!$D$8:$E$13,2,0),""),IF(A13<>"",IFERROR(VLOOKUP(A13,_h_SimpleLookup_h_!$D$8:$E$13,2,0),""),""))))))
B14: =IFERROR(INDEX(_h_SimpleLookup_h_!$I$16:$I$20,MATCH(CONCATENATE(INDIRECT("A"&ROW())),_h_SimpleLookup_h_!$H$16:$H$20,0)),"") | D14: =IFERROR(INDEX(_h_SimpleLookup_h_!$I$16:$I$20,MATCH(CONCATENATE(INDIRECT("A"&ROW()), "#", INDIRECT("C"&ROW())),_h_SimpleLookup_h_!$H$16:$H$20,0)),"") | F14: =IFERROR(INDEX(_h_SimpleLookup_h_!$I$16:$I$20,MATCH(CONCATENATE(INDIRECT("A"&ROW()), "#", INDIRECT("C"&ROW()), "#", INDIRECT("E"&ROW())),_h_SimpleLookup_h_!$H$16:$H$20,0)),"") | H14: =IFERROR(INDEX(_h_SimpleLookup_h_!$I$16:$I$20,MATCH(CONCATENATE(INDIRECT("A"&ROW()), "#", INDIRECT("C"&ROW()), "#", INDIRECT("E"&ROW()), "#", INDIRECT("G"&ROW())),_h_SimpleLookup_h_!$H$16:$H$20,0)),"") | J14: =IFERROR(INDEX(_h_SimpleLookup_h_!$I$16:$I$20,MATCH(CONCATENATE(INDIRECT("A"&ROW()), "#", INDIRECT("C"&ROW()), "#", INDIRECT("E"&ROW()), "#", INDIRECT("G"&ROW()), "#", INDIRECT("I"&ROW())),_h_SimpleLookup_h_!$H$16:$H$20,0)),"") | L14: =IF(K14<>"",IFERROR(VLOOKUP(K14,_h_SimpleLookup_h_!$D$8:$E$13,2,0),""),IF(I14<>"",IFERROR(VLOOKUP(I14,_h_SimpleLookup_h_!$D$8:$E$13,2,0),""),IF(G14<>"",IFERROR(VLOOKUP(G14,_h_SimpleLookup_h_!$D$8:$E$13,2,0),""),IF(E14<>"",IFERROR(VLOOKUP(E14,_h_SimpleLookup_h_!$D$8:$E$13,2,0),""),IF(C14<>"",IFERROR(VLOOKUP(C14,_h_SimpleLookup_h_!$D$8:$E$13,2,0),""),IF(A14<>"",IFERROR(VLOOKUP(A14,_h_SimpleLookup_h_!$D$8:$E$13,2,0),""),""))))))
B15: =IFERROR(INDEX(_h_SimpleLookup_h_!$I$16:$I$20,MATCH(CONCATENATE(INDIRECT("A"&ROW())),_h_SimpleLookup_h_!$H$16:$H$20,0)),"") | D15: =IFERROR(INDEX(_h_SimpleLookup_h_!$I$16:$I$20,MATCH(CONCATENATE(INDIRECT("A"&ROW()), "#", INDIRECT("C"&ROW())),_h_SimpleLookup_h_!$H$16:$H$20,0)),"") | F15: =IFERROR(INDEX(_h_SimpleLookup_h_!$I$16:$I$20,MATCH(CONCATENATE(INDIRECT("A"&ROW()), "#", INDIRECT("C"&ROW()), "#", INDIRECT("E"&ROW())),_h_SimpleLookup_h_!$H$16:$H$20,0)),"") | H15: =IFERROR(INDEX(_h_SimpleLookup_h_!$I$16:$I$20,MATCH(CONCATENATE(INDIRECT("A"&ROW()), "#", INDIRECT("C"&ROW()), "#", INDIRECT("E"&ROW()), "#", INDIRECT("G"&ROW())),_h_SimpleLookup_h_!$H$16:$H$20,0)),"") | J15: =IFERROR(INDEX(_h_SimpleLookup_h_!$I$16:$I$20,MATCH(CONCATENATE(INDIRECT("A"&ROW()), "#", INDIRECT("C"&ROW()), "#", INDIRECT("E"&ROW()), "#", INDIRECT("G"&ROW()), "#", INDIRECT("I"&ROW())),_h_SimpleLookup_h_!$H$16:$H$20,0)),"") | L15: =IF(K15<>"",IFERROR(VLOOKUP(K15,_h_SimpleLookup_h_!$D$8:$E$13,2,0),""),IF(I15<>"",IFERROR(VLOOKUP(I15,_h_SimpleLookup_h_!$D$8:$E$13,2,0),""),IF(G15<>"",IFERROR(VLOOKUP(G15,_h_SimpleLookup_h_!$D$8:$E$13,2,0),""),IF(E15<>"",IFERROR(VLOOKUP(E15,_h_SimpleLookup_h_!$D$8:$E$13,2,0),""),IF(C15<>"",IFERROR(VLOOKUP(C15,_h_SimpleLookup_h_!$D$8:$E$13,2,0),""),IF(A15<>"",IFERROR(VLOOKUP(A15,_h_SimpleLookup_h_!$D$8:$E$13,2,0),""),""))))))
B16: =IFERROR(INDEX(_h_SimpleLookup_h_!$I$16:$I$20,MATCH(CONCATENATE(INDIRECT("A"&ROW())),_h_SimpleLookup_h_!$H$16:$H$20,0)),"") | D16: =IFERROR(INDEX(_h_SimpleLookup_h_!$I$16:$I$20,MATCH(CONCATENATE(INDIRECT("A"&ROW()), "#", INDIRECT("C"&ROW())),_h_SimpleLookup_h_!$H$16:$H$20,0)),"") | F16: =IFERROR(INDEX(_h_SimpleLookup_h_!$I$16:$I$20,MATCH(CONCATENATE(INDIRECT("A"&ROW()), "#", INDIRECT("C"&ROW()), "#", INDIRECT("E"&ROW())),_h_SimpleLookup_h_!$H$16:$H$20,0)),"") | H16: =IFERROR(INDEX(_h_SimpleLookup_h_!$I$16:$I$20,MATCH(CONCATENATE(INDIRECT("A"&ROW()), "#", INDIRECT("C"&ROW()), "#", INDIRECT("E"&ROW()), "#", INDIRECT("G"&ROW())),_h_SimpleLookup_h_!$H$16:$H$20,0)),"") | J16: =IFERROR(INDEX(_h_SimpleLookup_h_!$I$16:$I$20,MATCH(CONCATENATE(INDIRECT("A"&ROW()), "#", INDIRECT("C"&ROW()), "#", INDIRECT("E"&ROW()), "#", INDIRECT("G"&ROW()), "#", INDIRECT("I"&ROW())),_h_SimpleLookup_h_!$H$16:$H$20,0)),"") | L16: =IF(K16<>"",IFERROR(VLOOKUP(K16,_h_SimpleLookup_h_!$D$8:$E$13,2,0),""),IF(I16<>"",IFERROR(VLOOKUP(I16,_h_SimpleLookup_h_!$D$8:$E$13,2,0),""),IF(G16<>"",IFERROR(VLOOKUP(G16,_h_SimpleLookup_h_!$D$8:$E$13,2,0),""),IF(E16<>"",IFERROR(VLOOKUP(E16,_h_SimpleLookup_h_!$D$8:$E$13,2,0),""),IF(C16<>"",IFERROR(VLOOKUP(C16,_h_SimpleLookup_h_!$D$8:$E$13,2,0),""),IF(A16<>"",IFERROR(VLOOKUP(A16,_h_SimpleLookup_h_!$D$8:$E$13,2,0),""),""))))))
B17: =IFERROR(INDEX(_h_SimpleLookup_h_!$I$16:$I$20,MATCH(CONCATENATE(INDIRECT("A"&ROW())),_h_SimpleLookup_h_!$H$16:$H$20,0)),"") | D17: =IFERROR(INDEX(_h_SimpleLookup_h_!$I$16:$I$20,MATCH(CONCATENATE(INDIRECT("A"&ROW()), "#", INDIRECT("C"&ROW())),_h_SimpleLookup_h_!$H$16:$H$20,0)),"") | F17: =IFERROR(INDEX(_h_SimpleLookup_h_!$I$16:$I$20,MATCH(CONCATENATE(INDIRECT("A"&ROW()), "#", INDIRECT("C"&ROW()), "#", INDIRECT("E"&ROW())),_h_SimpleLookup_h_!$H$16:$H$20,0)),"") | H17: =IFERROR(INDEX(_h_SimpleLookup_h_!$I$16:$I$20,MATCH(CONCATENATE(INDIRECT("A"&ROW()), "#", INDIRECT("C"&ROW()), "#", INDIRECT("E"&ROW()), "#", INDIRECT("G"&ROW())),_h_SimpleLookup_h_!$H$16:$H$20,0)),"") | J17: =IFERROR(INDEX(_h_SimpleLookup_h_!$I$16:$I$20,MATCH(CONCATENATE(INDIRECT("A"&ROW()), "#", INDIRECT("C"&ROW()), "#", INDIRECT("E"&ROW()), "#", INDIRECT("G"&ROW()), "#", INDIRECT("I"&ROW())),_h_SimpleLookup_h_!$H$16:$H$20,0)),"") | L17: =IF(K17<>"",IFERROR(VLOOKUP(K17,_h_SimpleLookup_h_!$D$8:$E$13,2,0),""),IF(I17<>"",IFERROR(VLOOKUP(I17,_h_SimpleLookup_h_!$D$8:$E$13,2,0),""),IF(G17<>"",IFERROR(VLOOKUP(G17,_h_SimpleLookup_h_!$D$8:$E$13,2,0),""),IF(E17<>"",IFERROR(VLOOKUP(E17,_h_SimpleLookup_h_!$D$8:$E$13,2,0),""),IF(C17<>"",IFERROR(VLOOKUP(C17,_h_SimpleLookup_h_!$D$8:$E$13,2,0),""),IF(A17<>"",IFERROR(VLOOKUP(A17,_h_SimpleLookup_h_!$D$8:$E$13,2,0),""),""))))))
B18: =IFERROR(INDEX(_h_SimpleLookup_h_!$I$16:$I$20,MATCH(CONCATENATE(INDIRECT("A"&ROW())),_h_SimpleLookup_h_!$H$16:$H$20,0)),"") | D18: =IFERROR(INDEX(_h_SimpleLookup_h_!$I$16:$I$20,MATCH(CONCATENATE(INDIRECT("A"&ROW()), "#", INDIRECT("C"&ROW())),_h_SimpleLookup_h_!$H$16:$H$20,0)),"") | F18: =IFERROR(INDEX(_h_SimpleLookup_h_!$I$16:$I$20,MATCH(CONCATENATE(INDIRECT("A"&ROW()), "#", INDIRECT("C"&ROW()), "#", INDIRECT("E"&ROW())),_h_SimpleLookup_h_!$H$16:$H$20,0)),"") | H18: =IFERROR(INDEX(_h_SimpleLookup_h_!$I$16:$I$20,MATCH(CONCATENATE(INDIRECT("A"&ROW()), "#", INDIRECT("C"&ROW()), "#", INDIRECT("E"&ROW()), "#", INDIRECT("G"&ROW())),_h_SimpleLookup_h_!$H$16:$H$20,0)),"") | J18: =IFERROR(INDEX(_h_SimpleLookup_h_!$I$16:$I$20,MATCH(CONCATENATE(INDIRECT("A"&ROW()), "#", INDIRECT("C"&ROW()), "#", INDIRECT("E"&ROW()), "#", INDIRECT("G"&ROW()), "#", INDIRECT("I"&ROW())),_h_SimpleLookup_h_!$H$16:$H$20,0)),"") | L18: =IF(K18<>"",IFERROR(VLOOKUP(K18,_h_SimpleLookup_h_!$D$8:$E$13,2,0),""),IF(I18<>"",IFERROR(VLOOKUP(I18,_h_SimpleLookup_h_!$D$8:$E$13,2,0),""),IF(G18<>"",IFERROR(VLOOKUP(G18,_h_SimpleLookup_h_!$D$8:$E$13,2,0),""),IF(E18<>"",IFERROR(VLOOKUP(E18,_h_SimpleLookup_h_!$D$8:$E$13,2,0),""),IF(C18<>"",IFERROR(VLOOKUP(C18,_h_SimpleLookup_h_!$D$8:$E$13,2,0),""),IF(A18<>"",IFERROR(VLOOKUP(A18,_h_SimpleLookup_h_!$D$8:$E$13,2,0),""),""))))))
B19: =IFERROR(INDEX(_h_SimpleLookup_h_!$I$16:$I$20,MATCH(CONCATENATE(INDIRECT("A"&ROW())),_h_SimpleLookup_h_!$H$16:$H$20,0)),"") | D19: =IFERROR(INDEX(_h_SimpleLookup_h_!$I$16:$I$20,MATCH(CONCATENATE(INDIRECT("A"&ROW()), "#", INDIRECT("C"&ROW())),_h_SimpleLookup_h_!$H$16:$H$20,0)),"") | F19: =IFERROR(INDEX(_h_SimpleLookup_h_!$I$16:$I$20,MATCH(CONCATENATE(INDIRECT("A"&ROW()), "#", INDIRECT("C"&ROW()), "#", INDIRECT("E"&ROW())),_h_SimpleLookup_h_!$H$16:$H$20,0)),"") | H19: =IFERROR(INDEX(_h_SimpleLookup_h_!$I$16:$I$20,MATCH(CONCATENATE(INDIRECT("A"&ROW()), "#", INDIRECT("C"&ROW()), "#", INDIRECT("E"&ROW()), "#", INDIRECT("G"&ROW())),_h_SimpleLookup_h_!$H$16:$H$20,0)),"") | J19: =IFERROR(INDEX(_h_SimpleLookup_h_!$I$16:$I$20,MATCH(CONCATENATE(INDIRECT("A"&ROW()), "#", INDIRECT("C"&ROW()), "#", INDIRECT("E"&ROW()), "#", INDIRECT("G"&ROW()), "#", INDIRECT("I"&ROW())),_h_SimpleLookup_h_!$H$16:$H$20,0)),"") | L19: =IF(K19<>"",IFERROR(VLOOKUP(K19,_h_SimpleLookup_h_!$D$8:$E$13,2,0),""),IF(I19<>"",IFERROR(VLOOKUP(I19,_h_SimpleLookup_h_!$D$8:$E$13,2,0),""),IF(G19<>"",IFERROR(VLOOKUP(G19,_h_SimpleLookup_h_!$D$8:$E$13,2,0),""),IF(E19<>"",IFERROR(VLOOKUP(E19,_h_SimpleLookup_h_!$D$8:$E$13,2,0),""),IF(C19<>"",IFERROR(VLOOKUP(C19,_h_SimpleLookup_h_!$D$8:$E$13,2,0),""),IF(A19<>"",IFERROR(VLOOKUP(A19,_h_SimpleLookup_h_!$D$8:$E$13,2,0),""),""))))))
B20: =IFERROR(INDEX(_h_SimpleLookup_h_!$I$16:$I$20,MATCH(CONCATENATE(INDIRECT("A"&ROW())),_h_SimpleLookup_h_!$H$16:$H$20,0)),"") | D20: =IFERROR(INDEX(_h_SimpleLookup_h_!$I$16:$I$20,MATCH(CONCATENATE(INDIRECT("A"&ROW()), "#", INDIRECT("C"&ROW())),_h_SimpleLookup_h_!$H$16:$H$20,0)),"") | F20: =IFERROR(INDEX(_h_SimpleLookup_h_!$I$16:$I$20,MATCH(CONCATENATE(INDIRECT("A"&ROW()), "#", INDIRECT("C"&ROW()), "#", INDIRECT("E"&ROW())),_h_SimpleLookup_h_!$H$16:$H$20,0)),"") | H20: =IFERROR(INDEX(_h_SimpleLookup_h_!$I$16:$I$20,MATCH(CONCATENATE(INDIRECT("A"&ROW()), "#", INDIRECT("C"&ROW()), "#", INDIRECT("E"&ROW()), "#", INDIRECT("G"&ROW())),_h_SimpleLookup_h_!$H$16:$H$20,0)),"") | J20: =IFERROR(INDEX(_h_SimpleLookup_h_!$I$16:$I$20,MATCH(CONCATENATE(INDIRECT("A"&ROW()), "#", INDIRECT("C"&ROW()), "#", INDIRECT("E"&ROW()), "#", INDIRECT("G"&ROW()), "#", INDIRECT("I"&ROW())),_h_SimpleLookup_h_!$H$16:$H$20,0)),"") | L20: =IF(K20<>"",IFERROR(VLOOKUP(K20,_h_SimpleLookup_h_!$D$8:$E$13,2,0),""),IF(I20<>"",IFERROR(VLOOKUP(I20,_h_SimpleLookup_h_!$D$8:$E$13,2,0),""),IF(G20<>"",IFERROR(VLOOKUP(G20,_h_SimpleLookup_h_!$D$8:$E$13,2,0),""),IF(E20<>"",IFERROR(VLOOKUP(E20,_h_SimpleLookup_h_!$D$8:$E$13,2,0),""),IF(C20<>"",IFERROR(VLOOKUP(C20,_h_SimpleLookup_h_!$D$8:$E$13,2,0),""),IF(A20<>"",IFERROR(VLOOKUP(A20,_h_SimpleLookup_h_!$D$8:$E$13,2,0),""),""))))))
B21: =IFERROR(INDEX(_h_SimpleLookup_h_!$I$16:$I$20,MATCH(CONCATENATE(INDIRECT("A"&ROW())),_h_SimpleLookup_h_!$H$16:$H$20,0)),"") | D21: =IFERROR(INDEX(_h_SimpleLookup_h_!$I$16:$I$20,MATCH(CONCATENATE(INDIRECT("A"&ROW()), "#", INDIRECT("C"&ROW())),_h_SimpleLookup_h_!$H$16:$H$20,0)),"") | F21: =IFERROR(INDEX(_h_SimpleLookup_h_!$I$16:$I$20,MATCH(CONCATENATE(INDIRECT("A"&ROW()), "#", INDIRECT("C"&ROW()), "#", INDIRECT("E"&ROW())),_h_SimpleLookup_h_!$H$16:$H$20,0)),"") | H21: =IFERROR(INDEX(_h_SimpleLookup_h_!$I$16:$I$20,MATCH(CONCATENATE(INDIRECT("A"&ROW()), "#", INDIRECT("C"&ROW()), "#", INDIRECT("E"&ROW()), "#", INDIRECT("G"&ROW())),_h_SimpleLookup_h_!$H$16:$H$20,0)),"") | J21: =IFERROR(INDEX(_h_SimpleLookup_h_!$I$16:$I$20,MATCH(CONCATENATE(INDIRECT("A"&ROW()), "#", INDIRECT("C"&ROW()), "#", INDIRECT("E"&ROW()), "#", INDIRECT("G"&ROW()), "#", INDIRECT("I"&ROW())),_h_SimpleLookup_h_!$H$16:$H$20,0)),"") | L21: =IF(K21<>"",IFERROR(VLOOKUP(K21,_h_SimpleLookup_h_!$D$8:$E$13,2,0),""),IF(I21<>"",IFERROR(VLOOKUP(I21,_h_SimpleLookup_h_!$D$8:$E$13,2,0),""),IF(G21<>"",IFERROR(VLOOKUP(G21,_h_SimpleLookup_h_!$D$8:$E$13,2,0),""),IF(E21<>"",IFERROR(VLOOKUP(E21,_h_SimpleLookup_h_!$D$8:$E$13,2,0),""),IF(C21<>"",IFERROR(VLOOKUP(C21,_h_SimpleLookup_h_!$D$8:$E$13,2,0),""),IF(A21<>"",IFERROR(VLOOKUP(A21,_h_SimpleLookup_h_!$D$8:$E$13,2,0),""),""))))))
B22: =IFERROR(INDEX(_h_SimpleLookup_h_!$I$16:$I$20,MATCH(CONCATENATE(INDIRECT("A"&ROW())),_h_SimpleLookup_h_!$H$16:$H$20,0)),"") | D22: =IFERROR(INDEX(_h_SimpleLookup_h_!$I$16:$I$20,MATCH(CONCATENATE(INDIRECT("A"&ROW()), "#", INDIRECT("C"&ROW())),_h_SimpleLookup_h_!$H$16:$H$20,0)),"") | F22: =IFERROR(INDEX(_h_SimpleLookup_h_!$I$16:$I$20,MATCH(CONCATENATE(INDIRECT("A"&ROW()), "#", INDIRECT("C"&ROW()), "#", INDIRECT("E"&ROW())),_h_SimpleLookup_h_!$H$16:$H$20,0)),"") | H22: =IFERROR(INDEX(_h_SimpleLookup_h_!$I$16:$I$20,MATCH(CONCATENATE(INDIRECT("A"&ROW()), "#", INDIRECT("C"&ROW()), "#", INDIRECT("E"&ROW()), "#", INDIRECT("G"&ROW())),_h_SimpleLookup_h_!$H$16:$H$20,0)),"") | J22: =IFERROR(INDEX(_h_SimpleLookup_h_!$I$16:$I$20,MATCH(CONCATENATE(INDIRECT("A"&ROW()), "#", INDIRECT("C"&ROW()), "#", INDIRECT("E"&ROW()), "#", INDIRECT("G"&ROW()), "#", INDIRECT("I"&ROW())),_h_SimpleLookup_h_!$H$16:$H$20,0)),"") | L22: =IF(K22<>"",IFERROR(VLOOKUP(K22,_h_SimpleLookup_h_!$D$8:$E$13,2,0),""),IF(I22<>"",IFERROR(VLOOKUP(I22,_h_SimpleLookup_h_!$D$8:$E$13,2,0),""),IF(G22<>"",IFERROR(VLOOKUP(G22,_h_SimpleLookup_h_!$D$8:$E$13,2,0),""),IF(E22<>"",IFERROR(VLOOKUP(E22,_h_SimpleLookup_h_!$D$8:$E$13,2,0),""),IF(C22<>"",IFERROR(VLOOKUP(C22,_h_SimpleLookup_h_!$D$8:$E$13,2,0),""),IF(A22<>"",IFERROR(VLOOKUP(A22,_h_SimpleLookup_h_!$D$8:$E$13,2,0),""),""))))))
B23: =IFERROR(INDEX(_h_SimpleLookup_h_!$I$16:$I$20,MATCH(CONCATENATE(INDIRECT("A"&ROW())),_h_SimpleLookup_h_!$H$16:$H$20,0)),"") | D23: =IFERROR(INDEX(_h_SimpleLookup_h_!$I$16:$I$20,MATCH(CONCATENATE(INDIRECT("A"&ROW()), "#", INDIRECT("C"&ROW())),_h_SimpleLookup_h_!$H$16:$H$20,0)),"") | F23: =IFERROR(INDEX(_h_SimpleLookup_h_!$I$16:$I$20,MATCH(CONCATENATE(INDIRECT("A"&ROW()), "#", INDIRECT("C"&ROW()), "#", INDIRECT("E"&ROW())),_h_SimpleLookup_h_!$H$16:$H$20,0)),"") | H23: =IFERROR(INDEX(_h_SimpleLookup_h_!$I$16:$I$20,MATCH(CONCATENATE(INDIRECT("A"&ROW()), "#", INDIRECT("C"&ROW()), "#", INDIRECT("E"&ROW()), "#", INDIRECT("G"&ROW())),_h_SimpleLookup_h_!$H$16:$H$20,0)),"") | J23: =IFERROR(INDEX(_h_SimpleLookup_h_!$I$16:$I$20,MATCH(CONCATENATE(INDIRECT("A"&ROW()), "#", INDIRECT("C"&ROW()), "#", INDIRECT("E"&ROW()), "#", INDIRECT("G"&ROW()), "#", INDIRECT("I"&ROW())),_h_SimpleLookup_h_!$H$16:$H$20,0)),"") | L23: =IF(K23<>"",IFERROR(VLOOKUP(K23,_h_SimpleLookup_h_!$D$8:$E$13,2,0),""),IF(I23<>"",IFERROR(VLOOKUP(I23,_h_SimpleLookup_h_!$D$8:$E$13,2,0),""),IF(G23<>"",IFERROR(VLOOKUP(G23,_h_SimpleLookup_h_!$D$8:$E$13,2,0),""),IF(E23<>"",IFERROR(VLOOKUP(E23,_h_SimpleLookup_h_!$D$8:$E$13,2,0),""),IF(C23<>"",IFERROR(VLOOKUP(C23,_h_SimpleLookup_h_!$D$8:$E$13,2,0),""),IF(A23<>"",IFERROR(VLOOKUP(A23,_h_SimpleLookup_h_!$D$8:$E$13,2,0),""),""))))))
... B1011: =IFERROR(INDEX(_h_SimpleLookup_h_!$I$16:$I$20,MATCH(CONCATENATE(INDIRECT("A"&ROW())),_h_SimpleLookup_h_!$H$16:$H$20,0)),"") | D1011: =IFERROR(INDEX(_h_SimpleLookup_h_!$I$16:$I$20,MATCH(CONCATENATE(INDIRECT("A"&ROW()), "#", INDIRECT("C"&ROW())),_h_SimpleLookup_h_!$H$16:$H$20,0)),"") | F1011: =IFERROR(INDEX(_h_SimpleLookup_h_!$I$16:$I$20,MATCH(CONCATENATE(INDIRECT("A"&ROW()), "#", INDIRECT("C"&ROW()), "#", INDIRECT("E"&ROW())),_h_SimpleLookup_h_!$H$16:$H$20,0)),"") | H1011: =IFERROR(INDEX(_h_SimpleLookup_h_!$I$16:$I$20,MATCH(CONCATENATE(INDIRECT("A"&ROW()), "#", INDIRECT("C"&ROW()), "#", INDIRECT("E"&ROW()), "#", INDIRECT("G"&ROW())),_h_SimpleLookup_h_!$H$16:$H$20,0)),"") | J1011: =IFERROR(INDEX(_h_SimpleLookup_h_!$I$16:$I$20,MATCH(CONCATENATE(INDIRECT("A"&ROW()), "#", INDIRECT("C"&ROW()), "#", INDIRECT("E"&ROW()), "#", INDIRECT("G"&ROW()), "#", INDIRECT("I"&ROW())),_h_SimpleLookup_h_!$H$16:$H$20,0)),"") | L1011: =IF(K1011<>"",IFERROR(VLOOKUP(K1011,_h_SimpleLookup_h_!$D$8:$E$13,2,0),""),IF(I1011<>"",IFERROR(VLOOKUP(I1011,_h_SimpleLookup_h_!$D$8:$E$13,2,0),""),IF(G1011<>"",IFERROR(VLOOKUP(G1011,_h_SimpleLookup_h_!$D$8:$E$13,2,0),""),IF(E1011<>"",IFERROR(VLOOKUP(E1011,_h_SimpleLookup_h_!$D$8:$E$13,2,0),""),IF(C1011<>"",IFERROR(VLOOKUP(C1011,_h_SimpleLookup_h_!$D$8:$E$13,2,0),""),IF(A1011<>"",IFERROR(VLOOKUP(A1011,_h_SimpleLookup_h_!$D$8:$E$13,2,0),""),""))))))

Sheet User List
A1: MICROPLAN_COUNTRY | B1: MICROPLAN_PROVINCE_HELPER | C1: MICROPLAN_PROVINCE | D1: MICROPLAN_DISTRICT_HELPER | E1: MICROPLAN_DISTRICT | F1: MICROPLAN_ADMINISTRATIVEPOST_HELPER | G1: MICROPLAN_ADMINISTRATIVEPOST | H1: MICROPLAN_LOCALITY_HELPER | I1: MICROPLAN_LOCALITY | J1: MICROPLAN_VILLAGE_HELPER | K1: MICROPLAN_VILLAGE | L1: HCM_ADMIN_CONSOLE_BOUNDARY_CODE | M1: HCM_ADMIN_CONSOLE_USER_NAME | N1: HCM_ADMIN_CONSOLE_USER_PHONE_NUMBER | O1: HCM_ADMIN_CONSOLE_USER_ROLE_MULTISELECT_1 | P1: HCM_ADMIN_CONSOLE_USER_ROLE_MULTISELECT_2 | Q1: HCM_ADMIN_CONSOLE_USER_ROLE_MULTISELECT_3 | R1: HCM_ADMIN_CONSOLE_USER_ROLE_MULTISELECT_4 | S1: HCM_ADMIN_CONSOLE_USER_ROLE_MULTISELECT_5 | T1: HCM_ADMIN_CONSOLE_USER_ROLE | U1: HCM_ADMIN_CONSOLE_USER_EMPLOYMENT_TYPE | V1: HCM_ADMIN_CONSOLE_USER_USAGE | W1: UserName | X1: HCM_ADMIN_CONSOLE_USER_WORKER_ID | Y1: HCM_ADMIN_CONSOLE_USER_PAYMENT_PROVIDER | Z1: HCM_ADMIN_CONSOLE_USER_PAYEE_PHONE_NUMBER | AA1: HCM_ADMIN_CONSOLE_USER_PAYEE_NAME | AB1: HCM_ADMIN_CONSOLE_USER_BANK_ACCOUNT | AC1: HCM_ADMIN_CONSOLE_USER_BANK_CODE | AD1: Password | AE1: UserService Uuids | AF1: #status# | AG1: #errorDetails#
A2: Country | B2: MICROPLAN_PROVINCE_HELPER | C2: Province | D2: MICROPLAN_DISTRICT_HELPER | E2: District | F2: MICROPLAN_ADMINISTRATIVEPOST_HELPER | G2: Administrative Post | H2: MICROPLAN_LOCALITY_HELPER | I2: Locality | J2: MICROPLAN_VILLAGE_HELPER | K2: Village | L2: Service Boundary Code | M2: Name | N2: Phone Number (Mandatory) | O2: User Role 1 | P2: User Role 2 | Q2: User Role 3 | R2: User Role 4 | S2: User Role 5 | T2: User Role | U2: Employment Type (Mandatory) | V2: Active / Inactive | W2: UserName | X2: User ID | Y2: Payment Provider | Z2: Payee Phone Number | AA2: Payee Name | AB2: Bank Account | AC2: Bank Code | AD2: Password | AE2: UserService Uuids | AF2: #status# | AG2: #errorDetails#
A3: Nigeria | B3: =IFERROR(INDEX(_h_SimpleLookup_h_!$I$16:$I$20,MATCH(CONCATENATE(INDIRECT("A"&ROW())),_h_SimpleLookup_h_!$H$16:$H$20,0)),"") -> H_04952a0f984dccfa1c401fbe5669c5342059049be3e2bba73dc5a481759b22a9 | D3: =IFERROR(INDEX(_h_SimpleLookup_h_!$I$16:$I$20,MATCH(CONCATENATE(INDIRECT("A"&ROW()), "#", INDIRECT("C"&ROW())),_h_SimpleLookup_h_!$H$16:$H$20,0)),"") | F3: =IFERROR(INDEX(_h_SimpleLookup_h_!$I$16:$I$20,MATCH(CONCATENATE(INDIRECT("A"&ROW()), "#", INDIRECT("C"&ROW()), "#", INDIRECT("E"&ROW())),_h_SimpleLookup_h_!$H$16:$H$20,0)),"") | H3: =IFERROR(INDEX(_h_SimpleLookup_h_!$I$16:$I$20,MATCH(CONCATENATE(INDIRECT("A"&ROW()), "#", INDIRECT("C"&ROW()), "#", INDIRECT("E"&ROW()), "#", INDIRECT("G"&ROW())),_h_SimpleLookup_h_!$H$16:$H$20,0)),"") | J3: =IFERROR(INDEX(_h_SimpleLookup_h_!$I$16:$I$20,MATCH(CONCATENATE(INDIRECT("A"&ROW()), "#", INDIRECT("C"&ROW()), "#", INDIRECT("E"&ROW()), "#", INDIRECT("G"&ROW()), "#", INDIRECT("I"&ROW())),_h_SimpleLookup_h_!$H$16:$H$20,0)),"") | L3: =IF(K3<>"",IFERROR(VLOOKUP(K3,_h_SimpleLookup_h_!$D$8:$E$13,2,0),""),IF(I3<>"",IFERROR(VLOOKUP(I3,_h_SimpleLookup_h_!$D$8:$E$13,2,0),""),IF(G3<>"",IFERROR(VLOOKUP(G3,_h_SimpleLookup_h_!$D$8:$E$13,2,0),""),IF(E3<>"",IFERROR(VLOOKUP(E3,_h_SimpleLookup_h_!$D$8:$E$13,2,0),""),IF(C3<>"",IFERROR(VLOOKUP(C3,_h_SimpleLookup_h_!$D$8:$E$13,2,0),""),IF(A3<>"",IFERROR(VLOOKUP(A3,_h_SimpleLookup_h_!$D$8:$E$13,2,0),""),"")))))) -> MICROPLAN_MO | M3: DISL1 | N3: 2859768546 | O3: DISTRIBUTOR | T3: =IF(AND(ISBLANK(O3),ISBLANK(P3),ISBLANK(Q3),ISBLANK(R3),ISBLANK(S3)),"",TRIM(CONCATENATE(IF(ISBLANK(O3),"",O3&","),IF(ISBLANK(P3),"",P3&","),IF(ISBLANK(Q3),"",Q3&","),IF(ISBLANK(R3),"",R3&","),IF(ISBLANK(S3),"",S3&",")))) -> DISTRIBUTOR, | U3: Temporary | V3: Active
A4: Nigeria | B4: =IFERROR(INDEX(_h_SimpleLookup_h_!$I$16:$I$20,MATCH(CONCATENATE(INDIRECT("A"&ROW())),_h_SimpleLookup_h_!$H$16:$H$20,0)),"") -> H_04952a0f984dccfa1c401fbe5669c5342059049be3e2bba73dc5a481759b22a9 | C4: Gaza | D4: =IFERROR(INDEX(_h_SimpleLookup_h_!$I$16:$I$20,MATCH(CONCATENATE(INDIRECT("A"&ROW()), "#", INDIRECT("C"&ROW())),_h_SimpleLookup_h_!$H$16:$H$20,0)),"") -> H_3d746386df8e70fc233233a9e10a429bbb45de06e238ef21fcff52d27fd51781 | F4: =IFERROR(INDEX(_h_SimpleLookup_h_!$I$16:$I$20,MATCH(CONCATENATE(INDIRECT("A"&ROW()), "#", INDIRECT("C"&ROW()), "#", INDIRECT("E"&ROW())),_h_SimpleLookup_h_!$H$16:$H$20,0)),"") | H4: =IFERROR(INDEX(_h_SimpleLookup_h_!$I$16:$I$20,MATCH(CONCATENATE(INDIRECT("A"&ROW()), "#", INDIRECT("C"&ROW()), "#", INDIRECT("E"&ROW()), "#", INDIRECT("G"&ROW())),_h_SimpleLookup_h_!$H$16:$H$20,0)),"") | J4: =IFERROR(INDEX(_h_SimpleLookup_h_!$I$16:$I$20,MATCH(CONCATENATE(INDIRECT("A"&ROW()), "#", INDIRECT("C"&ROW()), "#", INDIRECT("E"&ROW()), "#", INDIRECT("G"&ROW()), "#", INDIRECT("I"&ROW())),_h_SimpleLookup_h_!$H$16:$H$20,0)),"") | L4: =IF(K4<>"",IFERROR(VLOOKUP(K4,_h_SimpleLookup_h_!$D$8:$E$13,2,0),""),IF(I4<>"",IFERROR(VLOOKUP(I4,_h_SimpleLookup_h_!$D$8:$E$13,2,0),""),IF(G4<>"",IFERROR(VLOOKUP(G4,_h_SimpleLookup_h_!$D$8:$E$13,2,0),""),IF(E4<>"",IFERROR(VLOOKUP(E4,_h_SimpleLookup_h_!$D$8:$E$13,2,0),""),IF(C4<>"",IFERROR(VLOOKUP(C4,_h_SimpleLookup_h_!$D$8:$E$13,2,0),""),IF(A4<>"",IFERROR(VLOOKUP(A4,_h_SimpleLookup_h_!$D$8:$E$13,2,0),""),"")))))) -> MICROPLAN_MO_05_GAZA_TEST1 | M4: DISL2 | N4: 2859768547 | O4: DISTRIBUTOR | T4: =IF(AND(ISBLANK(O4),ISBLANK(P4),ISBLANK(Q4),ISBLANK(R4),ISBLANK(S4)),"",TRIM(CONCATENATE(IF(ISBLANK(O4),"",O4&","),IF(ISBLANK(P4),"",P4&","),IF(ISBLANK(Q4),"",Q4&","),IF(ISBLANK(R4),"",R4&","),IF(ISBLANK(S4),"",S4&",")))) -> DISTRIBUTOR, | U4: Temporary | V4: Active
A5: Nigeria | B5: =IFERROR(INDEX(_h_SimpleLookup_h_!$I$16:$I$20,MATCH(CONCATENATE(INDIRECT("A"&ROW())),_h_SimpleLookup_h_!$H$16:$H$20,0)),"") -> H_04952a0f984dccfa1c401fbe5669c5342059049be3e2bba73dc5a481759b22a9 | C5: Gaza | D5: =IFERROR(INDEX(_h_SimpleLookup_h_!$I$16:$I$20,MATCH(CONCATENATE(INDIRECT("A"&ROW()), "#", INDIRECT("C"&ROW())),_h_SimpleLookup_h_!$H$16:$H$20,0)),"") -> H_3d746386df8e70fc233233a9e10a429bbb45de06e238ef21fcff52d27fd51781 | E5: Chibuto | F5: =IFERROR(INDEX(_h_SimpleLookup_h_!$I$16:$I$20,MATCH(CONCATENATE(INDIRECT("A"&ROW()), "#", INDIRECT("C"&ROW()), "#", INDIRECT("E"&ROW())),_h_SimpleLookup_h_!$H$16:$H$20,0)),"") -> H_f8225e850582739dca18bbc9f1b87eec4a399a506bac01963630d2d5869939c4 | H5: =IFERROR(INDEX(_h_SimpleLookup_h_!$I$16:$I$20,MATCH(CONCATENATE(INDIRECT("A"&ROW()), "#", INDIRECT("C"&ROW()), "#", INDIRECT("E"&ROW()), "#", INDIRECT("G"&ROW())),_h_SimpleLookup_h_!$H$16:$H$20,0)),"") | J5: =IFERROR(INDEX(_h_SimpleLookup_h_!$I$16:$I$20,MATCH(CONCATENATE(INDIRECT("A"&ROW()), "#", INDIRECT("C"&ROW()), "#", INDIRECT("E"&ROW()), "#", INDIRECT("G"&ROW()), "#", INDIRECT("I"&ROW())),_h_SimpleLookup_h_!$H$16:$H$20,0)),"") | L5: =IF(K5<>"",IFERROR(VLOOKUP(K5,_h_SimpleLookup_h_!$D$8:$E$13,2,0),""),IF(I5<>"",IFERROR(VLOOKUP(I5,_h_SimpleLookup_h_!$D$8:$E$13,2,0),""),IF(G5<>"",IFERROR(VLOOKUP(G5,_h_SimpleLookup_h_!$D$8:$E$13,2,0),""),IF(E5<>"",IFERROR(VLOOKUP(E5,_h_SimpleLookup_h_!$D$8:$E$13,2,0),""),IF(C5<>"",IFERROR(VLOOKUP(C5,_h_SimpleLookup_h_!$D$8:$E$13,2,0),""),IF(A5<>"",IFERROR(VLOOKUP(A5,_h_SimpleLookup_h_!$D$8:$E$13,2,0),""),"")))))) -> MICROPLAN_MO_05_01_CHIBUTO_TEST1 | M5: DISL3 | N5: 2859768548 | O5: DISTRIBUTOR | T5: =IF(AND(ISBLANK(O5),ISBLANK(P5),ISBLANK(Q5),ISBLANK(R5),ISBLANK(S5)),"",TRIM(CONCATENATE(IF(ISBLANK(O5),"",O5&","),IF(ISBLANK(P5),"",P5&","),IF(ISBLANK(Q5),"",Q5&","),IF(ISBLANK(R5),"",R5&","),IF(ISBLANK(S5),"",S5&",")))) -> DISTRIBUTOR, | U5: Temporary | V5: Active
A6: Nigeria | B6: =IFERROR(INDEX(_h_SimpleLookup_h_!$I$16:$I$20,MATCH(CONCATENATE(INDIRECT("A"&ROW())),_h_SimpleLookup_h_!$H$16:$H$20,0)),"") -> H_04952a0f984dccfa1c401fbe5669c5342059049be3e2bba73dc5a481759b22a9 | C6: Gaza | D6: =IFERROR(INDEX(_h_SimpleLookup_h_!$I$16:$I$20,MATCH(CONCATENATE(INDIRECT("A"&ROW()), "#", INDIRECT("C"&ROW())),_h_SimpleLookup_h_!$H$16:$H$20,0)),"") -> H_3d746386df8e70fc233233a9e10a429bbb45de06e238ef21fcff52d27fd51781 | E6: Chibuto | F6: =IFERROR(INDEX(_h_SimpleLookup_h_!$I$16:$I$20,MATCH(CONCATENATE(INDIRECT("A"&ROW()), "#", INDIRECT("C"&ROW()), "#", INDIRECT("E"&ROW())),_h_SimpleLookup_h_!$H$16:$H$20,0)),"") -> H_f8225e850582739dca18bbc9f1b87eec4a399a506bac01963630d2d5869939c4 | G6: Chibutoo | H6: =IFERROR(INDEX(_h_SimpleLookup_h_!$I$16:$I$20,MATCH(CONCATENATE(INDIRECT("A"&ROW()), "#", INDIRECT("C"&ROW()), "#", INDIRECT("E"&ROW()), "#", INDIRECT("G"&ROW())),_h_SimpleLookup_h_!$H$16:$H$20,0)),"") -> H_9de166f1e87c37e01777111aa51a73d37bbe5559df989fc50fad851f9070f447 | J6: =IFERROR(INDEX(_h_SimpleLookup_h_!$I$16:$I$20,MATCH(CONCATENATE(INDIRECT("A"&ROW()), "#", INDIRECT("C"&ROW()), "#", INDIRECT("E"&ROW()), "#", INDIRECT("G"&ROW()), "#", INDIRECT("I"&ROW())),_h_SimpleLookup_h_!$H$16:$H$20,0)),"") | L6: =IF(K6<>"",IFERROR(VLOOKUP(K6,_h_SimpleLookup_h_!$D$8:$E$13,2,0),""),IF(I6<>"",IFERROR(VLOOKUP(I6,_h_SimpleLookup_h_!$D$8:$E$13,2,0),""),IF(G6<>"",IFERROR(VLOOKUP(G6,_h_SimpleLookup_h_!$D$8:$E$13,2,0),""),IF(E6<>"",IFERROR(VLOOKUP(E6,_h_SimpleLookup_h_!$D$8:$E$13,2,0),""),IF(C6<>"",IFERROR(VLOOKUP(C6,_h_SimpleLookup_h_!$D$8:$E$13,2,0),""),IF(A6<>"",IFERROR(VLOOKUP(A6,_h_SimpleLookup_h_!$D$8:$E$13,2,0),""),"")))))) -> MICROPLAN_MO_05_01_01_CHIBUTOO_TEST1 | M6: DISL4 | N6: 2859768549 | O6: DISTRIBUTOR | T6: =IF(AND(ISBLANK(O6),ISBLANK(P6),ISBLANK(Q6),ISBLANK(R6),ISBLANK(S6)),"",TRIM(CONCATENATE(IF(ISBLANK(O6),"",O6&","),IF(ISBLANK(P6),"",P6&","),IF(ISBLANK(Q6),"",Q6&","),IF(ISBLANK(R6),"",R6&","),IF(ISBLANK(S6),"",S6&",")))) -> DISTRIBUTOR, | U6: Temporary | V6: Active
A7: Nigeria | B7: =IFERROR(INDEX(_h_SimpleLookup_h_!$I$16:$I$20,MATCH(CONCATENATE(INDIRECT("A"&ROW())),_h_SimpleLookup_h_!$H$16:$H$20,0)),"") -> H_04952a0f984dccfa1c401fbe5669c5342059049be3e2bba73dc5a481759b22a9 | C7: Gaza | D7: =IFERROR(INDEX(_h_SimpleLookup_h_!$I$16:$I$20,MATCH(CONCATENATE(INDIRECT("A"&ROW()), "#", INDIRECT("C"&ROW())),_h_SimpleLookup_h_!$H$16:$H$20,0)),"") -> H_3d746386df8e70fc233233a9e10a429bbb45de06e238ef21fcff52d27fd51781 | E7: Chibuto | F7: =IFERROR(INDEX(_h_SimpleLookup_h_!$I$16:$I$20,MATCH(CONCATENATE(INDIRECT("A"&ROW()), "#", INDIRECT("C"&ROW()), "#", INDIRECT("E"&ROW())),_h_SimpleLookup_h_!$H$16:$H$20,0)),"") -> H_f8225e850582739dca18bbc9f1b87eec4a399a506bac01963630d2d5869939c4 | G7: Chibutoo | H7: =IFERROR(INDEX(_h_SimpleLookup_h_!$I$16:$I$20,MATCH(CONCATENATE(INDIRECT("A"&ROW()), "#", INDIRECT("C"&ROW()), "#", INDIRECT("E"&ROW()), "#", INDIRECT("G"&ROW())),_h_SimpleLookup_h_!$H$16:$H$20,0)),"") -> H_9de166f1e87c37e01777111aa51a73d37bbe5559df989fc50fad851f9070f447 | I7: Chibuto Sede | J7: =IFERROR(INDEX(_h_SimpleLookup_h_!$I$16:$I$20,MATCH(CONCATENATE(INDIRECT("A"&ROW()), "#", INDIRECT("C"&ROW()), "#", INDIRECT("E"&ROW()), "#", INDIRECT("G"&ROW()), "#", INDIRECT("I"&ROW())),_h_SimpleLookup_h_!$H$16:$H$20,0)),"") -> H_e9c3596c6f157c143621a34465e5390d1264415e6840e00130c0b1805b8f179c | L7: =IF(K7<>"",IFERROR(VLOOKUP(K7,_h_SimpleLookup_h_!$D$8:$E$13,2,0),""),IF(I7<>"",IFERROR(VLOOKUP(I7,_h_SimpleLookup_h_!$D$8:$E$13,2,0),""),IF(G7<>"",IFERROR(VLOOKUP(G7,_h_SimpleLookup_h_!$D$8:$E$13,2,0),""),IF(E7<>"",IFERROR(VLOOKUP(E7,_h_SimpleLookup_h_!$D$8:$E$13,2,0),""),IF(C7<>"",IFERROR(VLOOKUP(C7,_h_SimpleLookup_h_!$D$8:$E$13,2,0),""),IF(A7<>"",IFERROR(VLOOKUP(A7,_h_SimpleLookup_h_!$D$8:$E$13,2,0),""),"")))))) -> MICROPLAN_MO_05_01_01_01_CHIBUTO_SEDE_TEST1 | M7: DISL5 | N7: 2859768550 | O7: DISTRIBUTOR | T7: =IF(AND(ISBLANK(O7),ISBLANK(P7),ISBLANK(Q7),ISBLANK(R7),ISBLANK(S7)),"",TRIM(CONCATENATE(IF(ISBLANK(O7),"",O7&","),IF(ISBLANK(P7),"",P7&","),IF(ISBLANK(Q7),"",Q7&","),IF(ISBLANK(R7),"",R7&","),IF(ISBLANK(S7),"",S7&",")))) -> DISTRIBUTOR, | U7: Temporary | V7: Active
A8: Nigeria | B8: =IFERROR(INDEX(_h_SimpleLookup_h_!$I$16:$I$20,MATCH(CONCATENATE(INDIRECT("A"&ROW())),_h_SimpleLookup_h_!$H$16:$H$20,0)),"") -> H_04952a0f984dccfa1c401fbe5669c5342059049be3e2bba73dc5a481759b22a9 | C8: Gaza | D8: =IFERROR(INDEX(_h_SimpleLookup_h_!$I$16:$I$20,MATCH(CONCATENATE(INDIRECT("A"&ROW()), "#", INDIRECT("C"&ROW())),_h_SimpleLookup_h_!$H$16:$H$20,0)),"") -> H_3d746386df8e70fc233233a9e10a429bbb45de06e238ef21fcff52d27fd51781 | E8: Chibuto | F8: =IFERROR(INDEX(_h_SimpleLookup_h_!$I$16:$I$20,MATCH(CONCATENATE(INDIRECT("A"&ROW()), "#", INDIRECT("C"&ROW()), "#", INDIRECT("E"&ROW())),_h_SimpleLookup_h_!$H$16:$H$20,0)),"") -> H_f8225e850582739dca18bbc9f1b87eec4a399a506bac01963630d2d5869939c4 | G8: Chibutoo | H8: =IFERROR(INDEX(_h_SimpleLookup_h_!$I$16:$I$20,MATCH(CONCATENATE(INDIRECT("A"&ROW()), "#", INDIRECT("C"&ROW()), "#", INDIRECT("E"&ROW()), "#", INDIRECT("G"&ROW())),_h_SimpleLookup_h_!$H$16:$H$20,0)),"") -> H_9de166f1e87c37e01777111aa51a73d37bbe5559df989fc50fad851f9070f447 | I8: Chibuto Sede | J8: =IFERROR(INDEX(_h_SimpleLookup_h_!$I$16:$I$20,MATCH(CONCATENATE(INDIRECT("A"&ROW()), "#", INDIRECT("C"&ROW()), "#", INDIRECT("E"&ROW()), "#", INDIRECT("G"&ROW()), "#", INDIRECT("I"&ROW())),_h_SimpleLookup_h_!$H$16:$H$20,0)),"") -> H_e9c3596c6f157c143621a34465e5390d1264415e6840e00130c0b1805b8f179c | K8: Mapa | L8: =IF(K8<>"",IFERROR(VLOOKUP(K8,_h_SimpleLookup_h_!$D$8:$E$13,2,0),""),IF(I8<>"",IFERROR(VLOOKUP(I8,_h_SimpleLookup_h_!$D$8:$E$13,2,0),""),IF(G8<>"",IFERROR(VLOOKUP(G8,_h_SimpleLookup_h_!$D$8:$E$13,2,0),""),IF(E8<>"",IFERROR(VLOOKUP(E8,_h_SimpleLookup_h_!$D$8:$E$13,2,0),""),IF(C8<>"",IFERROR(VLOOKUP(C8,_h_SimpleLookup_h_!$D$8:$E$13,2,0),""),IF(A8<>"",IFERROR(VLOOKUP(A8,_h_SimpleLookup_h_!$D$8:$E$13,2,0),""),"")))))) -> MICROPLAN_MO_05_01_01_01_01_MAPA_TEST1 | M8: DISL6 | N8: 2859768551 | O8: DISTRIBUTOR | T8: =IF(AND(ISBLANK(O8),ISBLANK(P8),ISBLANK(Q8),ISBLANK(R8),ISBLANK(S8)),"",TRIM(CONCATENATE(IF(ISBLANK(O8),"",O8&","),IF(ISBLANK(P8),"",P8&","),IF(ISBLANK(Q8),"",Q8&","),IF(ISBLANK(R8),"",R8&","),IF(ISBLANK(S8),"",S8&",")))) -> DISTRIBUTOR, | U8: Temporary | V8: Active
A9: Nigeria | B9: =IFERROR(INDEX(_h_SimpleLookup_h_!$I$16:$I$20,MATCH(CONCATENATE(INDIRECT("A"&ROW())),_h_SimpleLookup_h_!$H$16:$H$20,0)),"") -> H_04952a0f984dccfa1c401fbe5669c5342059049be3e2bba73dc5a481759b22a9 | D9: =IFERROR(INDEX(_h_SimpleLookup_h_!$I$16:$I$20,MATCH(CONCATENATE(INDIRECT("A"&ROW()), "#", INDIRECT("C"&ROW())),_h_SimpleLookup_h_!$H$16:$H$20,0)),"") | F9: =IFERROR(INDEX(_h_SimpleLookup_h_!$I$16:$I$20,MATCH(CONCATENATE(INDIRECT("A"&ROW()), "#", INDIRECT("C"&ROW()), "#", INDIRECT("E"&ROW())),_h_SimpleLookup_h_!$H$16:$H$20,0)),"") | H9: =IFERROR(INDEX(_h_SimpleLookup_h_!$I$16:$I$20,MATCH(CONCATENATE(INDIRECT("A"&ROW()), "#", INDIRECT("C"&ROW()), "#", INDIRECT("E"&ROW()), "#", INDIRECT("G"&ROW())),_h_SimpleLookup_h_!$H$16:$H$20,0)),"") | J9: =IFERROR(INDEX(_h_SimpleLookup_h_!$I$16:$I$20,MATCH(CONCATENATE(INDIRECT("A"&ROW()), "#", INDIRECT("C"&ROW()), "#", INDIRECT("E"&ROW()), "#", INDIRECT("G"&ROW()), "#", INDIRECT("I"&ROW())),_h_SimpleLookup_h_!$H$16:$H$20,0)),"") | L9: =IF(K9<>"",IFERROR(VLOOKUP(K9,_h_SimpleLookup_h_!$D$8:$E$13,2,0),""),IF(I9<>"",IFERROR(VLOOKUP(I9,_h_SimpleLookup_h_!$D$8:$E$13,2,0),""),IF(G9<>"",IFERROR(VLOOKUP(G9,_h_SimpleLookup_h_!$D$8:$E$13,2,0),""),IF(E9<>"",IFERROR(VLOOKUP(E9,_h_SimpleLookup_h_!$D$8:$E$13,2,0),""),IF(C9<>"",IFERROR(VLOOKUP(C9,_h_SimpleLookup_h_!$D$8:$E$13,2,0),""),IF(A9<>"",IFERROR(VLOOKUP(A9,_h_SimpleLookup_h_!$D$8:$E$13,2,0),""),"")))))) -> MICROPLAN_MO | M9: HFL1 | N9: 2859768552 | O9: HEALTH_FACILITY_WORKER | T9: =IF(AND(ISBLANK(O9),ISBLANK(P9),ISBLANK(Q9),ISBLANK(R9),ISBLANK(S9)),"",TRIM(CONCATENATE(IF(ISBLANK(O9),"",O9&","),IF(ISBLANK(P9),"",P9&","),IF(ISBLANK(Q9),"",Q9&","),IF(ISBLANK(R9),"",R9&","),IF(ISBLANK(S9),"",S9&",")))) -> HEALTH_FACILITY_WORKER, | U9: Temporary | V9: Active
A10: Nigeria | B10: =IFERROR(INDEX(_h_SimpleLookup_h_!$I$16:$I$20,MATCH(CONCATENATE(INDIRECT("A"&ROW())),_h_SimpleLookup_h_!$H$16:$H$20,0)),"") -> H_04952a0f984dccfa1c401fbe5669c5342059049be3e2bba73dc5a481759b22a9 | C10: Gaza | D10: =IFERROR(INDEX(_h_SimpleLookup_h_!$I$16:$I$20,MATCH(CONCATENATE(INDIRECT("A"&ROW()), "#", INDIRECT("C"&ROW())),_h_SimpleLookup_h_!$H$16:$H$20,0)),"") -> H_3d746386df8e70fc233233a9e10a429bbb45de06e238ef21fcff52d27fd51781 | F10: =IFERROR(INDEX(_h_SimpleLookup_h_!$I$16:$I$20,MATCH(CONCATENATE(INDIRECT("A"&ROW()), "#", INDIRECT("C"&ROW()), "#", INDIRECT("E"&ROW())),_h_SimpleLookup_h_!$H$16:$H$20,0)),"") | H10: =IFERROR(INDEX(_h_SimpleLookup_h_!$I$16:$I$20,MATCH(CONCATENATE(INDIRECT("A"&ROW()), "#", INDIRECT("C"&ROW()), "#", INDIRECT("E"&ROW()), "#", INDIRECT("G"&ROW())),_h_SimpleLookup_h_!$H$16:$H$20,0)),"") | J10: =IFERROR(INDEX(_h_SimpleLookup_h_!$I$16:$I$20,MATCH(CONCATENATE(INDIRECT("A"&ROW()), "#", INDIRECT("C"&ROW()), "#", INDIRECT("E"&ROW()), "#", INDIRECT("G"&ROW()), "#", INDIRECT("I"&ROW())),_h_SimpleLookup_h_!$H$16:$H$20,0)),"") | L10: =IF(K10<>"",IFERROR(VLOOKUP(K10,_h_SimpleLookup_h_!$D$8:$E$13,2,0),""),IF(I10<>"",IFERROR(VLOOKUP(I10,_h_SimpleLookup_h_!$D$8:$E$13,2,0),""),IF(G10<>"",IFERROR(VLOOKUP(G10,_h_SimpleLookup_h_!$D$8:$E$13,2,0),""),IF(E10<>"",IFERROR(VLOOKUP(E10,_h_SimpleLookup_h_!$D$8:$E$13,2,0),""),IF(C10<>"",IFERROR(VLOOKUP(C10,_h_SimpleLookup_h_!$D$8:$E$13,2,0),""),IF(A10<>"",IFERROR(VLOOKUP(A10,_h_SimpleLookup_h_!$D$8:$E$13,2,0),""),"")))))) -> MICROPLAN_MO_05_GAZA_TEST1 | M10: HFL2 | N10: 2859768553 | O10: HEALTH_FACILITY_WORKER | T10: =IF(AND(ISBLANK(O10),ISBLANK(P10),ISBLANK(Q10),ISBLANK(R10),ISBLANK(S10)),"",TRIM(CONCATENATE(IF(ISBLANK(O10),"",O10&","),IF(ISBLANK(P10),"",P10&","),IF(ISBLANK(Q10),"",Q10&","),IF(ISBLANK(R10),"",R10&","),IF(ISBLANK(S10),"",S10&",")))) -> HEALTH_FACILITY_WORKER, | U10: Temporary | V10: Active
A11: Nigeria | B11: =IFERROR(INDEX(_h_SimpleLookup_h_!$I$16:$I$20,MATCH(CONCATENATE(INDIRECT("A"&ROW())),_h_SimpleLookup_h_!$H$16:$H$20,0)),"") -> H_04952a0f984dccfa1c401fbe5669c5342059049be3e2bba73dc5a481759b22a9 | C11: Gaza | D11: =IFERROR(INDEX(_h_SimpleLookup_h_!$I$16:$I$20,MATCH(CONCATENATE(INDIRECT("A"&ROW()), "#", INDIRECT("C"&ROW())),_h_SimpleLookup_h_!$H$16:$H$20,0)),"") -> H_3d746386df8e70fc233233a9e10a429bbb45de06e238ef21fcff52d27fd51781 | E11: Chibuto | F11: =IFERROR(INDEX(_h_SimpleLookup_h_!$I$16:$I$20,MATCH(CONCATENATE(INDIRECT("A"&ROW()), "#", INDIRECT("C"&ROW()), "#", INDIRECT("E"&ROW())),_h_SimpleLookup_h_!$H$16:$H$20,0)),"") -> H_f8225e850582739dca18bbc9f1b87eec4a399a506bac01963630d2d5869939c4 | H11: =IFERROR(INDEX(_h_SimpleLookup_h_!$I$16:$I$20,MATCH(CONCATENATE(INDIRECT("A"&ROW()), "#", INDIRECT("C"&ROW()), "#", INDIRECT("E"&ROW()), "#", INDIRECT("G"&ROW())),_h_SimpleLookup_h_!$H$16:$H$20,0)),"") | J11: =IFERROR(INDEX(_h_SimpleLookup_h_!$I$16:$I$20,MATCH(CONCATENATE(INDIRECT("A"&ROW()), "#", INDIRECT("C"&ROW()), "#", INDIRECT("E"&ROW()), "#", INDIRECT("G"&ROW()), "#", INDIRECT("I"&ROW())),_h_SimpleLookup_h_!$H$16:$H$20,0)),"") | L11: =IF(K11<>"",IFERROR(VLOOKUP(K11,_h_SimpleLookup_h_!$D$8:$E$13,2,0),""),IF(I11<>"",IFERROR(VLOOKUP(I11,_h_SimpleLookup_h_!$D$8:$E$13,2,0),""),IF(G11<>"",IFERROR(VLOOKUP(G11,_h_SimpleLookup_h_!$D$8:$E$13,2,0),""),IF(E11<>"",IFERROR(VLOOKUP(E11,_h_SimpleLookup_h_!$D$8:$E$13,2,0),""),IF(C11<>"",IFERROR(VLOOKUP(C11,_h_SimpleLookup_h_!$D$8:$E$13,2,0),""),IF(A11<>"",IFERROR(VLOOKUP(A11,_h_SimpleLookup_h_!$D$8:$E$13,2,0),""),"")))))) -> MICROPLAN_MO_05_01_CHIBUTO_TEST1 | M11: HFL3 | N11: 2859768554 | O11: HEALTH_FACILITY_WORKER | T11: =IF(AND(ISBLANK(O11),ISBLANK(P11),ISBLANK(Q11),ISBLANK(R11),ISBLANK(S11)),"",TRIM(CONCATENATE(IF(ISBLANK(O11),"",O11&","),IF(ISBLANK(P11),"",P11&","),IF(ISBLANK(Q11),"",Q11&","),IF(ISBLANK(R11),"",R11&","),IF(ISBLANK(S11),"",S11&",")))) -> HEALTH_FACILITY_WORKER, | U11: Temporary | V11: Active
A12: Nigeria | B12: =IFERROR(INDEX(_h_SimpleLookup_h_!$I$16:$I$20,MATCH(CONCATENATE(INDIRECT("A"&ROW())),_h_SimpleLookup_h_!$H$16:$H$20,0)),"") -> H_04952a0f984dccfa1c401fbe5669c5342059049be3e2bba73dc5a481759b22a9 | C12: Gaza | D12: =IFERROR(INDEX(_h_SimpleLookup_h_!$I$16:$I$20,MATCH(CONCATENATE(INDIRECT("A"&ROW()), "#", INDIRECT("C"&ROW())),_h_SimpleLookup_h_!$H$16:$H$20,0)),"") -> H_3d746386df8e70fc233233a9e10a429bbb45de06e238ef21fcff52d27fd51781 | E12: Chibuto | F12: =IFERROR(INDEX(_h_SimpleLookup_h_!$I$16:$I$20,MATCH(CONCATENATE(INDIRECT("A"&ROW()), "#", INDIRECT("C"&ROW()), "#", INDIRECT("E"&ROW())),_h_SimpleLookup_h_!$H$16:$H$20,0)),"") -> H_f8225e850582739dca18bbc9f1b87eec4a399a506bac01963630d2d5869939c4 | G12: Chibutoo | H12: =IFERROR(INDEX(_h_SimpleLookup_h_!$I$16:$I$20,MATCH(CONCATENATE(INDIRECT("A"&ROW()), "#", INDIRECT("C"&ROW()), "#", INDIRECT("E"&ROW()), "#", INDIRECT("G"&ROW())),_h_SimpleLookup_h_!$H$16:$H$20,0)),"") -> H_9de166f1e87c37e01777111aa51a73d37bbe5559df989fc50fad851f9070f447 | J12: =IFERROR(INDEX(_h_SimpleLookup_h_!$I$16:$I$20,MATCH(CONCATENATE(INDIRECT("A"&ROW()), "#", INDIRECT("C"&ROW()), "#", INDIRECT("E"&ROW()), "#", INDIRECT("G"&ROW()), "#", INDIRECT("I"&ROW())),_h_SimpleLookup_h_!$H$16:$H$20,0)),"") | L12: =IF(K12<>"",IFERROR(VLOOKUP(K12,_h_SimpleLookup_h_!$D$8:$E$13,2,0),""),IF(I12<>"",IFERROR(VLOOKUP(I12,_h_SimpleLookup_h_!$D$8:$E$13,2,0),""),IF(G12<>"",IFERROR(VLOOKUP(G12,_h_SimpleLookup_h_!$D$8:$E$13,2,0),""),IF(E12<>"",IFERROR(VLOOKUP(E12,_h_SimpleLookup_h_!$D$8:$E$13,2,0),""),IF(C12<>"",IFERROR(VLOOKUP(C12,_h_SimpleLookup_h_!$D$8:$E$13,2,0),""),IF(A12<>"",IFERROR(VLOOKUP(A12,_h_SimpleLookup_h_!$D$8:$E$13,2,0),""),"")))))) -> MICROPLAN_MO_05_01_01_CHIBUTOO_TEST1 | M12: HFL4 | N12: 2859768555 | O12: HEALTH_FACILITY_WORKER | T12: =IF(AND(ISBLANK(O12),ISBLANK(P12),ISBLANK(Q12),ISBLANK(R12),ISBLANK(S12)),"",TRIM(CONCATENATE(IF(ISBLANK(O12),"",O12&","),IF(ISBLANK(P12),"",P12&","),IF(ISBLANK(Q12),"",Q12&","),IF(ISBLANK(R12),"",R12&","),IF(ISBLANK(S12),"",S12&",")))) -> HEALTH_FACILITY_WORKER, | U12: Temporary | V12: Active
A13: Nigeria | B13: =IFERROR(INDEX(_h_SimpleLookup_h_!$I$16:$I$20,MATCH(CONCATENATE(INDIRECT("A"&ROW())),_h_SimpleLookup_h_!$H$16:$H$20,0)),"") -> H_04952a0f984dccfa1c401fbe5669c5342059049be3e2bba73dc5a481759b22a9 | C13: Gaza | D13: =IFERROR(INDEX(_h_SimpleLookup_h_!$I$16:$I$20,MATCH(CONCATENATE(INDIRECT("A"&ROW()), "#", INDIRECT("C"&ROW())),_h_SimpleLookup_h_!$H$16:$H$20,0)),"") -> H_3d746386df8e70fc233233a9e10a429bbb45de06e238ef21fcff52d27fd51781 | E13: Chibuto | F13: =IFERROR(INDEX(_h_SimpleLookup_h_!$I$16:$I$20,MATCH(CONCATENATE(INDIRECT("A"&ROW()), "#", INDIRECT("C"&ROW()), "#", INDIRECT("E"&ROW())),_h_SimpleLookup_h_!$H$16:$H$20,0)),"") -> H_f8225e850582739dca18bbc9f1b87eec4a399a506bac01963630d2d5869939c4 | G13: Chibutoo | H13: =IFERROR(INDEX(_h_SimpleLookup_h_!$I$16:$I$20,MATCH(CONCATENATE(INDIRECT("A"&ROW()), "#", INDIRECT("C"&ROW()), "#", INDIRECT("E"&ROW()), "#", INDIRECT("G"&ROW())),_h_SimpleLookup_h_!$H$16:$H$20,0)),"") -> H_9de166f1e87c37e01777111aa51a73d37bbe5559df989fc50fad851f9070f447 | I13: Chibuto Sede | J13: =IFERROR(INDEX(_h_SimpleLookup_h_!$I$16:$I$20,MATCH(CONCATENATE(INDIRECT("A"&ROW()), "#", INDIRECT("C"&ROW()), "#", INDIRECT("E"&ROW()), "#", INDIRECT("G"&ROW()), "#", INDIRECT("I"&ROW())),_h_SimpleLookup_h_!$H$16:$H$20,0)),"") -> H_e9c3596c6f157c143621a34465e5390d1264415e6840e00130c0b1805b8f179c | L13: =IF(K13<>"",IFERROR(VLOOKUP(K13,_h_SimpleLookup_h_!$D$8:$E$13,2,0),""),IF(I13<>"",IFERROR(VLOOKUP(I13,_h_SimpleLookup_h_!$D$8:$E$13,2,0),""),IF(G13<>"",IFERROR(VLOOKUP(G13,_h_SimpleLookup_h_!$D$8:$E$13,2,0),""),IF(E13<>"",IFERROR(VLOOKUP(E13,_h_SimpleLookup_h_!$D$8:$E$13,2,0),""),IF(C13<>"",IFERROR(VLOOKUP(C13,_h_SimpleLookup_h_!$D$8:$E$13,2,0),""),IF(A13<>"",IFERROR(VLOOKUP(A13,_h_SimpleLookup_h_!$D$8:$E$13,2,0),""),"")))))) -> MICROPLAN_MO_05_01_01_01_CHIBUTO_SEDE_TEST1 | M13: HFL5 | N13: 2859768556 | O13: HEALTH_FACILITY_WORKER | T13: =IF(AND(ISBLANK(O13),ISBLANK(P13),ISBLANK(Q13),ISBLANK(R13),ISBLANK(S13)),"",TRIM(CONCATENATE(IF(ISBLANK(O13),"",O13&","),IF(ISBLANK(P13),"",P13&","),IF(ISBLANK(Q13),"",Q13&","),IF(ISBLANK(R13),"",R13&","),IF(ISBLANK(S13),"",S13&",")))) -> HEALTH_FACILITY_WORKER, | U13: Temporary | V13: Active
A14: Nigeria | B14: =IFERROR(INDEX(_h_SimpleLookup_h_!$I$16:$I$20,MATCH(CONCATENATE(INDIRECT("A"&ROW())),_h_SimpleLookup_h_!$H$16:$H$20,0)),"") -> H_04952a0f984dccfa1c401fbe5669c5342059049be3e2bba73dc5a481759b22a9 | C14: Gaza | D14: =IFERROR(INDEX(_h_SimpleLookup_h_!$I$16:$I$20,MATCH(CONCATENATE(INDIRECT("A"&ROW()), "#", INDIRECT("C"&ROW())),_h_SimpleLookup_h_!$H$16:$H$20,0)),"") -> H_3d746386df8e70fc233233a9e10a429bbb45de06e238ef21fcff52d27fd51781 | E14: Chibuto | F14: =IFERROR(INDEX(_h_SimpleLookup_h_!$I$16:$I$20,MATCH(CONCATENATE(INDIRECT("A"&ROW()), "#", INDIRECT("C"&ROW()), "#", INDIRECT("E"&ROW())),_h_SimpleLookup_h_!$H$16:$H$20,0)),"") -> H_f8225e850582739dca18bbc9f1b87eec4a399a506bac01963630d2d5869939c4 | G14: Chibutoo | H14: =IFERROR(INDEX(_h_SimpleLookup_h_!$I$16:$I$20,MATCH(CONCATENATE(INDIRECT("A"&ROW()), "#", INDIRECT("C"&ROW()), "#", INDIRECT("E"&ROW()), "#", INDIRECT("G"&ROW())),_h_SimpleLookup_h_!$H$16:$H$20,0)),"") -> H_9de166f1e87c37e01777111aa51a73d37bbe5559df989fc50fad851f9070f447 | I14: Chibuto Sede | J14: =IFERROR(INDEX(_h_SimpleLookup_h_!$I$16:$I$20,MATCH(CONCATENATE(INDIRECT("A"&ROW()), "#", INDIRECT("C"&ROW()), "#", INDIRECT("E"&ROW()), "#", INDIRECT("G"&ROW()), "#", INDIRECT("I"&ROW())),_h_SimpleLookup_h_!$H$16:$H$20,0)),"") -> H_e9c3596c6f157c143621a34465e5390d1264415e6840e00130c0b1805b8f179c | K14: Mapa | L14: =IF(K14<>"",IFERROR(VLOOKUP(K14,_h_SimpleLookup_h_!$D$8:$E$13,2,0),""),IF(I14<>"",IFERROR(VLOOKUP(I14,_h_SimpleLookup_h_!$D$8:$E$13,2,0),""),IF(G14<>"",IFERROR(VLOOKUP(G14,_h_SimpleLookup_h_!$D$8:$E$13,2,0),""),IF(E14<>"",IFERROR(VLOOKUP(E14,_h_SimpleLookup_h_!$D$8:$E$13,2,0),""),IF(C14<>"",IFERROR(VLOOKUP(C14,_h_SimpleLookup_h_!$D$8:$E$13,2,0),""),IF(A14<>"",IFERROR(VLOOKUP(A14,_h_SimpleLookup_h_!$D$8:$E$13,2,0),""),"")))))) -> MICROPLAN_MO_05_01_01_01_01_MAPA_TEST1 | M14: HFL6 | N14: 2859768557 | O14: HEALTH_FACILITY_WORKER | T14: =IF(AND(ISBLANK(O14),ISBLANK(P14),ISBLANK(Q14),ISBLANK(R14),ISBLANK(S14)),"",TRIM(CONCATENATE(IF(ISBLANK(O14),"",O14&","),IF(ISBLANK(P14),"",P14&","),IF(ISBLANK(Q14),"",Q14&","),IF(ISBLANK(R14),"",R14&","),IF(ISBLANK(S14),"",S14&",")))) -> HEALTH_FACILITY_WORKER, | U14: Temporary | V14: Active
