Workbook

Sheet Facilities List
A1: NIGERIA_COUNTRY | B1: NIGERIA_STATE_HELPER | C1: NIGERIA_STATE | D1: NIGERIA_LGA_HELPER | E1: NIGERIA_LGA | F1: NIGERIA_WARD_HELPER | G1: NIGERIA_WARD | H1: NIGERIA_HEALTHFACILITY_HELPER | I1: NIGERIA_HEALTHFACILITY | J1: NIGERIA_VILLAGE_HELPER | K1: NIGERIA_VILLAGE | L1: HCM_ADMIN_CONSOLE_BOUNDARY_CODE | M1: HCM_ADMIN_CONSOLE_FACILITY_CODE | N1: HCM_ADMIN_CONSOLE_FACILITY_NAME | O1: HCM_ADMIN_CONSOLE_FACILITY_TYPE | P1: HCM_ADMIN_CONSOLE_FACILITY_STATUS | Q1: HCM_ADMIN_CONSOLE_FACILITY_CAPACITY | R1: HCM_ADMIN_CONSOLE_FACILITY_USAGE
A2: Country | B2: NIGERIA_STATE_HELPER | C2: State | D2: NIGERIA_LGA_HELPER | E2: LGA | F2: NIGERIA_WARD_HELPER | G2: Ward | H2: NIGERIA_HEALTHFACILITY_HELPER | I2: Health Facility | J2: NIGERIA_VILLAGE_HELPER | K2: Village | L2: Service Boundary Code | M2: Facility Code | N2: Facility Name | O2: Facility Type | P2: Facility Status | Q2: Capacity (Units: Bales for Bednets/ SPAQ Blister for SMC) | R2: Facility Usage
A3: Nigeria | B3: =IFERROR(INDEX(_h_SimpleLookup_h_!$J$59:$J$68,MATCH(CONCATENATE(INDIRECT("A"&ROW())),_h_SimpleLookup_h_!$I$59:$I$68,0)),"") -> H_fb6f8507bb42032f92d3fb39098d6015c7a2d1ef5850f24f0469a022b6bae7a6 | C3: Kaduna | D3: =IFERROR(INDEX(_h_SimpleLookup_h_!$J$59:$J$68,MATCH(CONCATENATE(INDIRECT("A"&ROW()), "#", INDIRECT("C"&ROW())),_h_SimpleLookup_h_!$I$59:$I$68,0)),"") -> H_2a2bf2599f027fcb0e1c647c7dcdba05fce783ba11b76c9b9900f47311a19ee4 | E3: Kachia | F3: =IFERROR(INDEX(_h_SimpleLookup_h_!$J$59:$J$68,MATCH(CONCATENATE(INDIRECT("A"&ROW()), "#", INDIRECT("C"&ROW()), "#", INDIRECT("E"&ROW())),_h_SimpleLookup_h_!$I$59:$I$68,0)),"") -> H_1487d1b2ba978586027ff36cb4b3f23a3349d18580e5f327ec230ce579ef0d8d | G3: Ankwa | H3: =IFERROR(INDEX(_h_SimpleLookup_h_!$J$59:$J$68,MATCH(CONCATENATE(INDIRECT("A"&ROW()), "#", INDIRECT("C"&ROW()), "#", INDIRECT("E"&ROW()), "#", INDIRECT("G"&ROW())),_h_SimpleLookup_h_!$I$59:$I$68,0)),"") -> H_019da8285b8f5a30ce41b7543a6551bfe93afdafd639f208c3f4f9474aca8e56 | I3: Abron Health Clinic | J3: =IFERROR(INDEX(_h_SimpleLookup_h_!$J$59:$J$68,MATCH(CONCATENATE(INDIRECT("A"&ROW()), "#", INDIRECT("C"&ROW()), "#", INDIRECT("E"&ROW()), "#", INDIRECT("G"&ROW()), "#", INDIRECT("I"&ROW())),_h_SimpleLookup_h_!$I$59:$I$68,0)),"") -> H_2f7448dc17e8b06c0a8a64cb3106ad85ff7c115b00d58195db1014fc59e5da80 | K3: Gidan Soda | L3: =IF(K3<>"",IFERROR(VLOOKUP(CONCATENATE(A3,"#",C3,"#",E3,"#",G3,"#",I3,"#",K3),_h_SimpleLookup_h_!$D$13:$E$56,2,0),""),IF(I3<>"",IFERROR(VLOOKUP(CONCATENATE(A3,"#",C3,"#",E3,"#",G3,"#",I3),_h_SimpleLookup_h_!$D$13:$E$56,2,0),""),IF(G3<>"",IFERROR(VLOOKUP(CONCATENATE(A3,"#",C3,"#",E3,"#",G3),_h_SimpleLookup_h_!$D$13:$E$56,2,0),""),IF(E3<>"",IFERROR(VLOOKUP(CONCATENATE(A3,"#",C3,"#",E3),_h_SimpleLookup_h_!$D$13:$E$56,2,0),""),IF(C3<>"",IFERROR(VLOOKUP(CONCATENATE(A3,"#",C3),_h_SimpleLookup_h_!$D$13:$E$56,2,0),""),IF(A3<>"",IFERROR(VLOOKUP(CONCATENATE(A3),_h_SimpleLookup_h_!$D$13:$E$56,2,0),""),"")))))) -> NIGERIA_NI_01_20_12_04_06_GIDAN_SODA | M3: F-2026-05-08-232376 | N3: Facility Storage Konobo | O3: Storing Resource | P3: Permanent | Q3: 200 | R3: Active
A4: Nigeria | B4: =IFERROR(INDEX(_h_SimpleLookup_h_!$J$59:$J$68,MATCH(CONCATENATE(INDIRECT("A"&ROW())),_h_SimpleLookup_h_!$I$59:$I$68,0)),"") -> H_fb6f8507bb42032f92d3fb39098d6015c7a2d1ef5850f24f0469a022b6bae7a6 | C4: Kaduna | D4: =IFERROR(INDEX(_h_SimpleLookup_h_!$J$59:$J$68,MATCH(CONCATENATE(INDIRECT("A"&ROW()), "#", INDIRECT("C"&ROW())),_h_SimpleLookup_h_!$I$59:$I$68,0)),"") -> H_2a2bf2599f027fcb0e1c647c7dcdba05fce783ba11b76c9b9900f47311a19ee4 | E4: Kachia | F4: =IFERROR(INDEX(_h_SimpleLookup_h_!$J$59:$J$68,MATCH(CONCATENATE(INDIRECT("A"&ROW()), "#", INDIRECT("C"&ROW()), "#", INDIRECT("E"&ROW())),_h_SimpleLookup_h_!$I$59:$I$68,0)),"") -> H_1487d1b2ba978586027ff36cb4b3f23a3349d18580e5f327ec230ce579ef0d8d | G4: Ankwa | H4: =IFERROR(INDEX(_h_SimpleLookup_h_!$J$59:$J$68,MATCH(CONCATENATE(INDIRECT("A"&ROW()), "#", INDIRECT("C"&ROW()), "#", INDIRECT("E"&ROW()), "#", INDIRECT("G"&ROW())),_h_SimpleLookup_h_!$I$59:$I$68,0)),"") -> H_019da8285b8f5a30ce41b7543a6551bfe93afdafd639f208c3f4f9474aca8e56 | I4: Abron Health Clinic | J4: =IFERROR(INDEX(_h_SimpleLookup_h_!$J$59:$J$68,MATCH(CONCATENATE(INDIRECT("A"&ROW()), "#", INDIRECT("C"&ROW()), "#", INDIRECT("E"&ROW()), "#", INDIRECT("G"&ROW()), "#", INDIRECT("I"&ROW())),_h_SimpleLookup_h_!$I$59:$I$68,0)),"") -> H_2f7448dc17e8b06c0a8a64cb3106ad85ff7c115b00d58195db1014fc59e5da80 | K4: Gidan Soda | L4: =IF(K4<>"",IFERROR(VLOOKUP(CONCATENATE(A4,"#",C4,"#",E4,"#",G4,"#",I4,"#",K4),_h_SimpleLookup_h_!$D$13:$E$56,2,0),""),IF(I4<>"",IFERROR(VLOOKUP(CONCATENATE(A4,"#",C4,"#",E4,"#",G4,"#",I4),_h_SimpleLookup_h_!$D$13:$E$56,2,0),""),IF(G4<>"",IFERROR(VLOOKUP(CONCATENATE(A4,"#",C4,"#",E4,"#",G4),_h_SimpleLookup_h_!$D$13:$E$56,2,0),""),IF(E4<>"",IFERROR(VLOOKUP(CONCATENATE(A4,"#",C4,"#",E4),_h_SimpleLookup_h_!$D$13:$E$56,2,0),""),IF(C4<>"",IFERROR(VLOOKUP(CONCATENATE(A4,"#",C4),_h_SimpleLookup_h_!$D$13:$E$56,2,0),""),IF(A4<>"",IFERROR(VLOOKUP(CONCATENATE(A4),_h_SimpleLookup_h_!$D$13:$E$56,2,0),""),"")))))) -> NIGERIA_NI_01_20_12_04_06_GIDAN_SODA | M4: F-2026-05-08-232377 | N4: Updated-Facility Storage Konobo | O4: Storing Resource | P4: Permanent | Q4: 200 | R4: Inactive
A5: Nigeria | B5: =IFERROR(INDEX(_h_SimpleLookup_h_!$J$59:$J$68,MATCH(CONCATENATE(INDIRECT("A"&ROW())),_h_SimpleLookup_h_!$I$59:$I$68,0)),"") -> H_fb6f8507bb42032f92d3fb39098d6015c7a2d1ef5850f24f0469a022b6bae7a6 | C5: Kaduna | D5: =IFERROR(INDEX(_h_SimpleLookup_h_!$J$59:$J$68,MATCH(CONCATENATE(INDIRECT("A"&ROW()), "#", INDIRECT("C"&ROW())),_h_SimpleLookup_h_!$I$59:$I$68,0)),"") -> H_2a2bf2599f027fcb0e1c647c7dcdba05fce783ba11b76c9b9900f47311a19ee4 | E5: Kachia | F5: =IFERROR(INDEX(_h_SimpleLookup_h_!$J$59:$J$68,MATCH(CONCATENATE(INDIRECT("A"&ROW()), "#", INDIRECT("C"&ROW()), "#", INDIRECT("E"&ROW())),_h_SimpleLookup_h_!$I$59:$I$68,0)),"") -> H_1487d1b2ba978586027ff36cb4b3f23a3349d18580e5f327ec230ce579ef0d8d | G5: Ankwa | H5: =IFERROR(INDEX(_h_SimpleLookup_h_!$J$59:$J$68,MATCH(CONCATENATE(INDIRECT("A"&ROW()), "#", INDIRECT("C"&ROW()), "#", INDIRECT("E"&ROW()), "#", INDIRECT("G"&ROW())),_h_SimpleLookup_h_!$I$59:$I$68,0)),"") -> H_019da8285b8f5a30ce41b7543a6551bfe93afdafd639f208c3f4f9474aca8e56 | J5: =IFERROR(INDEX(_h_SimpleLookup_h_!$J$59:$J$68,MATCH(CONCATENATE(INDIRECT("A"&ROW()), "#", INDIRECT("C"&ROW()), "#", INDIRECT("E"&ROW()), "#", INDIRECT("G"&ROW()), "#", INDIRECT("I"&ROW())),_h_SimpleLookup_h_!$I$59:$I$68,0)),"") | L5: =IF(K5<>"",IFERROR(VLOOKUP(CONCATENATE(A5,"#",C5,"#",E5,"#",G5,"#",I5,"#",K5),_h_SimpleLookup_h_!$D$13:$E$56,2,0),""),IF(I5<>"",IFERROR(VLOOKUP(CONCATENATE(A5,"#",C5,"#",E5,"#",G5,"#",I5),_h_SimpleLookup_h_!$D$13:$E$56,2,0),""),IF(G5<>"",IFERROR(VLOOKUP(CONCATENATE(A5,"#",C5,"#",E5,"#",G5),_h_SimpleLookup_h_!$D$13:$E$56,2,0),""),IF(E5<>"",IFERROR(VLOOKUP(CONCATENATE(A5,"#",C5,"#",E5),_h_SimpleLookup_h_!$D$13:$E$56,2,0),""),IF(C5<>"",IFERROR(VLOOKUP(CONCATENATE(A5,"#",C5),_h_SimpleLookup_h_!$D$13:$E$56,2,0),""),IF(A5<>"",IFERROR(VLOOKUP(CONCATENATE(A5),_h_SimpleLookup_h_!$D$13:$E$56,2,0),""),"")))))) -> NIGERIA_NI_01_20_12_ANKWA | M5: F-2026-06-01-232647 | N5: Ankwa Fac1 | O5: Warehouse | P5: Permanent | Q5: 400 | R5: Inactive
A6: Nigeria | B6: =IFERROR(INDEX(_h_SimpleLookup_h_!$J$59:$J$68,MATCH(CONCATENATE(INDIRECT("A"&ROW())),_h_SimpleLookup_h_!$I$59:$I$68,0)),"") -> H_fb6f8507bb42032f92d3fb39098d6015c7a2d1ef5850f24f0469a022b6bae7a6 | C6: Kaduna | D6: =IFERROR(INDEX(_h_SimpleLookup_h_!$J$59:$J$68,MATCH(CONCATENATE(INDIRECT("A"&ROW()), "#", INDIRECT("C"&ROW())),_h_SimpleLookup_h_!$I$59:$I$68,0)),"") -> H_2a2bf2599f027fcb0e1c647c7dcdba05fce783ba11b76c9b9900f47311a19ee4 | E6: Kachia | F6: =IFERROR(INDEX(_h_SimpleLookup_h_!$J$59:$J$68,MATCH(CONCATENATE(INDIRECT("A"&ROW()), "#", INDIRECT("C"&ROW()), "#", INDIRECT("E"&ROW())),_h_SimpleLookup_h_!$I$59:$I$68,0)),"") -> H_1487d1b2ba978586027ff36cb4b3f23a3349d18580e5f327ec230ce579ef0d8d | H6: =IFERROR(INDEX(_h_SimpleLookup_h_!$J$59:$J$68,MATCH(CONCATENATE(INDIRECT("A"&ROW()), "#", INDIRECT("C"&ROW()), "#", INDIRECT("E"&ROW()), "#", INDIRECT("G"&ROW())),_h_SimpleLookup_h_!$I$59:$I$68,0)),"") | J6: =IFERROR(INDEX(_h_SimpleLookup_h_!$J$59:$J$68,MATCH(CONCATENATE(INDIRECT("A"&ROW()), "#", INDIRECT("C"&ROW()), "#", INDIRECT("E"&ROW()), "#", INDIRECT("G"&ROW()), "#", INDIRECT("I"&ROW())),_h_SimpleLookup_h_!$I$59:$I$68,0)),"") | L6: =IF(K6<>"",IFERROR(VLOOKUP(CONCATENATE(A6,"#",C6,"#",E6,"#",G6,"#",I6,"#",K6),_h_SimpleLookup_h_!$D$13:$E$56,2,0),""),IF(I6<>"",IFERROR(VLOOKUP(CONCATENATE(A6,"#",C6,"#",E6,"#",G6,"#",I6),_h_SimpleLookup_h_!$D$13:$E$56,2,0),""),IF(G6<>"",IFERROR(VLOOKUP(CONCATENATE(A6,"#",C6,"#",E6,"#",G6),_h_SimpleLookup_h_!$D$13:$E$56,2,0),""),IF(E6<>"",IFERROR(VLOOKUP(CONCATENATE(A6,"#",C6,"#",E6),_h_SimpleLookup_h_!$D$13:$E$56,2,0),""),IF(C6<>"",IFERROR(VLOOKUP(CONCATENATE(A6,"#",C6),_h_SimpleLookup_h_!$D$13:$E$56,2,0),""),IF(A6<>"",IFERROR(VLOOKUP(CONCATENATE(A6),_h_SimpleLookup_h_!$D$13:$E$56,2,0),""),"")))))) -> NIGERIA_NI_01_20_KACHIA | M6: F-2026-06-01-232642 | N6: KachiaFac1 | O6: Storing Resource | P6: Permanent | Q6: 600 | R6: Inactive
A7: Nigeria | B7: =IFERROR(INDEX(_h_SimpleLookup_h_!$J$59:$J$68,MATCH(CONCATENATE(INDIRECT("A"&ROW())),_h_SimpleLookup_h_!$I$59:$I$68,0)),"") -> H_fb6f8507bb42032f92d3fb39098d6015c7a2d1ef5850f24f0469a022b6bae7a6 | C7: Kaduna | D7: =IFERROR(INDEX(_h_SimpleLookup_h_!$J$59:$J$68,MATCH(CONCATENATE(INDIRECT("A"&ROW()), "#", INDIRECT("C"&ROW())),_h_SimpleLookup_h_!$I$59:$I$68,0)),"") -> H_2a2bf2599f027fcb0e1c647c7dcdba05fce783ba11b76c9b9900f47311a19ee4 | F7: =IFERROR(INDEX(_h_SimpleLookup_h_!$J$59:$J$68,MATCH(CONCATENATE(INDIRECT("A"&ROW()), "#", INDIRECT("C"&ROW()), "#", INDIRECT("E"&ROW())),_h_SimpleLookup_h_!$I$59:$I$68,0)),"") | H7: =IFERROR(INDEX(_h_SimpleLookup_h_!$J$59:$J$68,MATCH(CONCATENATE(INDIRECT("A"&ROW()), "#", INDIRECT("C"&ROW()), "#", INDIRECT("E"&ROW()), "#", INDIRECT("G"&ROW())),_h_SimpleLookup_h_!$I$59:$I$68,0)),"") | J7: =IFERROR(INDEX(_h_SimpleLookup_h_!$J$59:$J$68,MATCH(CONCATENATE(INDIRECT("A"&ROW()), "#", INDIRECT("C"&ROW()), "#", INDIRECT("E"&ROW()), "#", INDIRECT("G"&ROW()), "#", INDIRECT("I"&ROW())),_h_SimpleLookup_h_!$I$59:$I$68,0)),"") | L7: =IF(K7<>"",IFERROR(VLOOKUP(CONCATENATE(A7,"#",C7,"#",E7,"#",G7,"#",I7,"#",K7),_h_SimpleLookup_h_!$D$13:$E$56,2,0),""),IF(I7<>"",IFERROR(VLOOKUP(CONCATENATE(A7,"#",C7,"#",E7,"#",G7,"#",I7),_h_SimpleLookup_h_!$D$13:$E$56,2,0),""),IF(G7<>"",IFERROR(VLOOKUP(CONCATENATE(A7,"#",C7,"#",E7,"#",G7),_h_SimpleLookup_h_!$D$13:$E$56,2,0),""),IF(E7<>"",IFERROR(VLOOKUP(CONCATENATE(A7,"#",C7,"#",E7),_h_SimpleLookup_h_!$D$13:$E$56,2,0),""),IF(C7<>"",IFERROR(VLOOKUP(CONCATENATE(A7,"#",C7),_h_SimpleLookup_h_!$D$13:$E$56,2,0),""),IF(A7<>"",IFERROR(VLOOKUP(CONCATENATE(A7),_h_SimpleLookup_h_!$D$13:$E$56,2,0),""),"")))))) -> NIGERIA_NI_01_KADUNA | M7: F-2026-06-01-232646 | N7: Kaduna Fac2 | O7: Health Facility | P7: Permanent | Q7: 800 | R7: Inactive
A8: Nigeria | B8: =IFERROR(INDEX(_h_SimpleLookup_h_!$J$59:$J$68,MATCH(CONCATENATE(INDIRECT("A"&ROW())),_h_SimpleLookup_h_!$I$59:$I$68,0)),"") -> H_fb6f8507bb42032f92d3fb39098d6015c7a2d1ef5850f24f0469a022b6bae7a6 | C8: Kaduna | D8: =IFERROR(INDEX(_h_SimpleLookup_h_!$J$59:$J$68,MATCH(CONCATENATE(INDIRECT("A"&ROW()), "#", INDIRECT("C"&ROW())),_h_SimpleLookup_h_!$I$59:$I$68,0)),"") -> H_2a2bf2599f027fcb0e1c647c7dcdba05fce783ba11b76c9b9900f47311a19ee4 | E8: Kachia | F8: =IFERROR(INDEX(_h_SimpleLookup_h_!$J$59:$J$68,MATCH(CONCATENATE(INDIRECT("A"&ROW()), "#", INDIRECT("C"&ROW()), "#", INDIRECT("E"&ROW())),_h_SimpleLookup_h_!$I$59:$I$68,0)),"") -> H_1487d1b2ba978586027ff36cb4b3f23a3349d18580e5f327ec230ce579ef0d8d | H8: =IFERROR(INDEX(_h_SimpleLookup_h_!$J$59:$J$68,MATCH(CONCATENATE(INDIRECT("A"&ROW()), "#", INDIRECT("C"&ROW()), "#", INDIRECT("E"&ROW()), "#", INDIRECT("G"&ROW())),_h_SimpleLookup_h_!$I$59:$I$68,0)),"") | J8: =IFERROR(INDEX(_h_SimpleLookup_h_!$J$59:$J$68,MATCH(CONCATENATE(INDIRECT("A"&ROW()), "#", INDIRECT("C"&ROW()), "#", INDIRECT("E"&ROW()), "#", INDIRECT("G"&ROW()), "#", INDIRECT("I"&ROW())),_h_SimpleLookup_h_!$I$59:$I$68,0)),"") | L8: =IF(K8<>"",IFERROR(VLOOKUP(CONCATENATE(A8,"#",C8,"#",E8,"#",G8,"#",I8,"#",K8),_h_SimpleLookup_h_!$D$13:$E$56,2,0),""),IF(I8<>"",IFERROR(VLOOKUP(CONCATENATE(A8,"#",C8,"#",E8,"#",G8,"#",I8),_h_SimpleLookup_h_!$D$13:$E$56,2,0),""),IF(G8<>"",IFERROR(VLOOKUP(CONCATENATE(A8,"#",C8,"#",E8,"#",G8),_h_SimpleLookup_h_!$D$13:$E$56,2,0),""),IF(E8<>"",IFERROR(VLOOKUP(CONCATENATE(A8,"#",C8,"#",E8),_h_SimpleLookup_h_!$D$13:$E$56,2,0),""),IF(C8<>"",IFERROR(VLOOKUP(CONCATENATE(A8,"#",C8),_h_SimpleLookup_h_!$D$13:$E$56,2,0),""),IF(A8<>"",IFERROR(VLOOKUP(CONCATENATE(A8),_h_SimpleLookup_h_!$D$13:$E$56,2,0),""),"")))))) -> NIGERIA_NI_01_20_KACHIA | M8: F-2026-06-01-232640 | N8: KachiaFac2 | O8: Storing Resource | P8: Permanent | Q8: 600 | R8: Inactive
A9: Nigeria | B9: =IFERROR(INDEX(_h_SimpleLookup_h_!$J$59:$J$68,MATCH(CONCATENATE(INDIRECT("A"&ROW())),_h_SimpleLookup_h_!$I$59:$I$68,0)),"") -> H_fb6f8507bb42032f92d3fb39098d6015c7a2d1ef5850f24f0469a022b6bae7a6 | C9: Kaduna | D9: =IFERROR(INDEX(_h_SimpleLookup_h_!$J$59:$J$68,MATCH(CONCATENATE(INDIRECT("A"&ROW()), "#", INDIRECT("C"&ROW())),_h_SimpleLookup_h_!$I$59:$I$68,0)),"") -> H_2a2bf2599f027fcb0e1c647c7dcdba05fce783ba11b76c9b9900f47311a19ee4 | E9: Kachia | F9: =IFERROR(INDEX(_h_SimpleLookup_h_!$J$59:$J$68,MATCH(CONCATENATE(INDIRECT("A"&ROW()), "#", INDIRECT("C"&ROW()), "#", INDIRECT("E"&ROW())),_h_SimpleLookup_h_!$I$59:$I$68,0)),"") -> H_1487d1b2ba978586027ff36cb4b3f23a3349d18580e5f327ec230ce579ef0d8d | G9: Ankwa | H9: =IFERROR(INDEX(_h_SimpleLookup_h_!$J$59:$J$68,MATCH(CONCATENATE(INDIRECT("A"&ROW()), "#", INDIRECT("C"&ROW()), "#", INDIRECT("E"&ROW()), "#", INDIRECT("G"&ROW())),_h_SimpleLookup_h_!$I$59:$I$68,0)),"") -> H_019da8285b8f5a30ce41b7543a6551bfe93afdafd639f208c3f4f9474aca8e56 | J9: =IFERROR(INDEX(_h_SimpleLookup_h_!$J$59:$J$68,MATCH(CONCATENATE(INDIRECT("A"&ROW()), "#", INDIRECT("C"&ROW()), "#", INDIRECT("E"&ROW()), "#", INDIRECT("G"&ROW()), "#", INDIRECT("I"&ROW())),_h_SimpleLookup_h_!$I$59:$I$68,0)),"") | L9: =IF(K9<>"",IFERROR(VLOOKUP(CONCATENATE(A9,"#",C9,"#",E9,"#",G9,"#",I9,"#",K9),_h_SimpleLookup_h_!$D$13:$E$56,2,0),""),IF(I9<>"",IFERROR(VLOOKUP(CONCATENATE(A9,"#",C9,"#",E9,"#",G9,"#",I9),_h_SimpleLookup_h_!$D$13:$E$56,2,0),""),IF(G9<>"",IFERROR(VLOOKUP(CONCATENATE(A9,"#",C9,"#",E9,"#",G9),_h_SimpleLookup_h_!$D$13:$E$56,2,0),""),IF(E9<>"",IFERROR(VLOOKUP(CONCATENATE(A9,"#",C9,"#",E9),_h_SimpleLookup_h_!$D$13:$E$56,2,0),""),IF(C9<>"",IFERROR(VLOOKUP(CONCATENATE(A9,"#",C9),_h_SimpleLookup_h_!$D$13:$E$56,2,0),""),IF(A9<>"",IFERROR(VLOOKUP(CONCATENATE(A9),_h_SimpleLookup_h_!$D$13:$E$56,2,0),""),"")))))) -> NIGERIA_NI_01_20_12_ANKWA | M9: F-2026-06-01-232649 | N9: Ankwa Fac2 | O9: Warehouse | P9: Permanent | Q9: 400 | R9: Inactive
A10: Nigeria | B10: =IFERROR(INDEX(_h_SimpleLookup_h_!$J$59:$J$68,MATCH(CONCATENATE(INDIRECT("A"&ROW())),_h_SimpleLookup_h_!$I$59:$I$68,0)),"") -> H_fb6f8507bb42032f92d3fb39098d6015c7a2d1ef5850f24f0469a022b6bae7a6 | D10: =IFERROR(INDEX(_h_SimpleLookup_h_!$J$59:$J$68,MATCH(CONCATENATE(INDIRECT("A"&ROW()), "#", INDIRECT("C"&ROW())),_h_SimpleLookup_h_!$I$59:$I$68,0)),"") | F10: =IFERROR(INDEX(_h_SimpleLookup_h_!$J$59:$J$68,MATCH(CONCATENATE(INDIRECT("A"&ROW()), "#", INDIRECT("C"&ROW()), "#", INDIRECT("E"&ROW())),_h_SimpleLookup_h_!$I$59:$I$68,0)),"") | H10: =IFERROR(INDEX(_h_SimpleLookup_h_!$J$59:$J$68,MATCH(CONCATENATE(INDIRECT("A"&ROW()), "#", INDIRECT("C"&ROW()), "#", INDIRECT("E"&ROW()), "#", INDIRECT("G"&ROW())),_h_SimpleLookup_h_!$I$59:$I$68,0)),"") | J10: =IFERROR(INDEX(_h_SimpleLookup_h_!$J$59:$J$68,MATCH(CONCATENATE(INDIRECT("A"&ROW()), "#", INDIRECT("C"&ROW()), "#", INDIRECT("E"&ROW()), "#", INDIRECT("G"&ROW()), "#", INDIRECT("I"&ROW())),_h_SimpleLookup_h_!$I$59:$I$68,0)),"") | L10: =IF(K10<>"",IFERROR(VLOOKUP(CONCATENATE(A10,"#",C10,"#",E10,"#",G10,"#",I10,"#",K10),_h_SimpleLookup_h_!$D$13:$E$56,2,0),""),IF(I10<>"",IFERROR(VLOOKUP(CONCATENATE(A10,"#",C10,"#",E10,"#",G10,"#",I10),_h_SimpleLookup_h_!$D$13:$E$56,2,0),""),IF(G10<>"",IFERROR(VLOOKUP(CONCATENATE(A10,"#",C10,"#",E10,"#",G10),_h_SimpleLookup_h_!$D$13:$E$56,2,0),""),IF(E10<>"",IFERROR(VLOOKUP(CONCATENATE(A10,"#",C10,"#",E10),_h_SimpleLookup_h_!$D$13:$E$56,2,0),""),IF(C10<>"",IFERROR(VLOOKUP(CONCATENATE(A10,"#",C10),_h_SimpleLookup_h_!$D$13:$E$56,2,0),""),IF(A10<>"",IFERROR(VLOOKUP(CONCATENATE(A10),_h_SimpleLookup_h_!$D$13:$E$56,2,0),""),"")))))) -> NIGERIA_NI | M10: F-2026-06-01-232648 | N10: Nig Fac1 | O10: Warehouse | P10: Permanent | Q10: 1000 | R10: Inactive
A11: Nigeria | B11: =IFERROR(INDEX(_h_SimpleLookup_h_!$J$59:$J$68,MATCH(CONCATENATE(INDIRECT("A"&ROW())),_h_SimpleLookup_h_!$I$59:$I$68,0)),"") -> H_fb6f8507bb42032f92d3fb39098d6015c7a2d1ef5850f24f0469a022b6bae7a6 | D11: =IFERROR(INDEX(_h_SimpleLookup_h_!$J$59:$J$68,MATCH(CONCATENATE(INDIRECT("A"&ROW()), "#", INDIRECT("C"&ROW())),_h_SimpleLookup_h_!$I$59:$I$68,0)),"") | F11: =IFERROR(INDEX(_h_SimpleLookup_h_!$J$59:$J$68,MATCH(CONCATENATE(INDIRECT("A"&ROW()), "#", INDIRECT("C"&ROW()), "#", INDIRECT("E"&ROW())),_h_SimpleLookup_h_!$I$59:$I$68,0)),"") | H11: =IFERROR(INDEX(_h_SimpleLookup_h_!$J$59:$J$68,MATCH(CONCATENATE(INDIRECT("A"&ROW()), "#", INDIRECT("C"&ROW()), "#", INDIRECT("E"&ROW()), "#", INDIRECT("G"&ROW())),_h_SimpleLookup_h_!$I$59:$I$68,0)),"") | J11: =IFERROR(INDEX(_h_SimpleLookup_h_!$J$59:$J$68,MATCH(CONCATENATE(INDIRECT("A"&ROW()), "#", INDIRECT("C"&ROW()), "#", INDIRECT("E"&ROW()), "#", INDIRECT("G"&ROW()), "#", INDIRECT("I"&ROW())),_h_SimpleLookup_h_!$I$59:$I$68,0)),"") | L11: =IF(K11<>"",IFERROR(VLOOKUP(CONCATENATE(A11,"#",C11,"#",E11,"#",G11,"#",I11,"#",K11),_h_SimpleLookup_h_!$D$13:$E$56,2,0),""),IF(I11<>"",IFERROR(VLOOKUP(CONCATENATE(A11,"#",C11,"#",E11,"#",G11,"#",I11),_h_SimpleLookup_h_!$D$13:$E$56,2,0),""),IF(G11<>"",IFERROR(VLOOKUP(CONCATENATE(A11,"#",C11,"#",E11,"#",G11),_h_SimpleLookup_h_!$D$13:$E$56,2,0),""),IF(E11<>"",IFERROR(VLOOKUP(CONCATENATE(A11,"#",C11,"#",E11),_h_SimpleLookup_h_!$D$13:$E$56,2,0),""),IF(C11<>"",IFERROR(VLOOKUP(CONCATENATE(A11,"#",C11),_h_SimpleLookup_h_!$D$13:$E$56,2,0),""),IF(A11<>"",IFERROR(VLOOKUP(CONCATENATE(A11),_h_SimpleLookup_h_!$D$13:$E$56,2,0),""),"")))))) -> NIGERIA_NI | M11: F-2026-06-01-232645 | N11: Nig Fac2 | O11: Warehouse | P11: Permanent | Q11: 1000 | R11: Inactive
A12: Nigeria | B12: =IFERROR(INDEX(_h_SimpleLookup_h_!$J$59:$J$68,MATCH(CONCATENATE(INDIRECT("A"&ROW())),_h_SimpleLookup_h_!$I$59:$I$68,0)),"") -> H_fb6f8507bb42032f92d3fb39098d6015c7a2d1ef5850f24f0469a022b6bae7a6 | C12: Kaduna | D12: =IFERROR(INDEX(_h_SimpleLookup_h_!$J$59:$J$68,MATCH(CONCATENATE(INDIRECT("A"&ROW()), "#", INDIRECT("C"&ROW())),_h_SimpleLookup_h_!$I$59:$I$68,0)),"") -> H_2a2bf2599f027fcb0e1c647c7dcdba05fce783ba11b76c9b9900f47311a19ee4 | E12: Kachia | F12: =IFERROR(INDEX(_h_SimpleLookup_h_!$J$59:$J$68,MATCH(CONCATENATE(INDIRECT("A"&ROW()), "#", INDIRECT("C"&ROW()), "#", INDIRECT("E"&ROW())),_h_SimpleLookup_h_!$I$59:$I$68,0)),"") -> H_1487d1b2ba978586027ff36cb4b3f23a3349d18580e5f327ec230ce579ef0d8d | G12: Ankwa | H12: =IFERROR(INDEX(_h_SimpleLookup_h_!$J$59:$J$68,MATCH(CONCATENATE(INDIRECT("A"&ROW()), "#", INDIRECT("C"&ROW()), "#", INDIRECT("E"&ROW()), "#", INDIRECT("G"&ROW())),_h_SimpleLookup_h_!$I$59:$I$68,0)),"") -> H_019da8285b8f5a30ce41b7543a6551bfe93afdafd639f208c3f4f9474aca8e56 | I12: Abron Health Clinic | J12: =IFERROR(INDEX(_h_SimpleLookup_h_!$J$59:$J$68,MATCH(CONCATENATE(INDIRECT("A"&ROW()), "#", INDIRECT("C"&ROW()), "#", INDIRECT("E"&ROW()), "#", INDIRECT("G"&ROW()), "#", INDIRECT("I"&ROW())),_h_SimpleLookup_h_!$I$59:$I$68,0)),"") -> H_2f7448dc17e8b06c0a8a64cb3106ad85ff7c115b00d58195db1014fc59e5da80 | L12: =IF(K12<>"",IFERROR(VLOOKUP(CONCATENATE(A12,"#",C12,"#",E12,"#",G12,"#",I12,"#",K12),_h_SimpleLookup_h_!$D$13:$E$56,2,0),""),IF(I12<>"",IFERROR(VLOOKUP(CONCATENATE(A12,"#",C12,"#",E12,"#",G12,"#",I12),_h_SimpleLookup_h_!$D$13:$E$56,2,0),""),IF(G12<>"",IFERROR(VLOOKUP(CONCATENATE(A12,"#",C12,"#",E12,"#",G12),_h_SimpleLookup_h_!$D$13:$E$56,2,0),""),IF(E12<>"",IFERROR(VLOOKUP(CONCATENATE(A12,"#",C12,"#",E12),_h_SimpleLookup_h_!$D$13:$E$56,2,0),""),IF(C12<>"",IFERROR(VLOOKUP(CONCATENATE(A12,"#",C12),_h_SimpleLookup_h_!$D$13:$E$56,2,0),""),IF(A12<>"",IFERROR(VLOOKUP(CONCATENATE(A12),_h_SimpleLookup_h_!$D$13:$E$56,2,0),""),"")))))) -> NIGERIA_NI_01_20_12_04_ABRON_HEALTH_CLINIC | M12: F-2026-06-01-232644 | N12: Abron Fac2 | O12: Health Facility | P12: Permanent | Q12: 300 | R12: Inactive
A13: Nigeria | B13: =IFERROR(INDEX(_h_SimpleLookup_h_!$J$59:$J$68,MATCH(CONCATENATE(INDIRECT("A"&ROW())),_h_SimpleLookup_h_!$I$59:$I$68,0)),"") -> H_fb6f8507bb42032f92d3fb39098d6015c7a2d1ef5850f24f0469a022b6bae7a6 | C13: Kaduna | D13: =IFERROR(INDEX(_h_SimpleLookup_h_!$J$59:$J$68,MATCH(CONCATENATE(INDIRECT("A"&ROW()), "#", INDIRECT("C"&ROW())),_h_SimpleLookup_h_!$I$59:$I$68,0)),"") -> H_2a2bf2599f027fcb0e1c647c7dcdba05fce783ba11b76c9b9900f47311a19ee4 | E13: Kachia | F13: =IFERROR(INDEX(_h_SimpleLookup_h_!$J$59:$J$68,MATCH(CONCATENATE(INDIRECT("A"&ROW()), "#", INDIRECT("C"&ROW()), "#", INDIRECT("E"&ROW())),_h_SimpleLookup_h_!$I$59:$I$68,0)),"") -> H_1487d1b2ba978586027ff36cb4b3f23a3349d18580e5f327ec230ce579ef0d8d | G13: Ankwa | H13: =IFERROR(INDEX(_h_SimpleLookup_h_!$J$59:$J$68,MATCH(CONCATENATE(INDIRECT("A"&ROW()), "#", INDIRECT("C"&ROW()), "#", INDIRECT("E"&ROW()), "#", INDIRECT("G"&ROW())),_h_SimpleLookup_h_!$I$59:$I$68,0)),"") -> H_019da8285b8f5a30ce41b7543a6551bfe93afdafd639f208c3f4f9474aca8e56 | I13: Abron Health Clinic | J13: =IFERROR(INDEX(_h_SimpleLookup_h_!$J$59:$J$68,MATCH(CONCATENATE(INDIRECT("A"&ROW()), "#", INDIRECT("C"&ROW()), "#", INDIRECT("E"&ROW()), "#", INDIRECT("G"&ROW()), "#", INDIRECT("I"&ROW())),_h_SimpleLookup_h_!$I$59:$I$68,0)),"") -> H_2f7448dc17e8b06c0a8a64cb3106ad85ff7c115b00d58195db1014fc59e5da80 | L13: =IF(K13<>"",IFERROR(VLOOKUP(CONCATENATE(A13,"#",C13,"#",E13,"#",G13,"#",I13,"#",K13),_h_SimpleLookup_h_!$D$13:$E$56,2,0),""),IF(I13<>"",IFERROR(VLOOKUP(CONCATENATE(A13,"#",C13,"#",E13,"#",G13,"#",I13),_h_SimpleLookup_h_!$D$13:$E$56,2,0),""),IF(G13<>"",IFERROR(VLOOKUP(CONCATENATE(A13,"#",C13,"#",E13,"#",G13),_h_SimpleLookup_h_!$D$13:$E$56,2,0),""),IF(E13<>"",IFERROR(VLOOKUP(CONCATENATE(A13,"#",C13,"#",E13),_h_SimpleLookup_h_!$D$13:$E$56,2,0),""),IF(C13<>"",IFERROR(VLOOKUP(CONCATENATE(A13,"#",C13),_h_SimpleLookup_h_!$D$13:$E$56,2,0),""),IF(A13<>"",IFERROR(VLOOKUP(CONCATENATE(A13),_h_SimpleLookup_h_!$D$13:$E$56,2,0),""),"")))))) -> NIGERIA_NI_01_20_12_04_ABRON_HEALTH_CLINIC | M13: F-2026-06-01-232641 | N13: Abron Fac1 | O13: Health Facility | P13: Permanent | Q13: 300 | R13: Inactive
A14: Nigeria | B14: =IFERROR(INDEX(_h_SimpleLookup_h_!$J$59:$J$68,MATCH(CONCATENATE(INDIRECT("A"&ROW())),_h_SimpleLookup_h_!$I$59:$I$68,0)),"") -> H_fb6f8507bb42032f92d3fb39098d6015c7a2d1ef5850f24f0469a022b6bae7a6 | C14: Kaduna | D14: =IFERROR(INDEX(_h_SimpleLookup_h_!$J$59:$J$68,MATCH(CONCATENATE(INDIRECT("A"&ROW()), "#", INDIRECT("C"&ROW())),_h_SimpleLookup_h_!$I$59:$I$68,0)),"") -> H_2a2bf2599f027fcb0e1c647c7dcdba05fce783ba11b76c9b9900f47311a19ee4 | F14: =IFERROR(INDEX(_h_SimpleLookup_h_!$J$59:$J$68,MATCH(CONCATENATE(INDIRECT("A"&ROW()), "#", INDIRECT("C"&ROW()), "#", INDIRECT("E"&ROW())),_h_SimpleLookup_h_!$I$59:$I$68,0)),"") | H14: =IFERROR(INDEX(_h_SimpleLookup_h_!$J$59:$J$68,MATCH(CONCATENATE(INDIRECT("A"&ROW()), "#", INDIRECT("C"&ROW()), "#", INDIRECT("E"&ROW()), "#", INDIRECT("G"&ROW())),_h_SimpleLookup_h_!$I$59:$I$68,0)),"") | J14: =IFERROR(INDEX(_h_SimpleLookup_h_!$J$59:$J$68,MATCH(CONCATENATE(INDIRECT("A"&ROW()), "#", INDIRECT("C"&ROW()), "#", INDIRECT("E"&ROW()), "#", INDIRECT("G"&ROW()), "#", INDIRECT("I"&ROW())),_h_SimpleLookup_h_!$I$59:$I$68,0)),"") | L14: =IF(K14<>"",IFERROR(VLOOKUP(CONCATENATE(A14,"#",C14,"#",E14,"#",G14,"#",I14,"#",K14),_h_SimpleLookup_h_!$D$13:$E$56,2,0),""),IF(I14<>"",IFERROR(VLOOKUP(CONCATENATE(A14,"#",C14,"#",E14,"#",G14,"#",I14),_h_SimpleLookup_h_!$D$13:$E$56,2,0),""),IF(G14<>"",IFERROR(VLOOKUP(CONCATENATE(A14,"#",C14,"#",E14,"#",G14),_h_SimpleLookup_h_!$D$13:$E$56,2,0),""),IF(E14<>"",IFERROR(VLOOKUP(CONCATENATE(A14,"#",C14,"#",E14),_h_SimpleLookup_h_!$D$13:$E$56,2,0),""),IF(C14<>"",IFERROR(VLOOKUP(CONCATENATE(A14,"#",C14),_h_SimpleLookup_h_!$D$13:$E$56,2,0),""),IF(A14<>"",IFERROR(VLOOKUP(CONCATENATE(A14),_h_SimpleLookup_h_!$D$13:$E$56,2,0),""),"")))))) -> NIGERIA_NI_01_KADUNA | M14: F-2026-06-01-232643 | N14: Kaduna Fac1 | O14: Health Facility | P14: Permanent | Q14: 800 | R14: Inactive
B15: =IFERROR(INDEX(_h_SimpleLookup_h_!$J$59:$J$68,MATCH(CONCATENATE(INDIRECT("A"&ROW())),_h_SimpleLookup_h_!$I$59:$I$68,0)),"") | D15: =IFERROR(INDEX(_h_SimpleLookup_h_!$J$59:$J$68,MATCH(CONCATENATE(INDIRECT("A"&ROW()), "#", INDIRECT("C"&ROW())),_h_SimpleLookup_h_!$I$59:$I$68,0)),"") | F15: =IFERROR(INDEX(_h_SimpleLookup_h_!$J$59:$J$68,MATCH(CONCATENATE(INDIRECT("A"&ROW()), "#", INDIRECT("C"&ROW()), "#", INDIRECT("E"&ROW())),_h_SimpleLookup_h_!$I$59:$I$68,0)),"") | H15: =IFERROR(INDEX(_h_SimpleLookup_h_!$J$59:$J$68,MATCH(CONCATENATE(INDIRECT("A"&ROW()), "#", INDIRECT("C"&ROW()), "#", INDIRECT("E"&ROW()), "#", INDIRECT("G"&ROW())),_h_SimpleLookup_h_!$I$59:$I$68,0)),"") | J15: =IFERROR(INDEX(_h_SimpleLookup_h_!$J$59:$J$68,MATCH(CONCATENATE(INDIRECT("A"&ROW()), "#", INDIRECT("C"&ROW()), "#", INDIRECT("E"&ROW()), "#", INDIRECT("G"&ROW()), "#", INDIRECT("I"&ROW())),_h_SimpleLookup_h_!$I$59:$I$68,0)),"") | L15: =IF(K15<>"",IFERROR(VLOOKUP(CONCATENATE(A15,"#",C15,"#",E15,"#",G15,"#",I15,"#",K15),_h_SimpleLookup_h_!$D$13:$E$56,2,0),""),IF(I15<>"",IFERROR(VLOOKUP(CONCATENATE(A15,"#",C15,"#",E15,"#",G15,"#",I15),_h_SimpleLookup_h_!$D$13:$E$56,2,0),""),IF(G15<>"",IFERROR(VLOOKUP(CONCATENATE(A15,"#",C15,"#",E15,"#",G15),_h_SimpleLookup_h_!$D$13:$E$56,2,0),""),IF(E15<>"",IFERROR(VLOOKUP(CONCATENATE(A15,"#",C15,"#",E15),_h_SimpleLookup_h_!$D$13:$E$56,2,0),""),IF(C15<>"",IFERROR(VLOOKUP(CONCATENATE(A15,"#",C15),_h_SimpleLookup_h_!$D$13:$E$56,2,0),""),IF(A15<>"",IFERROR(VLOOKUP(CONCATENATE(A15),_h_SimpleLookup_h_!$D$13:$E$56,2,0),""),""))))))
B16: =IFERROR(INDEX(_h_SimpleLookup_h_!$J$59:$J$68,MATCH(CONCATENATE(INDIRECT("A"&ROW())),_h_SimpleLookup_h_!$I$59:$I$68,0)),"") | D16: =IFERROR(INDEX(_h_SimpleLookup_h_!$J$59:$J$68,MATCH(CONCATENATE(INDIRECT("A"&ROW()), "#", INDIRECT("C"&ROW())),_h_SimpleLookup_h_!$I$59:$I$68,0)),"") | F16: =IFERROR(INDEX(_h_SimpleLookup_h_!$J$59:$J$68,MATCH(CONCATENATE(INDIRECT("A"&ROW()), "#", INDIRECT("C"&ROW()), "#", INDIRECT("E"&ROW())),_h_SimpleLookup_h_!$I$59:$I$68,0)),"") | H16: =IFERROR(INDEX(_h_SimpleLookup_h_!$J$59:$J$68,MATCH(CONCATENATE(INDIRECT("A"&ROW()), "#", INDIRECT("C"&ROW()), "#", INDIRECT("E"&ROW()), "#", INDIRECT("G"&ROW())),_h_SimpleLookup_h_!$I$59:$I$68,0)),"") | J16: =IFERROR(INDEX(_h_SimpleLookup_h_!$J$59:$J$68,MATCH(CONCATENATE(INDIRECT("A"&ROW()), "#", INDIRECT("C"&ROW()), "#", INDIRECT("E"&ROW()), "#", INDIRECT("G"&ROW()), "#", INDIRECT("I"&ROW())),_h_SimpleLookup_h_!$I$59:$I$68,0)),"") | L16: =IF(K16<>"",IFERROR(VLOOKUP(CONCATENATE(A16,"#",C16,"#",E16,"#",G16,"#",I16,"#",K16),_h_SimpleLookup_h_!$D$13:$E$56,2,0),""),IF(I16<>"",IFERROR(VLOOKUP(CONCATENATE(A16,"#",C16,"#",E16,"#",G16,"#",I16),_h_SimpleLookup_h_!$D$13:$E$56,2,0),""),IF(G16<>"",IFERROR(VLOOKUP(CONCATENATE(A16,"#",C16,"#",E16,"#",G16),_h_SimpleLookup_h_!$D$13:$E$56,2,0),""),IF(E16<>"",IFERROR(VLOOKUP(CONCATENATE(A16,"#",C16,"#",E16),_h_SimpleLookup_h_!$D$13:$E$56,2,0),""),IF(C16<>"",IFERROR(VLOOKUP(CONCATENATE(A16,"#",C16),_h_SimpleLookup_h_!$D$13:$E$56,2,0),""),IF(A16<>"",IFERROR(VLOOKUP(CONCATENATE(A16),_h_SimpleLookup_h_!$D$13:$E$56,2,0),""),""))))))
B17: =IFERROR(INDEX(_h_SimpleLookup_h_!$J$59:$J$68,MATCH(CONCATENATE(INDIRECT("A"&ROW())),_h_SimpleLookup_h_!$I$59:$I$68,0)),"") | D17: =IFERROR(INDEX(_h_SimpleLookup_h_!$J$59:$J$68,MATCH(CONCATENATE(INDIRECT("A"&ROW()), "#", INDIRECT("C"&ROW())),_h_SimpleLookup_h_!$I$59:$I$68,0)),"") | F17: =IFERROR(INDEX(_h_SimpleLookup_h_!$J$59:$J$68,MATCH(CONCATENATE(INDIRECT("A"&ROW()), "#", INDIRECT("C"&ROW()), "#", INDIRECT("E"&ROW())),_h_SimpleLookup_h_!$I$59:$I$68,0)),"") | H17: =IFERROR(INDEX(_h_SimpleLookup_h_!$J$59:$J$68,MATCH(CONCATENATE(INDIRECT("A"&ROW()), "#", INDIRECT("C"&ROW()), "#", INDIRECT("E"&ROW()), "#", INDIRECT("G"&ROW())),_h_SimpleLookup_h_!$I$59:$I$68,0)),"") | J17: =IFERROR(INDEX(_h_SimpleLookup_h_!$J$59:$J$68,MATCH(CONCATENATE(INDIRECT("A"&ROW()), "#", INDIRECT("C"&ROW()), "#", INDIRECT("E"&ROW()), "#", INDIRECT("G"&ROW()), "#", INDIRECT("I"&ROW())),_h_SimpleLookup_h_!$I$59:$I$68,0)),"") | L17: =IF(K17<>"",IFERROR(VLOOKUP(CONCATENATE(A17,"#",C17,"#",E17,"#",G17,"#",I17,"#",K17),_h_SimpleLookup_h_!$D$13:$E$56,2,0),""),IF(I17<>"",IFERROR(VLOOKUP(CONCATENATE(A17,"#",C17,"#",E17,"#",G17,"#",I17),_h_SimpleLookup_h_!$D$13:$E$56,2,0),""),IF(G17<>"",IFERROR(VLOOKUP(CONCATENATE(A17,"#",C17,"#",E17,"#",G17),_h_SimpleLookup_h_!$D$13:$E$56,2,0),""),IF(E17<>"",IFERROR(VLOOKUP(CONCATENATE(A17,"#",C17,"#",E17),_h_SimpleLookup_h_!$D$13:$E$56,2,0),""),IF(C17<>"",IFERROR(VLOOKUP(CONCATENATE(A17,"#",C17),_h_SimpleLookup_h_!$D$13:$E$56,2,0),""),IF(A17<>"",IFERROR(VLOOKUP(CONCATENATE(A17),_h_SimpleLookup_h_!$D$13:$E$56,2,0),""),""))))))
B18: =IFERROR(INDEX(_h_SimpleLookup_h_!$J$59:$J$68,MATCH(CONCATENATE(INDIRECT("A"&ROW())),_h_SimpleLookup_h_!$I$59:$I$68,0)),"") | D18: =IFERROR(INDEX(_h_SimpleLookup_h_!$J$59:$J$68,MATCH(CONCATENATE(INDIRECT("A"&ROW()), "#", INDIRECT("C"&ROW())),_h_SimpleLookup_h_!$I$59:$I$68,0)),"") | F18: =IFERROR(INDEX(_h_SimpleLookup_h_!$J$59:$J$68,MATCH(CONCATENATE(INDIRECT("A"&ROW()), "#", INDIRECT("C"&ROW()), "#", INDIRECT("E"&ROW())),_h_SimpleLookup_h_!$I$59:$I$68,0)),"") | H18: =IFERROR(INDEX(_h_SimpleLookup_h_!$J$59:$J$68,MATCH(CONCATENATE(INDIRECT("A"&ROW()), "#", INDIRECT("C"&ROW()), "#", INDIRECT("E"&ROW()), "#", INDIRECT("G"&ROW())),_h_SimpleLookup_h_!$I$59:$I$68,0)),"") | J18: =IFERROR(INDEX(_h_SimpleLookup_h_!$J$59:$J$68,MATCH(CONCATENATE(INDIRECT("A"&ROW()), "#", INDIRECT("C"&ROW()), "#", INDIRECT("E"&ROW()), "#", INDIRECT("G"&ROW()), "#", INDIRECT("I"&ROW())),_h_SimpleLookup_h_!$I$59:$I$68,0)),"") | L18: =IF(K18<>"",IFERROR(VLOOKUP(CONCATENATE(A18,"#",C18,"#",E18,"#",G18,"#",I18,"#",K18),_h_SimpleLookup_h_!$D$13:$E$56,2,0),""),IF(I18<>"",IFERROR(VLOOKUP(CONCATENATE(A18,"#",C18,"#",E18,"#",G18,"#",I18),_h_SimpleLookup_h_!$D$13:$E$56,2,0),""),IF(G18<>"",IFERROR(VLOOKUP(CONCATENATE(A18,"#",C18,"#",E18,"#",G18),_h_SimpleLookup_h_!$D$13:$E$56,2,0),""),IF(E18<>"",IFERROR(VLOOKUP(CONCATENATE(A18,"#",C18,"#",E18),_h_SimpleLookup_h_!$D$13:$E$56,2,0),""),IF(C18<>"",IFERROR(VLOOKUP(CONCATENATE(A18,"#",C18),_h_SimpleLookup_h_!$D$13:$E$56,2,0),""),IF(A18<>"",IFERROR(VLOOKUP(CONCATENATE(A18),_h_SimpleLookup_h_!$D$13:$E$56,2,0),""),""))))))
B19: =IFERROR(INDEX(_h_SimpleLookup_h_!$J$59:$J$68,MATCH(CONCATENATE(INDIRECT("A"&ROW())),_h_SimpleLookup_h_!$I$59:$I$68,0)),"") | D19: =IFERROR(INDEX(_h_SimpleLookup_h_!$J$59:$J$68,MATCH(CONCATENATE(INDIRECT("A"&ROW()), "#", INDIRECT("C"&ROW())),_h_SimpleLookup_h_!$I$59:$I$68,0)),"") | F19: =IFERROR(INDEX(_h_SimpleLookup_h_!$J$59:$J$68,MATCH(CONCATENATE(INDIRECT("A"&ROW()), "#", INDIRECT("C"&ROW()), "#", INDIRECT("E"&ROW())),_h_SimpleLookup_h_!$I$59:$I$68,0)),"") | H19: =IFERROR(INDEX(_h_SimpleLookup_h_!$J$59:$J$68,MATCH(CONCATENATE(INDIRECT("A"&ROW()), "#", INDIRECT("C"&ROW()), "#", INDIRECT("E"&ROW()), "#", INDIRECT("G"&ROW())),_h_SimpleLookup_h_!$I$59:$I$68,0)),"") | J19: =IFERROR(INDEX(_h_SimpleLookup_h_!$J$59:$J$68,MATCH(CONCATENATE(INDIRECT("A"&ROW()), "#", INDIRECT("C"&ROW()), "#", INDIRECT("E"&ROW()), "#", INDIRECT("G"&ROW()), "#", INDIRECT("I"&ROW())),_h_SimpleLookup_h_!$I$59:$I$68,0)),"") | L19: =IF(K19<>"",IFERROR(VLOOKUP(CONCATENATE(A19,"#",C19,"#",E19,"#",G19,"#",I19,"#",K19),_h_SimpleLookup_h_!$D$13:$E$56,2,0),""),IF(I19<>"",IFERROR(VLOOKUP(CONCATENATE(A19,"#",C19,"#",E19,"#",G19,"#",I19),_h_SimpleLookup_h_!$D$13:$E$56,2,0),""),IF(G19<>"",IFERROR(VLOOKUP(CONCATENATE(A19,"#",C19,"#",E19,"#",G19),_h_SimpleLookup_h_!$D$13:$E$56,2,0),""),IF(E19<>"",IFERROR(VLOOKUP(CONCATENATE(A19,"#",C19,"#",E19),_h_SimpleLookup_h_!$D$13:$E$56,2,0),""),IF(C19<>"",IFERROR(VLOOKUP(CONCATENATE(A19,"#",C19),_h_SimpleLookup_h_!$D$13:$E$56,2,0),""),IF(A19<>"",IFERROR(VLOOKUP(CONCATENATE(A19),_h_SimpleLookup_h_!$D$13:$E$56,2,0),""),""))))))
B20: =IFERROR(INDEX(_h_SimpleLookup_h_!$J$59:$J$68,MATCH(CONCATENATE(INDIRECT("A"&ROW())),_h_SimpleLookup_h_!$I$59:$I$68,0)),"") | D20: =IFERROR(INDEX(_h_SimpleLookup_h_!$J$59:$J$68,MATCH(CONCATENATE(INDIRECT("A"&ROW()), "#", INDIRECT("C"&ROW())),_h_SimpleLookup_h_!$I$59:$I$68,0)),"") | F20: =IFERROR(INDEX(_h_SimpleLookup_h_!$J$59:$J$68,MATCH(CONCATENATE(INDIRECT("A"&ROW()), "#", INDIRECT("C"&ROW()), "#", INDIRECT("E"&ROW())),_h_SimpleLookup_h_!$I$59:$I$68,0)),"") | H20: =IFERROR(INDEX(_h_SimpleLookup_h_!$J$59:$J$68,MATCH(CONCATENATE(INDIRECT("A"&ROW()), "#", INDIRECT("C"&ROW()), "#", INDIRECT("E"&ROW()), "#", INDIRECT("G"&ROW())),_h_SimpleLookup_h_!$I$59:$I$68,0)),"") | J20: =IFERROR(INDEX(_h_SimpleLookup_h_!$J$59:$J$68,MATCH(CONCATENATE(INDIRECT("A"&ROW()), "#", INDIRECT("C"&ROW()), "#", INDIRECT("E"&ROW()), "#", INDIRECT("G"&ROW()), "#", INDIRECT("I"&ROW())),_h_SimpleLookup_h_!$I$59:$I$68,0)),"") | L20: =IF(K20<>"",IFERROR(VLOOKUP(CONCATENATE(A20,"#",C20,"#",E20,"#",G20,"#",I20,"#",K20),_h_SimpleLookup_h_!$D$13:$E$56,2,0),""),IF(I20<>"",IFERROR(VLOOKUP(CONCATENATE(A20,"#",C20,"#",E20,"#",G20,"#",I20),_h_SimpleLookup_h_!$D$13:$E$56,2,0),""),IF(G20<>"",IFERROR(VLOOKUP(CONCATENATE(A20,"#",C20,"#",E20,"#",G20),_h_SimpleLookup_h_!$D$13:$E$56,2,0),""),IF(E20<>"",IFERROR(VLOOKUP(CONCATENATE(A20,"#",C20,"#",E20),_h_SimpleLookup_h_!$D$13:$E$56,2,0),""),IF(C20<>"",IFERROR(VLOOKUP(CONCATENATE(A20,"#",C20),_h_SimpleLookup_h_!$D$13:$E$56,2,0),""),IF(A20<>"",IFERROR(VLOOKUP(CONCATENATE(A20),_h_SimpleLookup_h_!$D$13:$E$56,2,0),""),""))))))
B21: =IFERROR(INDEX(_h_SimpleLookup_h_!$J$59:$J$68,MATCH(CONCATENATE(INDIRECT("A"&ROW())),_h_SimpleLookup_h_!$I$59:$I$68,0)),"") | D21: =IFERROR(INDEX(_h_SimpleLookup_h_!$J$59:$J$68,MATCH(CONCATENATE(INDIRECT("A"&ROW()), "#", INDIRECT("C"&ROW())),_h_SimpleLookup_h_!$I$59:$I$68,0)),"") | F21: =IFERROR(INDEX(_h_SimpleLookup_h_!$J$59:$J$68,MATCH(CONCATENATE(INDIRECT("A"&ROW()), "#", INDIRECT("C"&ROW()), "#", INDIRECT("E"&ROW())),_h_SimpleLookup_h_!$I$59:$I$68,0)),"") | H21: =IFERROR(INDEX(_h_SimpleLookup_h_!$J$59:$J$68,MATCH(CONCATENATE(INDIRECT("A"&ROW()), "#", INDIRECT("C"&ROW()), "#", INDIRECT("E"&ROW()), "#", INDIRECT("G"&ROW())),_h_SimpleLookup_h_!$I$59:$I$68,0)),"") | J21: =IFERROR(INDEX(_h_SimpleLookup_h_!$J$59:$J$68,MATCH(CONCATENATE(INDIRECT("A"&ROW()), "#", INDIRECT("C"&ROW()), "#", INDIRECT("E"&ROW()), "#", INDIRECT("G"&ROW()), "#", INDIRECT("I"&ROW())),_h_SimpleLookup_h_!$I$59:$I$68,0)),"") | L21: =IF(K21<>"",IFERROR(VLOOKUP(CONCATENATE(A21,"#",C21,"#",E21,"#",G21,"#",I21,"#",K21),_h_SimpleLookup_h_!$D$13:$E$56,2,0),""),IF(I21<>"",IFERROR(VLOOKUP(CONCATENATE(A21,"#",C21,"#",E21,"#",G21,"#",I21),_h_SimpleLookup_h_!$D$13:$E$56,2,0),""),IF(G21<>"",IFERROR(VLOOKUP(CONCATENATE(A21,"#",C21,"#",E21,"#",G21),_h_SimpleLookup_h_!$D$13:$E$56,2,0),""),IF(E21<>"",IFERROR(VLOOKUP(CONCATENATE(A21,"#",C21,"#",E21),_h_SimpleLookup_h_!$D$13:$E$56,2,0),""),IF(C21<>"",IFERROR(VLOOKUP(CONCATENATE(A21,"#",C21),_h_SimpleLookup_h_!$D$13:$E$56,2,0),""),IF(A21<>"",IFERROR(VLOOKUP(CONCATENATE(A21),_h_SimpleLookup_h_!$D$13:$E$56,2,0),""),""))))))
B22: =IFERROR(INDEX(_h_SimpleLookup_h_!$J$59:$J$68,MATCH(CONCATENATE(INDIRECT("A"&ROW())),_h_SimpleLookup_h_!$I$59:$I$68,0)),"") | D22: =IFERROR(INDEX(_h_SimpleLookup_h_!$J$59:$J$68,MATCH(CONCATENATE(INDIRECT("A"&ROW()), "#", INDIRECT("C"&ROW())),_h_SimpleLookup_h_!$I$59:$I$68,0)),"") | F22: =IFERROR(INDEX(_h_SimpleLookup_h_!$J$59:$J$68,MATCH(CONCATENATE(INDIRECT("A"&ROW()), "#", INDIRECT("C"&ROW()), "#", INDIRECT("E"&ROW())),_h_SimpleLookup_h_!$I$59:$I$68,0)),"") | H22: =IFERROR(INDEX(_h_SimpleLookup_h_!$J$59:$J$68,MATCH(CONCATENATE(INDIRECT("A"&ROW()), "#", INDIRECT("C"&ROW()), "#", INDIRECT("E"&ROW()), "#", INDIRECT("G"&ROW())),_h_SimpleLookup_h_!$I$59:$I$68,0)),"") | J22: =IFERROR(INDEX(_h_SimpleLookup_h_!$J$59:$J$68,MATCH(CONCATENATE(INDIRECT("A"&ROW()), "#", INDIRECT("C"&ROW()), "#", INDIRECT("E"&ROW()), "#", INDIRECT("G"&ROW()), "#", INDIRECT("I"&ROW())),_h_SimpleLookup_h_!$I$59:$I$68,0)),"") | L22: =IF(K22<>"",IFERROR(VLOOKUP(CONCATENATE(A22,"#",C22,"#",E22,"#",G22,"#",I22,"#",K22),_h_SimpleLookup_h_!$D$13:$E$56,2,0),""),IF(I22<>"",IFERROR(VLOOKUP(CONCATENATE(A22,"#",C22,"#",E22,"#",G22,"#",I22),_h_SimpleLookup_h_!$D$13:$E$56,2,0),""),IF(G22<>"",IFERROR(VLOOKUP(CONCATENATE(A22,"#",C22,"#",E22,"#",G22),_h_SimpleLookup_h_!$D$13:$E$56,2,0),""),IF(E22<>"",IFERROR(VLOOKUP(CONCATENATE(A22,"#",C22,"#",E22),_h_SimpleLookup_h_!$D$13:$E$56,2,0),""),IF(C22<>"",IFERROR(VLOOKUP(CONCATENATE(A22,"#",C22),_h_SimpleLookup_h_!$D$13:$E$56,2,0),""),IF(A22<>"",IFERROR(VLOOKUP(CONCATENATE(A22),_h_SimpleLookup_h_!$D$13:$E$56,2,0),""),""))))))
B23: =IFERROR(INDEX(_h_SimpleLookup_h_!$J$59:$J$68,MATCH(CONCATENATE(INDIRECT("A"&ROW())),_h_SimpleLookup_h_!$I$59:$I$68,0)),"") | D23: =IFERROR(INDEX(_h_SimpleLookup_h_!$J$59:$J$68,MATCH(CONCATENATE(INDIRECT("A"&ROW()), "#", INDIRECT("C"&ROW())),_h_SimpleLookup_h_!$I$59:$I$68,0)),"") | F23: =IFERROR(INDEX(_h_SimpleLookup_h_!$J$59:$J$68,MATCH(CONCATENATE(INDIRECT("A"&ROW()), "#", INDIRECT("C"&ROW()), "#", INDIRECT("E"&ROW())),_h_SimpleLookup_h_!$I$59:$I$68,0)),"") | H23: =IFERROR(INDEX(_h_SimpleLookup_h_!$J$59:$J$68,MATCH(CONCATENATE(INDIRECT("A"&ROW()), "#", INDIRECT("C"&ROW()), "#", INDIRECT("E"&ROW()), "#", INDIRECT("G"&ROW())),_h_SimpleLookup_h_!$I$59:$I$68,0)),"") | J23: =IFERROR(INDEX(_h_SimpleLookup_h_!$J$59:$J$68,MATCH(CONCATENATE(INDIRECT("A"&ROW()), "#", INDIRECT("C"&ROW()), "#", INDIRECT("E"&ROW()), "#", INDIRECT("G"&ROW()), "#", INDIRECT("I"&ROW())),_h_SimpleLookup_h_!$I$59:$I$68,0)),"") | L23: =IF(K23<>"",IFERROR(VLOOKUP(CONCATENATE(A23,"#",C23,"#",E23,"#",G23,"#",I23,"#",K23),_h_SimpleLookup_h_!$D$13:$E$56,2,0),""),IF(I23<>"",IFERROR(VLOOKUP(CONCATENATE(A23,"#",C23,"#",E23,"#",G23,"#",I23),_h_SimpleLookup_h_!$D$13:$E$56,2,0),""),IF(G23<>"",IFERROR(VLOOKUP(CONCATENATE(A23,"#",C23,"#",E23,"#",G23),_h_SimpleLookup_h_!$D$13:$E$56,2,0),""),IF(E23<>"",IFERROR(VLOOKUP(CONCATENATE(A23,"#",C23,"#",E23),_h_SimpleLookup_h_!$D$13:$E$56,2,0),""),IF(C23<>"",IFERROR(VLOOKUP(CONCATENATE(A23,"#",C23),_h_SimpleLookup_h_!$D$13:$E$56,2,0),""),IF(A23<>"",IFERROR(VLOOKUP(CONCATENATE(A23),_h_SimpleLookup_h_!$D$13:$E$56,2,0),""),""))))))
B24: =IFERROR(INDEX(_h_SimpleLookup_h_!$J$59:$J$68,MATCH(CONCATENATE(INDIRECT("A"&ROW())),_h_SimpleLookup_h_!$I$59:$I$68,0)),"") | D24: =IFERROR(INDEX(_h_SimpleLookup_h_!$J$59:$J$68,MATCH(CONCATENATE(INDIRECT("A"&ROW()), "#", INDIRECT("C"&ROW())),_h_SimpleLookup_h_!$I$59:$I$68,0)),"") | F24: =IFERROR(INDEX(_h_SimpleLookup_h_!$J$59:$J$68,MATCH(CONCATENATE(INDIRECT("A"&ROW()), "#", INDIRECT("C"&ROW()), "#", INDIRECT("E"&ROW())),_h_SimpleLookup_h_!$I$59:$I$68,0)),"") | H24: =IFERROR(INDEX(_h_SimpleLookup_h_!$J$59:$J$68,MATCH(CONCATENATE(INDIRECT("A"&ROW()), "#", INDIRECT("C"&ROW()), "#", INDIRECT("E"&ROW()), "#", INDIRECT("G"&ROW())),_h_SimpleLookup_h_!$I$59:$I$68,0)),"") | J24: =IFERROR(INDEX(_h_SimpleLookup_h_!$J$59:$J$68,MATCH(CONCATENATE(INDIRECT("A"&ROW()), "#", INDIRECT("C"&ROW()), "#", INDIRECT("E"&ROW()), "#", INDIRECT("G"&ROW()), "#", INDIRECT("I"&ROW())),_h_SimpleLookup_h_!$I$59:$I$68,0)),"") | L24: =IF(K24<>"",IFERROR(VLOOKUP(CONCATENATE(A24,"#",C24,"#",E24,"#",G24,"#",I24,"#",K24),_h_SimpleLookup_h_!$D$13:$E$56,2,0),""),IF(I24<>"",IFERROR(VLOOKUP(CONCATENATE(A24,"#",C24,"#",E24,"#",G24,"#",I24),_h_SimpleLookup_h_!$D$13:$E$56,2,0),""),IF(G24<>"",IFERROR(VLOOKUP(CONCATENATE(A24,"#",C24,"#",E24,"#",G24),_h_SimpleLookup_h_!$D$13:$E$56,2,0),""),IF(E24<>"",IFERROR(VLOOKUP(CONCATENATE(A24,"#",C24,"#",E24),_h_SimpleLookup_h_!$D$13:$E$56,2,0),""),IF(C24<>"",IFERROR(VLOOKUP(CONCATENATE(A24,"#",C24),_h_SimpleLookup_h_!$D$13:$E$56,2,0),""),IF(A24<>"",IFERROR(VLOOKUP(CONCATENATE(A24),_h_SimpleLookup_h_!$D$13:$E$56,2,0),""),""))))))
B25: =IFERROR(INDEX(_h_SimpleLookup_h_!$J$59:$J$68,MATCH(CONCATENATE(INDIRECT("A"&ROW())),_h_SimpleLookup_h_!$I$59:$I$68,0)),"") | D25: =IFERROR(INDEX(_h_SimpleLookup_h_!$J$59:$J$68,MATCH(CONCATENATE(INDIRECT("A"&ROW()), "#", INDIRECT("C"&ROW())),_h_SimpleLookup_h_!$I$59:$I$68,0)),"") | F25: =IFERROR(INDEX(_h_SimpleLookup_h_!$J$59:$J$68,MATCH(CONCATENATE(INDIRECT("A"&ROW()), "#", INDIRECT("C"&ROW()), "#", INDIRECT("E"&ROW())),_h_SimpleLookup_h_!$I$59:$I$68,0)),"") | H25: =IFERROR(INDEX(_h_SimpleLookup_h_!$J$59:$J$68,MATCH(CONCATENATE(INDIRECT("A"&ROW()), "#", INDIRECT("C"&ROW()), "#", INDIRECT("E"&ROW()), "#", INDIRECT("G"&ROW())),_h_SimpleLookup_h_!$I$59:$I$68,0)),"") | J25: =IFERROR(INDEX(_h_SimpleLookup_h_!$J$59:$J$68,MATCH(CONCATENATE(INDIRECT("A"&ROW()), "#", INDIRECT("C"&ROW()), "#", INDIRECT("E"&ROW()), "#", INDIRECT("G"&ROW()), "#", INDIRECT("I"&ROW())),_h_SimpleLookup_h_!$I$59:$I$68,0)),"") | L25: =IF(K25<>"",IFERROR(VLOOKUP(CONCATENATE(A25,"#",C25,"#",E25,"#",G25,"#",I25,"#",K25),_h_SimpleLookup_h_!$D$13:$E$56,2,0),""),IF(I25<>"",IFERROR(VLOOKUP(CONCATENATE(A25,"#",C25,"#",E25,"#",G25,"#",I25),_h_SimpleLookup_h_!$D$13:$E$56,2,0),""),IF(G25<>"",IFERROR(VLOOKUP(CONCATENATE(A25,"#",C25,"#",E25,"#",G25),_h_SimpleLookup_h_!$D$13:$E$56,2,0),""),IF(E25<>"",IFERROR(VLOOKUP(CONCATENATE(A25,"#",C25,"#",E25),_h_SimpleLookup_h_!$D$13:$E$56,2,0),""),IF(C25<>"",IFERROR(VLOOKUP(CONCATENATE(A25,"#",C25),_h_SimpleLookup_h_!$D$13:$E$56,2,0),""),IF(A25<>"",IFERROR(VLOOKUP(CONCATENATE(A25),_h_SimpleLookup_h_!$D$13:$E$56,2,0),""),""))))))
B26: =IFERROR(INDEX(_h_SimpleLookup_h_!$J$59:$J$68,MATCH(CONCATENATE(INDIRECT("A"&ROW())),_h_SimpleLookup_h_!$I$59:$I$68,0)),"") | D26: =IFERROR(INDEX(_h_SimpleLookup_h_!$J$59:$J$68,MATCH(CONCATENATE(INDIRECT("A"&ROW()), "#", INDIRECT("C"&ROW())),_h_SimpleLookup_h_!$I$59:$I$68,0)),"") | F26: =IFERROR(INDEX(_h_SimpleLookup_h_!$J$59:$J$68,MATCH(CONCATENATE(INDIRECT("A"&ROW()), "#", INDIRECT("C"&ROW()), "#", INDIRECT("E"&ROW())),_h_SimpleLookup_h_!$I$59:$I$68,0)),"") | H26: =IFERROR(INDEX(_h_SimpleLookup_h_!$J$59:$J$68,MATCH(CONCATENATE(INDIRECT("A"&ROW()), "#", INDIRECT("C"&ROW()), "#", INDIRECT("E"&ROW()), "#", INDIRECT("G"&ROW())),_h_SimpleLookup_h_!$I$59:$I$68,0)),"") | J26: =IFERROR(INDEX(_h_SimpleLookup_h_!$J$59:$J$68,MATCH(CONCATENATE(INDIRECT("A"&ROW()), "#", INDIRECT("C"&ROW()), "#", INDIRECT("E"&ROW()), "#", INDIRECT("G"&ROW()), "#", INDIRECT("I"&ROW())),_h_SimpleLookup_h_!$I$59:$I$68,0)),"") | L26: =IF(K26<>"",IFERROR(VLOOKUP(CONCATENATE(A26,"#",C26,"#",E26,"#",G26,"#",I26,"#",K26),_h_SimpleLookup_h_!$D$13:$E$56,2,0),""),IF(I26<>"",IFERROR(VLOOKUP(CONCATENATE(A26,"#",C26,"#",E26,"#",G26,"#",I26),_h_SimpleLookup_h_!$D$13:$E$56,2,0),""),IF(G26<>"",IFERROR(VLOOKUP(CONCATENATE(A26,"#",C26,"#",E26,"#",G26),_h_SimpleLookup_h_!$D$13:$E$56,2,0),""),IF(E26<>"",IFERROR(VLOOKUP(CONCATENATE(A26,"#",C26,"#",E26),_h_SimpleLookup_h_!$D$13:$E$56,2,0),""),IF(C26<>"",IFERROR(VLOOKUP(CONCATENATE(A26,"#",C26),_h_SimpleLookup_h_!$D$13:$E$56,2,0),""),IF(A26<>"",IFERROR(VLOOKUP(CONCATENATE(A26),_h_SimpleLookup_h_!$D$13:$E$56,2,0),""),""))))))
... B1014: =IFERROR(INDEX(_h_SimpleLookup_h_!$J$59:$J$68,MATCH(CONCATENATE(INDIRECT("A"&ROW())),_h_SimpleLookup_h_!$I$59:$I$68,0)),"") | D1014: =IFERROR(INDEX(_h_SimpleLookup_h_!$J$59:$J$68,MATCH(CONCATENATE(INDIRECT("A"&ROW()), "#", INDIRECT("C"&ROW())),_h_SimpleLookup_h_!$I$59:$I$68,0)),"") | F1014: =IFERROR(INDEX(_h_SimpleLookup_h_!$J$59:$J$68,MATCH(CONCATENATE(INDIRECT("A"&ROW()), "#", INDIRECT("C"&ROW()), "#", INDIRECT("E"&ROW())),_h_SimpleLookup_h_!$I$59:$I$68,0)),"") | H1014: =IFERROR(INDEX(_h_SimpleLookup_h_!$J$59:$J$68,MATCH(CONCATENATE(INDIRECT("A"&ROW()), "#", INDIRECT("C"&ROW()), "#", INDIRECT("E"&ROW()), "#", INDIRECT("G"&ROW())),_h_SimpleLookup_h_!$I$59:$I$68,0)),"") | J1014: =IFERROR(INDEX(_h_SimpleLookup_h_!$J$59:$J$68,MATCH(CONCATENATE(INDIRECT("A"&ROW()), "#", INDIRECT("C"&ROW()), "#", INDIRECT("E"&ROW()), "#", INDIRECT("G"&ROW()), "#", INDIRECT("I"&ROW())),_h_SimpleLookup_h_!$I$59:$I$68,0)),"") | L1014: =IF(K1014<>"",IFERROR(VLOOKUP(CONCATENATE(A1014,"#",C1014,"#",E1014,"#",G1014,"#",I1014,"#",K1014),_h_SimpleLookup_h_!$D$13:$E$56,2,0),""),IF(I1014<>"",IFERROR(VLOOKUP(CONCATENATE(A1014,"#",C1014,"#",E1014,"#",G1014,"#",I1014),_h_SimpleLookup_h_!$D$13:$E$56,2,0),""),IF(G1014<>"",IFERROR(VLOOKUP(CONCATENATE(A1014,"#",C1014,"#",E1014,"#",G1014),_h_SimpleLookup_h_!$D$13:$E$56,2,0),""),IF(E1014<>"",IFERROR(VLOOKUP(CONCATENATE(A1014,"#",C1014,"#",E1014),_h_SimpleLookup_h_!$D$13:$E$56,2,0),""),IF(C1014<>"",IFERROR(VLOOKUP(CONCATENATE(A1014,"#",C1014),_h_SimpleLookup_h_!$D$13:$E$56,2,0),""),IF(A1014<>"",IFERROR(VLOOKUP(CONCATENATE(A1014),_h_SimpleLookup_h_!$D$13:$E$56,2,0),""),""))))))

Sheet User List
A1: NIGERIA_COUNTRY | B1: NIGERIA_STATE_HELPER | C1: NIGERIA_STATE | D1: NIGERIA_LGA_HELPER | E1: NIGERIA_LGA | F1: NIGERIA_WARD_HELPER | G1: NIGERIA_WARD | H1: NIGERIA_HEALTHFACILITY_HELPER | I1: NIGERIA_HEALTHFACILITY | J1: NIGERIA_VILLAGE_HELPER | K1: NIGERIA_VILLAGE | L1: HCM_ADMIN_CONSOLE_BOUNDARY_CODE | M1: HCM_ADMIN_CONSOLE_USER_NAME | N1: HCM_ADMIN_CONSOLE_USER_PHONE_NUMBER | O1: HCM_ADMIN_CONSOLE_USER_ROLE_MULTISELECT_1 | P1: HCM_ADMIN_CONSOLE_USER_ROLE_MULTISELECT_2 | Q1: HCM_ADMIN_CONSOLE_USER_ROLE_MULTISELECT_3 | R1: HCM_ADMIN_CONSOLE_USER_ROLE_MULTISELECT_4 | S1: HCM_ADMIN_CONSOLE_USER_ROLE_MULTISELECT_5 | T1: HCM_ADMIN_CONSOLE_USER_EMPLOYMENT_TYPE | U1: HCM_ADMIN_CONSOLE_USER_USAGE | V1: UserName | W1: HCM_ADMIN_CONSOLE_USER_WORKER_ID | X1: HCM_ADMIN_CONSOLE_USER_PAYMENT_PROVIDER | Y1: HCM_ADMIN_CONSOLE_USER_PAYEE_PHONE_NUMBER | Z1: HCM_ADMIN_CONSOLE_USER_PAYEE_NAME | AA1: HCM_ADMIN_CONSOLE_USER_BANK_ACCOUNT | AB1: HCM_ADMIN_CONSOLE_USER_BANK_CODE | AC1: HCM_ADMIN_CONSOLE_USER_BENEFICIARY_CODE | AD1: Password | AE1: UserService Uuids
A2: Country | B2: NIGERIA_STATE_HELPER | C2: State | D2: NIGERIA_LGA_HELPER | E2: LGA | F2: NIGERIA_WARD_HELPER | G2: Ward | H2: NIGERIA_HEALTHFACILITY_HELPER | I2: Health Facility | J2: NIGERIA_VILLAGE_HELPER | K2: Village | L2: Service Boundary Code | M2: Name | N2: Phone Number (Mandatory) | O2: User Role 1 | P2: User Role 2 | Q2: User Role 3 | R2: User Role 4 | S2: User Role 5 | T2: Employment Type (Mandatory) | U2: Active / Inactive | V2: UserName | W2: User ID | X2: Payment Provider | Y2: Payee Phone Number | Z2: Payee Name | AA2: Bank Account | AB2: Bank Code | AC2: Beneficiary Code | AD2: Password | AE2: UserService Uuids
A3: Nigeria | B3: =IFERROR(INDEX(_h_SimpleLookup_h_!$J$59:$J$68,MATCH(CONCATENATE(INDIRECT("A"&ROW())),_h_SimpleLookup_h_!$I$59:$I$68,0)),"") -> H_fb6f8507bb42032f92d3fb39098d6015c7a2d1ef5850f24f0469a022b6bae7a6 | D3: =IFERROR(INDEX(_h_SimpleLookup_h_!$J$59:$J$68,MATCH(CONCATENATE(INDIRECT("A"&ROW()), "#", INDIRECT("C"&ROW())),_h_SimpleLookup_h_!$I$59:$I$68,0)),"") | F3: =IFERROR(INDEX(_h_SimpleLookup_h_!$J$59:$J$68,MATCH(CONCATENATE(INDIRECT("A"&ROW()), "#", INDIRECT("C"&ROW()), "#", INDIRECT("E"&ROW())),_h_SimpleLookup_h_!$I$59:$I$68,0)),"") | H3: =IFERROR(INDEX(_h_SimpleLookup_h_!$J$59:$J$68,MATCH(CONCATENATE(INDIRECT("A"&ROW()), "#", INDIRECT("C"&ROW()), "#", INDIRECT("E"&ROW()), "#", INDIRECT("G"&ROW())),_h_SimpleLookup_h_!$I$59:$I$68,0)),"") | J3: =IFERROR(INDEX(_h_SimpleLookup_h_!$J$59:$J$68,MATCH(CONCATENATE(INDIRECT("A"&ROW()), "#", INDIRECT("C"&ROW()), "#", INDIRECT("E"&ROW()), "#", INDIRECT("G"&ROW()), "#", INDIRECT("I"&ROW())),_h_SimpleLookup_h_!$I$59:$I$68,0)),"") | L3: =IF(K3<>"",IFERROR(VLOOKUP(CONCATENATE(A3,"#",C3,"#",E3,"#",G3,"#",I3,"#",K3),_h_SimpleLookup_h_!$D$13:$E$56,2,0),""),IF(I3<>"",IFERROR(VLOOKUP(CONCATENATE(A3,"#",C3,"#",E3,"#",G3,"#",I3),_h_SimpleLookup_h_!$D$13:$E$56,2,0),""),IF(G3<>"",IFERROR(VLOOKUP(CONCATENATE(A3,"#",C3,"#",E3,"#",G3),_h_SimpleLookup_h_!$D$13:$E$56,2,0),""),IF(E3<>"",IFERROR(VLOOKUP(CONCATENATE(A3,"#",C3,"#",E3),_h_SimpleLookup_h_!$D$13:$E$56,2,0),""),IF(C3<>"",IFERROR(VLOOKUP(CONCATENATE(A3,"#",C3),_h_SimpleLookup_h_!$D$13:$E$56,2,0),""),IF(A3<>"",IFERROR(VLOOKUP(CONCATENATE(A3),_h_SimpleLookup_h_!$D$13:$E$56,2,0),""),"")))))) -> NIGERIA_NI | M3: DIS | N3: 9765432345 | O3: DISTRIBUTOR | T3: Temporary | U3: Active
A4: Nigeria | B4: =IFERROR(INDEX(_h_SimpleLookup_h_!$J$59:$J$68,MATCH(CONCATENATE(INDIRECT("A"&ROW())),_h_SimpleLookup_h_!$I$59:$I$68,0)),"") -> H_fb6f8507bb42032f92d3fb39098d6015c7a2d1ef5850f24f0469a022b6bae7a6 | D4: =IFERROR(INDEX(_h_SimpleLookup_h_!$J$59:$J$68,MATCH(CONCATENATE(INDIRECT("A"&ROW()), "#", INDIRECT("C"&ROW())),_h_SimpleLookup_h_!$I$59:$I$68,0)),"") | F4: =IFERROR(INDEX(_h_SimpleLookup_h_!$J$59:$J$68,MATCH(CONCATENATE(INDIRECT("A"&ROW()), "#", INDIRECT("C"&ROW()), "#", INDIRECT("E"&ROW())),_h_SimpleLookup_h_!$I$59:$I$68,0)),"") | H4: =IFERROR(INDEX(_h_SimpleLookup_h_!$J$59:$J$68,MATCH(CONCATENATE(INDIRECT("A"&ROW()), "#", INDIRECT("C"&ROW()), "#", INDIRECT("E"&ROW()), "#", INDIRECT("G"&ROW())),_h_SimpleLookup_h_!$I$59:$I$68,0)),"") | J4: =IFERROR(INDEX(_h_SimpleLookup_h_!$J$59:$J$68,MATCH(CONCATENATE(INDIRECT("A"&ROW()), "#", INDIRECT("C"&ROW()), "#", INDIRECT("E"&ROW()), "#", INDIRECT("G"&ROW()), "#", INDIRECT("I"&ROW())),_h_SimpleLookup_h_!$I$59:$I$68,0)),"") | L4: =IF(K4<>"",IFERROR(VLOOKUP(CONCATENATE(A4,"#",C4,"#",E4,"#",G4,"#",I4,"#",K4),_h_SimpleLookup_h_!$D$13:$E$56,2,0),""),IF(I4<>"",IFERROR(VLOOKUP(CONCATENATE(A4,"#",C4,"#",E4,"#",G4,"#",I4),_h_SimpleLookup_h_!$D$13:$E$56,2,0),""),IF(G4<>"",IFERROR(VLOOKUP(CONCATENATE(A4,"#",C4,"#",E4,"#",G4),_h_SimpleLookup_h_!$D$13:$E$56,2,0),""),IF(E4<>"",IFERROR(VLOOKUP(CONCATENATE(A4,"#",C4,"#",E4),_h_SimpleLookup_h_!$D$13:$E$56,2,0),""),IF(C4<>"",IFERROR(VLOOKUP(CONCATENATE(A4,"#",C4),_h_SimpleLookup_h_!$D$13:$E$56,2,0),""),IF(A4<>"",IFERROR(VLOOKUP(CONCATENATE(A4),_h_SimpleLookup_h_!$D$13:$E$56,2,0),""),"")))))) -> NIGERIA_NI | M4: HFW | N4: 9765432346 | O4: HEALTH_FACILITY_WORKER | T4: Temporary | U4: Active
A5: Nigeria | B5: =IFERROR(INDEX(_h_SimpleLookup_h_!$J$59:$J$68,MATCH(CONCATENATE(INDIRECT("A"&ROW())),_h_SimpleLookup_h_!$I$59:$I$68,0)),"") -> H_fb6f8507bb42032f92d3fb39098d6015c7a2d1ef5850f24f0469a022b6bae7a6 | D5: =IFERROR(INDEX(_h_SimpleLookup_h_!$J$59:$J$68,MATCH(CONCATENATE(INDIRECT("A"&ROW()), "#", INDIRECT("C"&ROW())),_h_SimpleLookup_h_!$I$59:$I$68,0)),"") | F5: =IFERROR(INDEX(_h_SimpleLookup_h_!$J$59:$J$68,MATCH(CONCATENATE(INDIRECT("A"&ROW()), "#", INDIRECT("C"&ROW()), "#", INDIRECT("E"&ROW())),_h_SimpleLookup_h_!$I$59:$I$68,0)),"") | H5: =IFERROR(INDEX(_h_SimpleLookup_h_!$J$59:$J$68,MATCH(CONCATENATE(INDIRECT("A"&ROW()), "#", INDIRECT("C"&ROW()), "#", INDIRECT("E"&ROW()), "#", INDIRECT("G"&ROW())),_h_SimpleLookup_h_!$I$59:$I$68,0)),"") | J5: =IFERROR(INDEX(_h_SimpleLookup_h_!$J$59:$J$68,MATCH(CONCATENATE(INDIRECT("A"&ROW()), "#", INDIRECT("C"&ROW()), "#", INDIRECT("E"&ROW()), "#", INDIRECT("G"&ROW()), "#", INDIRECT("I"&ROW())),_h_SimpleLookup_h_!$I$59:$I$68,0)),"") | L5: =IF(K5<>"",IFERROR(VLOOKUP(CONCATENATE(A5,"#",C5,"#",E5,"#",G5,"#",I5,"#",K5),_h_SimpleLookup_h_!$D$13:$E$56,2,0),""),IF(I5<>"",IFERROR(VLOOKUP(CONCATENATE(A5,"#",C5,"#",E5,"#",G5,"#",I5),_h_SimpleLookup_h_!$D$13:$E$56,2,0),""),IF(G5<>"",IFERROR(VLOOKUP(CONCATENATE(A5,"#",C5,"#",E5,"#",G5),_h_SimpleLookup_h_!$D$13:$E$56,2,0),""),IF(E5<>"",IFERROR(VLOOKUP(CONCATENATE(A5,"#",C5,"#",E5),_h_SimpleLookup_h_!$D$13:$E$56,2,0),""),IF(C5<>"",IFERROR(VLOOKUP(CONCATENATE(A5,"#",C5),_h_SimpleLookup_h_!$D$13:$E$56,2,0),""),IF(A5<>"",IFERROR(VLOOKUP(CONCATENATE(A5),_h_SimpleLookup_h_!$D$13:$E$56,2,0),""),"")))))) -> NIGERIA_NI | M5: WM | N5: 9765432347 | O5: WAREHOUSE_MANAGER | T5: Temporary | U5: Active
A6: Nigeria | B6: =IFERROR(INDEX(_h_SimpleLookup_h_!$J$59:$J$68,MATCH(CONCATENATE(INDIRECT("A"&ROW())),_h_SimpleLookup_h_!$I$59:$I$68,0)),"") -> H_fb6f8507bb42032f92d3fb39098d6015c7a2d1ef5850f24f0469a022b6bae7a6 | D6: =IFERROR(INDEX(_h_SimpleLookup_h_!$J$59:$J$68,MATCH(CONCATENATE(INDIRECT("A"&ROW()), "#", INDIRECT("C"&ROW())),_h_SimpleLookup_h_!$I$59:$I$68,0)),"") | F6: =IFERROR(INDEX(_h_SimpleLookup_h_!$J$59:$J$68,MATCH(CONCATENATE(INDIRECT("A"&ROW()), "#", INDIRECT("C"&ROW()), "#", INDIRECT("E"&ROW())),_h_SimpleLookup_h_!$I$59:$I$68,0)),"") | H6: =IFERROR(INDEX(_h_SimpleLookup_h_!$J$59:$J$68,MATCH(CONCATENATE(INDIRECT("A"&ROW()), "#", INDIRECT("C"&ROW()), "#", INDIRECT("E"&ROW()), "#", INDIRECT("G"&ROW())),_h_SimpleLookup_h_!$I$59:$I$68,0)),"") | J6: =IFERROR(INDEX(_h_SimpleLookup_h_!$J$59:$J$68,MATCH(CONCATENATE(INDIRECT("A"&ROW()), "#", INDIRECT("C"&ROW()), "#", INDIRECT("E"&ROW()), "#", INDIRECT("G"&ROW()), "#", INDIRECT("I"&ROW())),_h_SimpleLookup_h_!$I$59:$I$68,0)),"") | L6: =IF(K6<>"",IFERROR(VLOOKUP(CONCATENATE(A6,"#",C6,"#",E6,"#",G6,"#",I6,"#",K6),_h_SimpleLookup_h_!$D$13:$E$56,2,0),""),IF(I6<>"",IFERROR(VLOOKUP(CONCATENATE(A6,"#",C6,"#",E6,"#",G6,"#",I6),_h_SimpleLookup_h_!$D$13:$E$56,2,0),""),IF(G6<>"",IFERROR(VLOOKUP(CONCATENATE(A6,"#",C6,"#",E6,"#",G6),_h_SimpleLookup_h_!$D$13:$E$56,2,0),""),IF(E6<>"",IFERROR(VLOOKUP(CONCATENATE(A6,"#",C6,"#",E6),_h_SimpleLookup_h_!$D$13:$E$56,2,0),""),IF(C6<>"",IFERROR(VLOOKUP(CONCATENATE(A6,"#",C6),_h_SimpleLookup_h_!$D$13:$E$56,2,0),""),IF(A6<>"",IFERROR(VLOOKUP(CONCATENATE(A6),_h_SimpleLookup_h_!$D$13:$E$56,2,0),""),"")))))) -> NIGERIA_NI | M6: NS | N6: 9765432348 | O6: NATIONAL_SUPERVISOR | T6: Temporary | U6: Active
A7: Nigeria | B7: =IFERROR(INDEX(_h_SimpleLookup_h_!$J$59:$J$68,MATCH(CONCATENATE(INDIRECT("A"&ROW())),_h_SimpleLookup_h_!$I$59:$I$68,0)),"") -> H_fb6f8507bb42032f92d3fb39098d6015c7a2d1ef5850f24f0469a022b6bae7a6 | D7: =IFERROR(INDEX(_h_SimpleLookup_h_!$J$59:$J$68,MATCH(CONCATENATE(INDIRECT("A"&ROW()), "#", INDIRECT("C"&ROW())),_h_SimpleLookup_h_!$I$59:$I$68,0)),"") | F7: =IFERROR(INDEX(_h_SimpleLookup_h_!$J$59:$J$68,MATCH(CONCATENATE(INDIRECT("A"&ROW()), "#", INDIRECT("C"&ROW()), "#", INDIRECT("E"&ROW())),_h_SimpleLookup_h_!$I$59:$I$68,0)),"") | H7: =IFERROR(INDEX(_h_SimpleLookup_h_!$J$59:$J$68,MATCH(CONCATENATE(INDIRECT("A"&ROW()), "#", INDIRECT("C"&ROW()), "#", INDIRECT("E"&ROW()), "#", INDIRECT("G"&ROW())),_h_SimpleLookup_h_!$I$59:$I$68,0)),"") | J7: =IFERROR(INDEX(_h_SimpleLookup_h_!$J$59:$J$68,MATCH(CONCATENATE(INDIRECT("A"&ROW()), "#", INDIRECT("C"&ROW()), "#", INDIRECT("E"&ROW()), "#", INDIRECT("G"&ROW()), "#", INDIRECT("I"&ROW())),_h_SimpleLookup_h_!$I$59:$I$68,0)),"") | L7: =IF(K7<>"",IFERROR(VLOOKUP(CONCATENATE(A7,"#",C7,"#",E7,"#",G7,"#",I7,"#",K7),_h_SimpleLookup_h_!$D$13:$E$56,2,0),""),IF(I7<>"",IFERROR(VLOOKUP(CONCATENATE(A7,"#",C7,"#",E7,"#",G7,"#",I7),_h_SimpleLookup_h_!$D$13:$E$56,2,0),""),IF(G7<>"",IFERROR(VLOOKUP(CONCATENATE(A7,"#",C7,"#",E7,"#",G7),_h_SimpleLookup_h_!$D$13:$E$56,2,0),""),IF(E7<>"",IFERROR(VLOOKUP(CONCATENATE(A7,"#",C7,"#",E7),_h_SimpleLookup_h_!$D$13:$E$56,2,0),""),IF(C7<>"",IFERROR(VLOOKUP(CONCATENATE(A7,"#",C7),_h_SimpleLookup_h_!$D$13:$E$56,2,0),""),IF(A7<>"",IFERROR(VLOOKUP(CONCATENATE(A7),_h_SimpleLookup_h_!$D$13:$E$56,2,0),""),"")))))) -> NIGERIA_NI | M7: DS | N7: 9765432349 | O7: DISTRICT_SUPERVISOR | T7: Temporary | U7: Active
A8: Nigeria | B8: =IFERROR(INDEX(_h_SimpleLookup_h_!$J$59:$J$68,MATCH(CONCATENATE(INDIRECT("A"&ROW())),_h_SimpleLookup_h_!$I$59:$I$68,0)),"") -> H_fb6f8507bb42032f92d3fb39098d6015c7a2d1ef5850f24f0469a022b6bae7a6 | D8: =IFERROR(INDEX(_h_SimpleLookup_h_!$J$59:$J$68,MATCH(CONCATENATE(INDIRECT("A"&ROW()), "#", INDIRECT("C"&ROW())),_h_SimpleLookup_h_!$I$59:$I$68,0)),"") | F8: =IFERROR(INDEX(_h_SimpleLookup_h_!$J$59:$J$68,MATCH(CONCATENATE(INDIRECT("A"&ROW()), "#", INDIRECT("C"&ROW()), "#", INDIRECT("E"&ROW())),_h_SimpleLookup_h_!$I$59:$I$68,0)),"") | H8: =IFERROR(INDEX(_h_SimpleLookup_h_!$J$59:$J$68,MATCH(CONCATENATE(INDIRECT("A"&ROW()), "#", INDIRECT("C"&ROW()), "#", INDIRECT("E"&ROW()), "#", INDIRECT("G"&ROW())),_h_SimpleLookup_h_!$I$59:$I$68,0)),"") | J8: =IFERROR(INDEX(_h_SimpleLookup_h_!$J$59:$J$68,MATCH(CONCATENATE(INDIRECT("A"&ROW()), "#", INDIRECT("C"&ROW()), "#", INDIRECT("E"&ROW()), "#", INDIRECT("G"&ROW()), "#", INDIRECT("I"&ROW())),_h_SimpleLookup_h_!$I$59:$I$68,0)),"") | L8: =IF(K8<>"",IFERROR(VLOOKUP(CONCATENATE(A8,"#",C8,"#",E8,"#",G8,"#",I8,"#",K8),_h_SimpleLookup_h_!$D$13:$E$56,2,0),""),IF(I8<>"",IFERROR(VLOOKUP(CONCATENATE(A8,"#",C8,"#",E8,"#",G8,"#",I8),_h_SimpleLookup_h_!$D$13:$E$56,2,0),""),IF(G8<>"",IFERROR(VLOOKUP(CONCATENATE(A8,"#",C8,"#",E8,"#",G8),_h_SimpleLookup_h_!$D$13:$E$56,2,0),""),IF(E8<>"",IFERROR(VLOOKUP(CONCATENATE(A8,"#",C8,"#",E8),_h_SimpleLookup_h_!$D$13:$E$56,2,0),""),IF(C8<>"",IFERROR(VLOOKUP(CONCATENATE(A8,"#",C8),_h_SimpleLookup_h_!$D$13:$E$56,2,0),""),IF(A8<>"",IFERROR(VLOOKUP(CONCATENATE(A8),_h_SimpleLookup_h_!$D$13:$E$56,2,0),""),"")))))) -> NIGERIA_NI | M8: TS | N8: 9765432350 | O8: TEAM_SUPERVISOR | T8: Temporary | U8: Active
A9: Nigeria | B9: =IFERROR(INDEX(_h_SimpleLookup_h_!$J$59:$J$68,MATCH(CONCATENATE(INDIRECT("A"&ROW())),_h_SimpleLookup_h_!$I$59:$I$68,0)),"") -> H_fb6f8507bb42032f92d3fb39098d6015c7a2d1ef5850f24f0469a022b6bae7a6 | D9: =IFERROR(INDEX(_h_SimpleLookup_h_!$J$59:$J$68,MATCH(CONCATENATE(INDIRECT("A"&ROW()), "#", INDIRECT("C"&ROW())),_h_SimpleLookup_h_!$I$59:$I$68,0)),"") | F9: =IFERROR(INDEX(_h_SimpleLookup_h_!$J$59:$J$68,MATCH(CONCATENATE(INDIRECT("A"&ROW()), "#", INDIRECT("C"&ROW()), "#", INDIRECT("E"&ROW())),_h_SimpleLookup_h_!$I$59:$I$68,0)),"") | H9: =IFERROR(INDEX(_h_SimpleLookup_h_!$J$59:$J$68,MATCH(CONCATENATE(INDIRECT("A"&ROW()), "#", INDIRECT("C"&ROW()), "#", INDIRECT("E"&ROW()), "#", INDIRECT("G"&ROW())),_h_SimpleLookup_h_!$I$59:$I$68,0)),"") | J9: =IFERROR(INDEX(_h_SimpleLookup_h_!$J$59:$J$68,MATCH(CONCATENATE(INDIRECT("A"&ROW()), "#", INDIRECT("C"&ROW()), "#", INDIRECT("E"&ROW()), "#", INDIRECT("G"&ROW()), "#", INDIRECT("I"&ROW())),_h_SimpleLookup_h_!$I$59:$I$68,0)),"") | L9: =IF(K9<>"",IFERROR(VLOOKUP(CONCATENATE(A9,"#",C9,"#",E9,"#",G9,"#",I9,"#",K9),_h_SimpleLookup_h_!$D$13:$E$56,2,0),""),IF(I9<>"",IFERROR(VLOOKUP(CONCATENATE(A9,"#",C9,"#",E9,"#",G9,"#",I9),_h_SimpleLookup_h_!$D$13:$E$56,2,0),""),IF(G9<>"",IFERROR(VLOOKUP(CONCATENATE(A9,"#",C9,"#",E9,"#",G9),_h_SimpleLookup_h_!$D$13:$E$56,2,0),""),IF(E9<>"",IFERROR(VLOOKUP(CONCATENATE(A9,"#",C9,"#",E9),_h_SimpleLookup_h_!$D$13:$E$56,2,0),""),IF(C9<>"",IFERROR(VLOOKUP(CONCATENATE(A9,"#",C9),_h_SimpleLookup_h_!$D$13:$E$56,2,0),""),IF(A9<>"",IFERROR(VLOOKUP(CONCATENATE(A9),_h_SimpleLookup_h_!$D$13:$E$56,2,0),""),"")))))) -> NIGERIA_NI | M9: PS | N9: 9765432351 | O9: PROVINCIAL_SUPERVISOR | T9: Temporary | U9: Active
